File: dataFiles/staticInstron_4.raw
"Test Type","Tension"
"Method Name","C:\Users\mmen339\Documents\tension test 1mm_s.im_tens"
"Sample name","C:\Users\mmen339\Documents\sample 3\S3.FailureExtension_1.is_tens"
"User",""
"Sample note 1",""
"Sample note 2",""
"Sample note 3",""
"Geometry","Rectangular"
"Specimen",1
"Specimen label",""
"Width",10.000000,"mm"
"Thickness",1.000000,"mm"
"Length",100.000000,"mm"
"Diameter",10.000000,"mm"
"Inner diameter",8.000000,"mm"
"Outer diameter",10.000000,"mm"
"Wall thickness",1.000000,"mm"
"Area",0.100000,"cm^2"
"Linear density",100.000000,"tex"
"Sled weight",10.000000,"N"
"Loading span",10.000000,"mm"
"Support span",100.000000,"mm"
"Span ratio","2"
"Fixture type","4-point"
"Included"
"Final width",10.000000,"mm"
"Final thickness",1.000000,"mm"
"Final length",100.000000,"mm"
"Final diameter",10.000000,"mm"
"Final Inner diameter",8.000000,"mm"
"Final outer diameter",10.000000,"mm"
"Final wall thickness",1.000000,"mm"
"Final area",0.100000,"cm^2"
"Final linear density",100.000000,"tex"
"Custom text input  1",""
"Custom text input  2",""
"Custom text input  3",""
"Custom text input  4",""
"Custom text input  5",""
"Custom text input  6",""
"Custom text input  7",""
"Custom text input  8",""
"Custom text input  9",""
"Custom text input 10",""
"Custom text input 11",""
"Custom text input 12",""
"Custom text input 13",""
"Custom text input 14",""
"Custom text input 15",""
"Custom text input 16",""
"Custom text input 17",""
"Custom text input 18",""
"Custom text input 19",""
"Custom text input 20",""
"Custom text input 21",""
"Custom text input 22",""
"Custom text input 23",""
"Custom text input 24",""
"Custom text input 25",""
"Custom text input 26",""
"Custom text input 27",""
"Custom text input 28",""
"Custom text input 29",""
"Custom text input 30",""
"Custom text input 31",""
"Custom text input 32",""
"Custom text input 33",""
"Custom text input 34",""
"Custom text input 35",""
"Custom text input 36",""
"Custom text input 37",""
"Custom text input 38",""
"Custom text input 39",""
"Custom text input 40",""
"Custom text input 41",""
"Custom text input 42",""
"Custom text input 43",""
"Custom text input 44",""
"Custom text input 45",""
"Custom text input 46",""
"Custom text input 47",""
"Custom text input 48",""
"Custom text input 49",""
"Custom text input 50",""
"Custom number input  1",0.000000,""
"Custom number input  2",0.000000,""
"Custom number input  3",0.000000,""
"Custom number input  4",0.000000,""
"Custom number input  5",0.000000,""
"Custom number input  6",0.000000,""
"Custom number input  7",0.000000,""
"Custom number input  8",0.000000,""
"Custom number input  9",0.000000,""
"Custom number input 10",0.000000,""
"Time sec","Extension mm","Load N","Tensile stress MPa","Cycle Count ","Total Cycle Count ","Repetitions Count ","Marked Data ","PIP Count ","Tensile extension mm","Tensile strain %","Corrected Position mm","Tenacity gf/tex"
0,0,-0.0006130198,-6.130198e-005,0,0,0,0,0,0,0,0,-0.0006251062
0.4,0.00203125,0.0009426367,9.426367e-005,0,0,0,0,0,0.002031249,0.002031249,0.00203125,0.0009612219
0.8,0.0134375,0.01710551,0.001710551,0,0,0,0,0,0.0134375,0.0134375,0.0134375,0.01744277
1.2,0.02,0.02401442,0.002401442,0,0,0,0,0,0.02,0.02,0.02,0.0244879
1.6,0.0265625,0.03140281,0.003140281,0,0,0,0,0,0.0265625,0.0265625,0.0265625,0.03202195
2,0.03312499,0.03781519,0.003781519,0,0,0,0,0,0.03312499,0.03312499,0.03312499,0.03856076
2.4,0.04015624,0.04542078,0.004542078,0,0,0,0,0,0.04015624,0.04015624,0.04015624,0.04631631
2.8,0.04687499,0.05150952,0.005150952,0,0,0,0,0,0.04687499,0.04687499,0.04687499,0.05252509
3.2,0.05312499,0.05843529,0.005843529,0,0,0,0,0,0.05312499,0.05312499,0.05312499,0.05958741
3.6,0.05984374,0.06409199,0.006409199,0,0,0,0,0,0.05984375,0.05984375,0.05984374,0.06535564
4,0.06703124,0.07187557,0.007187557,0,0,0,0,0,0.06703123,0.06703123,0.06703124,0.07329269
4.4,0.07312499,0.07774045,0.007774045,0,0,0,0,0,0.07312499,0.07312499,0.07312499,0.07927319
4.8,0.07968749,0.08285514,0.008285514,0,0,0,0,0,0.07968749,0.07968749,0.07968749,0.08448873
5.2,0.08640624,0.08959371,0.008959371,0,0,0,0,0,0.08640624,0.08640624,0.08640624,0.09136016
5.6,0.09328124,0.0954778,0.00954778,0,0,0,0,0,0.09328124,0.09328124,0.09328124,0.09736026
6,0.1001562,0.1018892,0.01018892,0,0,0,0,0,0.1001562,0.1001562,0.1001562,0.1038981
6.4,0.1067187,0.1070437,0.01070437,0,0,0,0,0,0.1067187,0.1067187,0.1067187,0.1091542
6.8,0.1129687,0.111504,0.0111504,0,0,0,0,0,0.1129687,0.1129687,0.1129687,0.1137025
7.2,0.1196875,0.1175228,0.01175228,0,0,0,0,0,0.1196875,0.1196875,0.1196875,0.1198399
7.6,0.126875,0.1237621,0.01237621,0,0,0,0,0,0.126875,0.126875,0.126875,0.1262022
8,0.133125,0.1287809,0.01287809,0,0,0,0,0,0.133125,0.133125,0.133125,0.13132
8.400001,0.1396875,0.133372,0.0133372,0,0,0,0,0,0.1396875,0.1396875,0.1396875,0.1360016
8.8,0.1465625,0.1392904,0.01392904,0,0,0,0,0,0.1465625,0.1465625,0.1465625,0.1420367
9.200001,0.1534375,0.14462,0.014462,0,0,0,0,0,0.1534375,0.1534375,0.1534375,0.1474713
9.6,0.1598437,0.149686,0.0149686,0,0,0,0,0,0.1598437,0.1598437,0.1598437,0.1526373
10,0.1664062,0.1542564,0.01542564,0,0,0,0,0,0.1664062,0.1664062,0.1664062,0.1572977
10.4,0.1729687,0.1590608,0.01590608,0,0,0,0,0,0.1729687,0.1729687,0.1729687,0.1621968
10.8,0.1801562,0.165478,0.0165478,0,0,0,0,0,0.1801562,0.1801562,0.1801562,0.1687406
11.2,0.186875,0.1702711,0.01702711,0,0,0,0,0,0.186875,0.186875,0.186875,0.1736282
11.6,0.1932812,0.1752164,0.01752164,0,0,0,0,0,0.1932812,0.1932812,0.1932812,0.178671
12,0.1995312,0.179093,0.0179093,0,0,0,0,0,0.1995312,0.1995312,0.1995312,0.182624
12.4,0.2065625,0.1853574,0.01853574,0,0,0,0,0,0.2065625,0.2065625,0.2065625,0.1890119
12.8,0.2134375,0.1909125,0.01909125,0,0,0,0,0,0.2134375,0.2134375,0.2134375,0.1946766
13.2,0.22,0.1956534,0.01956534,0,0,0,0,0,0.22,0.22,0.22,0.1995109
13.6,0.2264062,0.1999848,0.01999848,0,0,0,0,0,0.2264062,0.2264062,0.2264062,0.2039277
14,0.2332812,0.205406,0.0205406,0,0,0,0,0,0.2332812,0.2332812,0.2332812,0.2094559
14.4,0.24,0.2103671,0.02103671,0,0,0,0,0,0.24,0.24,0.24,0.2145147
14.8,0.2464062,0.2150783,0.02150783,0,0,0,0,0,0.2464062,0.2464062,0.2464062,0.2193188
15.2,0.2531249,0.2198439,0.02198439,0,0,0,0,0,0.253125,0.253125,0.2531249,0.2241784
15.6,0.2598437,0.2252546,0.02252546,0,0,0,0,0,0.2598437,0.2598437,0.2598437,0.2296958
16,0.2670312,0.2305947,0.02305947,0,0,0,0,0,0.2670312,0.2670312,0.2670312,0.2351412
16.4,0.2735937,0.2354334,0.02354334,0,0,0,0,0,0.2735937,0.2735937,0.2735937,0.2400752
16.8,0.2796875,0.2399304,0.02399304,0,0,0,0,0,0.2796875,0.2796875,0.2796875,0.2446609
17.2,0.2862499,0.2445499,0.02445499,0,0,0,0,0,0.2862499,0.2862499,0.2862499,0.2493715
17.6,0.293125,0.2501155,0.02501155,0,0,0,0,0,0.293125,0.293125,0.293125,0.2550468
18,0.3,0.2552559,0.02552559,0,0,0,0,0,0.3,0.3,0.3,0.2602885
18.4,0.3065625,0.2596321,0.02596321,0,0,0,0,0,0.3065625,0.3065625,0.3065625,0.2647511
18.8,0.3131249,0.2636955,0.02636955,0,0,0,0,0,0.3131249,0.3131249,0.3131249,0.2688946
19.2,0.3198437,0.2688161,0.02688161,0,0,0,0,0,0.3198437,0.3198437,0.3198437,0.2741162
19.6,0.3267187,0.274156,0.0274156,0,0,0,0,0,0.3267187,0.3267187,0.3267187,0.2795613
20,0.3332812,0.279258,0.0279258,0,0,0,0,0,0.3332812,0.3332812,0.3332812,0.2847639
20.4,0.3396875,0.2836742,0.02836742,0,0,0,0,0,0.3396875,0.3396875,0.3396875,0.2892672
20.8,0.3464062,0.2892784,0.02892784,0,0,0,0,0,0.3464062,0.3464062,0.3464062,0.2949819
21.2,0.3535937,0.2943839,0.02943839,0,0,0,0,0,0.3535937,0.3535937,0.3535937,0.300188
21.6,0.3601562,0.2986108,0.02986108,0,0,0,0,0,0.3601562,0.3601562,0.3601562,0.3044983
22,0.3662499,0.30375,0.030375,0,0,0,0,0,0.3662499,0.3662499,0.3662499,0.3097388
22.4,0.373125,0.3091409,0.03091409,0,0,0,0,0,0.373125,0.373125,0.373125,0.3152359
22.8,0.3803124,0.3151492,0.03151492,0,0,0,0,0,0.3803124,0.3803124,0.3803124,0.3213628
23.2,0.3867187,0.3202116,0.03202116,0,0,0,0,0,0.3867187,0.3867187,0.3867187,0.3265249
23.6,0.3932812,0.3254606,0.03254606,0,0,0,0,0,0.3932812,0.3932812,0.3932812,0.3318774
24,0.4,0.3303071,0.03303071,0,0,0,0,0,0.3999999,0.3999999,0.4,0.3368195
24.4,0.4065624,0.3346935,0.03346935,0,0,0,0,0,0.4065624,0.4065624,0.4065624,0.3412924
24.8,0.4132812,0.3411747,0.03411747,0,0,0,0,0,0.4132812,0.4132812,0.4132812,0.3479014
25.2,0.4198437,0.3466715,0.03466715,0,0,0,0,0,0.4198437,0.4198437,0.4198437,0.3535065
25.6,0.4264062,0.351557,0.0351557,0,0,0,0,0,0.4264062,0.4264062,0.4264062,0.3584884
26,0.4332812,0.3581736,0.03581737,0,0,0,0,0,0.4332812,0.4332812,0.4332812,0.3652355
26.4,0.4404687,0.3642569,0.03642569,0,0,0,0,0,0.4404687,0.4404687,0.4404687,0.3714387
26.8,0.4465625,0.3680747,0.03680747,0,0,0,0,0,0.4465624,0.4465624,0.4465625,0.3753317
27.2,0.4529687,0.3729447,0.03729447,0,0,0,0,0,0.4529687,0.4529687,0.4529687,0.3802978
27.6,0.4596874,0.3787545,0.03787545,0,0,0,0,0,0.4596874,0.4596874,0.4596874,0.3862222
28,0.4667187,0.384283,0.0384283,0,0,0,0,0,0.4667187,0.4667187,0.4667187,0.3918597
28.4,0.4732812,0.3899317,0.03899317,0,0,0,0,0,0.4732812,0.4732812,0.4732812,0.3976197
28.8,0.4798437,0.3948925,0.03948925,0,0,0,0,0,0.4798437,0.4798437,0.4798437,0.4026783
29.2,0.4862499,0.4000452,0.04000452,0,0,0,0,0,0.48625,0.48625,0.4862499,0.4079326
29.6,0.4934374,0.4067246,0.04067246,0,0,0,0,0,0.4934374,0.4934374,0.4934374,0.4147437
30,0.5001561,0.4121711,0.04121711,0,0,0,0,0,0.5001562,0.5001562,0.5001561,0.4202976
30.4,0.5064061,0.4175928,0.04175928,0,0,0,0,0,0.5064061,0.5064061,0.5064061,0.4258262
30.8,0.5129686,0.4230943,0.04230943,0,0,0,0,0,0.5129687,0.5129687,0.5129686,0.4314361
31.2,0.5199999,0.4290231,0.04290231,0,0,0,0,0,0.5199999,0.5199999,0.5199999,0.4374818
31.6,0.5267186,0.4350826,0.04350826,0,0,0,0,0,0.5267186,0.5267186,0.5267186,0.4436608
32,0.5329687,0.4400146,0.04400146,0,0,0,0,0,0.5329686,0.5329686,0.5329687,0.44869
32.4,0.5396874,0.4457675,0.04457675,0,0,0,0,0,0.5396874,0.5396874,0.5396874,0.4545564
32.8,0.5465624,0.4529376,0.04529376,0,0,0,0,0,0.5465624,0.5465624,0.5465624,0.4618678
33.2,0.5535936,0.4599424,0.04599424,0,0,0,0,0,0.5535936,0.5535936,0.5535936,0.4690107
33.6,0.5601561,0.4648381,0.04648381,0,0,0,0,0,0.5601561,0.5601561,0.5601561,0.4740029
34,0.5667186,0.4700718,0.04700717,0,0,0,0,0,0.5667186,0.5667186,0.5667186,0.4793398
34.4,0.5731249,0.4755256,0.04755256,0,0,0,0,0,0.5731249,0.5731249,0.5731249,0.4849011
34.8,0.5799999,0.4819738,0.04819738,0,0,0,0,0,0.5799999,0.5799999,0.5799999,0.4914765
35.2,0.5867187,0.4876619,0.04876619,0,0,0,0,0,0.5867187,0.5867187,0.5867187,0.4972767
35.6,0.5929687,0.4942854,0.04942854,0,0,0,0,0,0.5929686,0.5929686,0.5929687,0.5040308
36,0.5998436,0.4997851,0.04997851,0,0,0,0,0,0.5998436,0.5998436,0.5998436,0.509639
36.4,0.6071874,0.5063755,0.05063754,0,0,0,0,0,0.6071874,0.6071874,0.6071874,0.5163593
36.8,0.6132812,0.5096845,0.05096845,0,0,0,0,0,0.6132811,0.6132811,0.6132812,0.5197336
37.2,0.6196874,0.5152293,0.05152293,0,0,0,0,0,0.6196874,0.6196874,0.6196874,0.5253876
37.6,0.6262499,0.5167752,0.05167752,0,0,0,0,0,0.6262498,0.6262498,0.6262499,0.526964
38,0.6331249,0.5229578,0.05229578,0,0,0,0,0,0.6331249,0.6331249,0.6331249,0.5332685
38.4,0.6399999,0.5301143,0.05301143,0,0,0,0,0,0.6399999,0.6399999,0.6399999,0.5405661
38.8,0.6467187,0.5365996,0.05365996,0,0,0,0,0,0.6467187,0.6467187,0.6467187,0.5471793
39.2,0.6529687,0.5418697,0.05418697,0,0,0,0,0,0.6529686,0.6529686,0.6529687,0.5525534
39.6,0.6598437,0.5492963,0.05492963,0,0,0,0,0,0.6598437,0.6598437,0.6598437,0.5601264
40,0.6668749,0.5566769,0.05566769,0,0,0,0,0,0.6668749,0.6668749,0.6668749,0.5676525
40.4,0.6734374,0.5633282,0.05633283,0,0,0,0,0,0.6734374,0.6734374,0.6734374,0.5744349
40.8,0.6796874,0.5677427,0.05677427,0,0,0,0,0,0.6796874,0.6796874,0.6796874,0.5789365
41.2,0.6865624,0.5737482,0.05737482,0,0,0,0,0,0.6865624,0.6865624,0.6865624,0.5850603
41.6,0.6937499,0.5811495,0.05811495,0,0,0,0,0,0.6937498,0.6937498,0.6937499,0.5926076
42,0.6998436,0.586463,0.0586463,0,0,0,0,0,0.6998436,0.6998436,0.6998436,0.5980258
42.4,0.7062499,0.5930753,0.05930753,0,0,0,0,0,0.7062499,0.7062499,0.7062499,0.6047685
42.8,0.7131249,0.6003733,0.06003733,0,0,0,0,0,0.7131249,0.7131249,0.7131249,0.6122104
43.2,0.7201561,0.6075396,0.06075396,0,0,0,0,0,0.7201561,0.7201561,0.7201561,0.619518
43.6,0.7267186,0.6136587,0.06136587,0,0,0,0,0,0.7267186,0.7267186,0.7267186,0.6257578
44,0.7334374,0.6204684,0.06204684,0,0,0,0,0,0.7334374,0.7334374,0.7334374,0.6327017
44.4,0.7395311,0.6259401,0.06259401,0,0,0,0,0,0.7395311,0.7395311,0.7395311,0.6382812
44.8,0.7465624,0.6337394,0.06337394,0,0,0,0,0,0.7465624,0.7465624,0.7465624,0.6462343
45.2,0.7532812,0.6409388,0.06409387,0,0,0,0,0,0.7532812,0.7532812,0.7532812,0.6535757
45.6,0.7598436,0.6482047,0.06482047,0,0,0,0,0,0.7598436,0.7598436,0.7598436,0.6609848
46,0.7664061,0.6545088,0.06545088,0,0,0,0,0,0.7664061,0.7664061,0.7664061,0.6674132
46.4,0.7732812,0.6626361,0.06626361,0,0,0,0,0,0.7732812,0.7732812,0.7732812,0.6757007
46.8,0.7799999,0.6690064,0.06690064,0,0,0,0,0,0.7799999,0.7799999,0.7799999,0.6821967
47.2,0.7864062,0.6762653,0.06762653,0,0,0,0,0,0.7864062,0.7864062,0.7864062,0.6895987
47.6,0.7929687,0.683905,0.0683905,0,0,0,0,0,0.7929687,0.7929687,0.7929687,0.697389
48,0.7996874,0.6908043,0.06908043,0,0,0,0,0,0.7996874,0.7996874,0.7996874,0.7044243
48.4,0.8068749,0.6991816,0.06991816,0,0,0,0,0,0.8068749,0.8068749,0.8068749,0.7129669
48.8,0.8134374,0.7047748,0.07047749,0,0,0,0,0,0.8134374,0.8134374,0.8134374,0.7186703
49.2,0.8196874,0.7105832,0.07105833,0,0,0,0,0,0.8196874,0.8196874,0.8196874,0.7245933
49.6,0.8262499,0.7176954,0.07176954,0,0,0,0,0,0.8262499,0.8262499,0.8262499,0.7318457
50,0.8332811,0.7257005,0.07257006,0,0,0,0,0,0.8332812,0.8332812,0.8332811,0.7400086
50.4,0.8399999,0.7330609,0.07330608,0,0,0,0,0,0.8399999,0.8399999,0.8399999,0.7475141
50.8,0.8465624,0.7388926,0.07388926,0,0,0,0,0,0.8465624,0.8465624,0.8465624,0.7534608
51.2,0.8531249,0.7455418,0.07455418,0,0,0,0,0,0.8531249,0.8531249,0.8531249,0.760241
51.6,0.8601561,0.7533344,0.07533344,0,0,0,0,0,0.8601561,0.8601561,0.8601561,0.7681873
52,0.8665624,0.7591532,0.07591532,0,0,0,0,0,0.8665624,0.8665624,0.8665624,0.7741208
52.4,0.8729686,0.7538741,0.0753874,0,0,0,0,0,0.8729686,0.8729686,0.8729686,0.7687376
52.8,0.8796874,0.7610157,0.07610156,0,0,0,0,0,0.8796874,0.8796874,0.8796874,0.77602
53.2,0.8865624,0.768958,0.0768958,0,0,0,0,0,0.8865624,0.8865624,0.8865624,0.784119
53.6,0.8937499,0.7773763,0.07773763,0,0,0,0,0,0.8937499,0.8937499,0.8937499,0.7927032
54,0.9003124,0.7837282,0.07837282,0,0,0,0,0,0.9003124,0.9003124,0.9003124,0.7991804
54.4,0.9062499,0.7538335,0.07538335,0,0,0,0,0,0.9062499,0.9062499,0.9062499,0.7686962
54.8,0.9131249,0.7449463,0.07449463,0,0,0,0,0,0.9131249,0.9131249,0.9131249,0.7596338
55.2,0.9199999,0.7535598,0.07535598,0,0,0,0,0,0.9199999,0.9199999,0.9199999,0.7684172
55.6,0.9265624,0.7632576,0.07632576,0,0,0,0,0,0.9265624,0.9265624,0.9265624,0.7783061
56,0.9331249,0.7714344,0.07714344,0,0,0,0,0,0.9331249,0.9331249,0.9331249,0.7866442
56.4,0.9398437,0.7774541,0.07774541,0,0,0,0,0,0.9398437,0.9398437,0.9398437,0.7927825
56.8,0.9468749,0.7874918,0.07874918,0,0,0,0,0,0.9468749,0.9468749,0.9468749,0.8030182
57.2,0.9532811,0.7956062,0.07956062,0,0,0,0,0,0.9532811,0.9532811,0.9532811,0.8112926
57.6,0.9596874,0.8040036,0.08040036,0,0,0,0,0,0.9596874,0.9596874,0.9596874,0.8198555
58,0.9664061,0.8129816,0.08129816,0,0,0,0,0,0.9664061,0.9664061,0.9664061,0.8290105
58.4,0.9732812,0.8219001,0.08219001,0,0,0,0,0,0.9732811,0.9732811,0.9732812,0.8381048
58.8,0.9803124,0.8318515,0.08318515,0,0,0,0,0,0.9803123,0.9803123,0.9803124,0.8482525
59.2,0.9865623,0.8392064,0.08392064,0,0,0,0,0,0.9865624,0.9865624,0.9865623,0.8557523
59.6,0.9928123,0.8464049,0.08464049,0,0,0,0,0,0.9928123,0.9928123,0.9928123,0.8630928
60,0.9998436,0.8558094,0.08558094,0,0,0,0,0,0.9998436,0.9998436,0.9998436,0.8726827
60.4,1.006875,0.8657898,0.08657898,0,0,0,0,0,1.006875,1.006875,1.006875,0.8828599
60.8,1.013437,0.874024,0.0874024,0,0,0,0,0,1.013437,1.013437,1.013437,0.8912564
61.2,1.019844,0.8814842,0.08814842,0,0,0,0,0,1.019843,1.019843,1.019844,0.8988637
61.6,1.026562,0.888721,0.0888721,0,0,0,0,0,1.026562,1.026562,1.026562,0.9062432
62,1.033281,0.8982942,0.08982942,0,0,0,0,0,1.033281,1.033281,1.033281,0.9160051
62.4,1.04,0.9050842,0.09050842,0,0,0,0,0,1.04,1.04,1.04,0.922929
62.8,1.046406,0.9127902,0.09127901,0,0,0,0,0,1.046406,1.046406,1.046406,0.930787
63.2,1.052969,0.9218317,0.09218317,0,0,0,0,0,1.052969,1.052969,1.052969,0.9400067
63.6,1.060156,0.9308069,0.09308069,0,0,0,0,0,1.060156,1.060156,1.060156,0.9491589
64,1.066875,0.9383821,0.09383821,0,0,0,0,0,1.066875,1.066875,1.066875,0.9568834
64.4,1.072969,0.9461734,0.09461734,0,0,0,0,0,1.072969,1.072969,1.072969,0.9648284
64.8,1.079531,0.9508077,0.09508077,0,0,0,0,0,1.079531,1.079531,1.079531,0.969554
65.2,1.086406,0.8943136,0.08943136,0,0,0,0,0,1.086406,1.086406,1.086406,0.9119461
65.60001,1.093594,0.9090182,0.09090182,0,0,0,0,0,1.093594,1.093594,1.093594,0.9269406
66,1.1,0.9179866,0.09179866,0,0,0,0,0,1.1,1.1,1.1,0.9360858
66.4,1.106562,0.9232848,0.09232848,0,0,0,0,0,1.106562,1.106562,1.106562,0.9414885
66.8,1.112969,0.9312052,0.09312052,0,0,0,0,0,1.112969,1.112969,1.112969,0.9495651
67.20001,1.12,0.9434548,0.09434548,0,0,0,0,0,1.12,1.12,1.12,0.9620562
67.60001,1.126719,0.9552461,0.09552461,0,0,0,0,0,1.126719,1.126719,1.126719,0.97408
68,1.133125,0.9644603,0.09644604,0,0,0,0,0,1.133125,1.133125,1.133125,0.9834759
68.4,1.139687,0.9750948,0.09750948,0,0,0,0,0,1.139687,1.139687,1.139687,0.99432
68.8,1.147031,0.9864718,0.09864718,0,0,0,0,0,1.147031,1.147031,1.147031,1.005921
69.20001,1.153281,0.9950208,0.09950209,0,0,0,0,0,1.153281,1.153281,1.153281,1.014639
69.60001,1.159687,1.002212,0.1002212,0,0,0,0,0,1.159687,1.159687,1.159687,1.021972
70,1.16625,1.01027,0.101027,0,0,0,0,0,1.16625,1.16625,1.16625,1.030189
70.4,1.173281,1.020889,0.1020889,0,0,0,0,0,1.173281,1.173281,1.173281,1.041017
70.8,1.18,1.030534,0.1030534,0,0,0,0,0,1.18,1.18,1.18,1.050852
71.20001,1.186719,1.038557,0.1038557,0,0,0,0,0,1.186719,1.186719,1.186719,1.059034
71.60001,1.193437,1.046483,0.1046483,0,0,0,0,0,1.193437,1.193437,1.193437,1.067115
72,1.199844,1.054868,0.1054868,0,0,0,0,0,1.199844,1.199844,1.199844,1.075666
72.4,1.206719,1.057679,0.1057679,0,0,0,0,0,1.206718,1.206718,1.206719,1.078532
72.8,1.213281,1.063093,0.1063093,0,0,0,0,0,1.213281,1.213281,1.213281,1.084053
73.20001,1.219687,1.067657,0.1067657,0,0,0,0,0,1.219687,1.219687,1.219687,1.088707
73.60001,1.226562,1.074533,0.1074533,0,0,0,0,0,1.226562,1.226562,1.226562,1.095719
74,1.23375,1.084232,0.1084232,0,0,0,0,0,1.23375,1.23375,1.23375,1.105609
74.4,1.24,1.091505,0.1091505,0,0,0,0,0,1.24,1.24,1.24,1.113025
74.8,1.246406,1.100337,0.1100337,0,0,0,0,0,1.246406,1.246406,1.246406,1.122032
75.20001,1.252969,1.109694,0.1109694,0,0,0,0,0,1.252969,1.252969,1.252969,1.131573
75.60001,1.26,1.120352,0.1120352,0,0,0,0,0,1.26,1.26,1.26,1.142441
76,1.266718,1.12903,0.112903,0,0,0,0,0,1.266719,1.266719,1.266718,1.15129
76.4,1.273281,1.136691,0.1136691,0,0,0,0,0,1.273281,1.273281,1.273281,1.159102
76.8,1.279687,1.1446,0.1144601,0,0,0,0,0,1.279687,1.279687,1.279687,1.167168
77.20001,1.286562,1.154922,0.1154922,0,0,0,0,0,1.286562,1.286562,1.286562,1.177693
77.60001,1.293437,1.164464,0.1164464,0,0,0,0,0,1.293437,1.293437,1.293437,1.187422
78,1.3,1.172777,0.1172777,0,0,0,0,0,1.3,1.3,1.3,1.1959
78.4,1.306406,1.181179,0.1181179,0,0,0,0,0,1.306406,1.306406,1.306406,1.204468
78.8,1.313437,1.190515,0.1190515,0,0,0,0,0,1.313437,1.313437,1.313437,1.213987
79.20001,1.320312,1.197384,0.1197384,0,0,0,0,0,1.320312,1.320312,1.320312,1.220991
79.60001,1.326406,1.203887,0.1203887,0,0,0,0,0,1.326406,1.326406,1.326406,1.227623
80,1.332969,1.212433,0.1212433,0,0,0,0,0,1.332969,1.332969,1.332969,1.236337
80.4,1.339843,1.223318,0.1223318,0,0,0,0,0,1.339844,1.339844,1.339843,1.247437
80.8,1.347031,1.23432,0.123432,0,0,0,0,0,1.347031,1.347031,1.347031,1.258657
81.20001,1.353594,1.240999,0.1240999,0,0,0,0,0,1.353594,1.353594,1.353594,1.265467
81.60001,1.360156,1.250115,0.1250115,0,0,0,0,0,1.360156,1.360156,1.360156,1.274763
82.00001,1.36625,1.25729,0.125729,0,0,0,0,0,1.36625,1.36625,1.36625,1.282079
82.4,1.373125,1.268305,0.1268305,0,0,0,0,0,1.373125,1.373125,1.373125,1.293312
82.8,1.38,1.27765,0.127765,0,0,0,0,0,1.38,1.38,1.38,1.302841
83.20001,1.386406,1.285367,0.1285367,0,0,0,0,0,1.386406,1.386406,1.386406,1.310709
83.60001,1.393125,1.294237,0.1294237,0,0,0,0,0,1.393125,1.393125,1.393125,1.319755
84.00001,1.400156,1.303523,0.1303523,0,0,0,0,0,1.400156,1.400156,1.400156,1.329224
84.4,1.406719,1.311175,0.1311175,0,0,0,0,0,1.406718,1.406718,1.406719,1.337027
84.8,1.412969,1.318704,0.1318704,0,0,0,0,0,1.412969,1.412969,1.412969,1.344704
85.20001,1.419687,1.327763,0.1327763,0,0,0,0,0,1.419687,1.419687,1.419687,1.353941
85.60001,1.426406,1.337559,0.1337559,0,0,0,0,0,1.426406,1.426406,1.426406,1.36393
86.00001,1.433437,1.339142,0.1339142,0,0,0,0,0,1.433437,1.433437,1.433437,1.365545
86.4,1.440156,1.348025,0.1348025,0,0,0,0,0,1.440156,1.440156,1.440156,1.374603
86.8,1.44625,1.353325,0.1353325,0,0,0,0,0,1.44625,1.44625,1.44625,1.380007
87.20001,1.452969,1.363241,0.1363241,0,0,0,0,0,1.452969,1.452969,1.452969,1.390119
87.60001,1.460156,1.372708,0.1372709,0,0,0,0,0,1.460156,1.460156,1.460156,1.399773
88.00001,1.466719,1.381491,0.1381491,0,0,0,0,0,1.466719,1.466719,1.466719,1.408729
88.4,1.473125,1.388987,0.1388987,0,0,0,0,0,1.473125,1.473125,1.473125,1.416372
88.8,1.479844,1.398373,0.1398373,0,0,0,0,0,1.479843,1.479843,1.479844,1.425943
89.20001,1.487031,1.410299,0.1410299,0,0,0,0,0,1.487031,1.487031,1.487031,1.438105
89.60001,1.493281,1.417896,0.1417896,0,0,0,0,0,1.493281,1.493281,1.493281,1.445852
90.00001,1.499687,1.427117,0.1427117,0,0,0,0,0,1.499687,1.499687,1.499687,1.455255
90.4,1.506406,1.436251,0.1436251,0,0,0,0,0,1.506406,1.506406,1.506406,1.464568
90.8,1.513437,1.446478,0.1446478,0,0,0,0,0,1.513437,1.513437,1.513437,1.474997
91.20001,1.520312,1.457011,0.1457011,0,0,0,0,0,1.520312,1.520312,1.520312,1.485738
91.60001,1.526875,1.464531,0.1464531,0,0,0,0,0,1.526875,1.526875,1.526875,1.493406
92.00001,1.532968,1.468857,0.1468857,0,0,0,0,0,1.532969,1.532969,1.532968,1.497817
92.4,1.539844,1.479236,0.1479236,0,0,0,0,0,1.539844,1.539844,1.539844,1.508401
92.8,1.546719,1.482545,0.1482545,0,0,0,0,0,1.546718,1.546718,1.546719,1.511775
93.20001,1.553281,1.486176,0.1486176,0,0,0,0,0,1.553281,1.553281,1.553281,1.515478
93.60001,1.559844,1.494853,0.1494853,0,0,0,0,0,1.559844,1.559844,1.559844,1.524326
94.00001,1.566719,1.504443,0.1504443,0,0,0,0,0,1.566719,1.566719,1.566719,1.534105
94.4,1.573437,1.513816,0.1513816,0,0,0,0,0,1.573437,1.573437,1.573437,1.543663
94.8,1.58,1.523341,0.1523341,0,0,0,0,0,1.58,1.58,1.58,1.553375
95.20001,1.586406,1.532407,0.1532407,0,0,0,0,0,1.586406,1.586406,1.586406,1.56262
95.60001,1.593125,1.54323,0.154323,0,0,0,0,0,1.593125,1.593125,1.593125,1.573656
96.00001,1.599843,1.55346,0.155346,0,0,0,0,0,1.599844,1.599844,1.599843,1.584088
96.4,1.606875,1.563331,0.1563331,0,0,0,0,0,1.606875,1.606875,1.606875,1.594154
96.8,1.613125,1.56887,0.156887,0,0,0,0,0,1.613125,1.613125,1.613125,1.599803
97.20001,1.619531,1.577284,0.1577284,0,0,0,0,0,1.619531,1.619531,1.619531,1.608382
97.60001,1.626562,1.588252,0.1588252,0,0,0,0,0,1.626562,1.626562,1.626562,1.619567
98.00001,1.633437,1.598233,0.1598233,0,0,0,0,0,1.633437,1.633437,1.633437,1.629744
98.4,1.640156,1.607064,0.1607064,0,0,0,0,0,1.640156,1.640156,1.640156,1.638749
98.8,1.646562,1.614864,0.1614864,0,0,0,0,0,1.646562,1.646562,1.646562,1.646703
99.20001,1.653125,1.622978,0.1622978,0,0,0,0,0,1.653125,1.653125,1.653125,1.654977
99.60001,1.66,1.63304,0.163304,0,0,0,0,0,1.66,1.66,1.66,1.665237
100,1.666562,1.64185,0.164185,0,0,0,0,0,1.666562,1.666562,1.666562,1.674221
100.4,1.673125,1.65114,0.165114,0,0,0,0,0,1.673125,1.673125,1.673125,1.683694
100.8,1.679844,1.649829,0.1649829,0,0,0,0,0,1.679844,1.679844,1.679844,1.682357
101.2,1.687031,1.658673,0.1658673,0,0,0,0,0,1.687031,1.687031,1.687031,1.691376
101.6,1.693437,1.657111,0.1657111,0,0,0,0,0,1.693437,1.693437,1.693437,1.689783
102,1.699687,1.659537,0.1659538,0,0,0,0,0,1.699687,1.699687,1.699687,1.692257
102.4,1.70625,1.666872,0.1666872,0,0,0,0,0,1.70625,1.70625,1.70625,1.699736
102.8,1.713125,1.675029,0.1675029,0,0,0,0,0,1.713125,1.713125,1.713125,1.708054
103.2,1.72,1.68443,0.168443,0,0,0,0,0,1.72,1.72,1.72,1.717641
103.6,1.726406,1.687244,0.1687244,0,0,0,0,0,1.726406,1.726406,1.726406,1.72051
104,1.733125,1.693844,0.1693844,0,0,0,0,0,1.733125,1.733125,1.733125,1.727241
104.4,1.739687,1.701421,0.1701421,0,0,0,0,0,1.739687,1.739687,1.739687,1.734966
104.8,1.746719,1.711408,0.1711408,0,0,0,0,0,1.746719,1.746719,1.746719,1.745151
105.2,1.753281,1.718881,0.1718881,0,0,0,0,0,1.753281,1.753281,1.753281,1.752771
105.6,1.759687,1.723921,0.1723921,0,0,0,0,0,1.759687,1.759687,1.759687,1.75791
106,1.766406,1.73196,0.173196,0,0,0,0,0,1.766406,1.766406,1.766406,1.766108
106.4,1.77375,1.742563,0.1742563,0,0,0,0,0,1.77375,1.77375,1.77375,1.77692
106.8,1.779687,1.74583,0.174583,0,0,0,0,0,1.779687,1.779687,1.779687,1.780251
107.2,1.78625,1.753921,0.1753921,0,0,0,0,0,1.78625,1.78625,1.78625,1.788501
107.6,1.792968,1.763486,0.1763486,0,0,0,0,0,1.792969,1.792969,1.792968,1.798255
108,1.800312,1.775625,0.1775625,0,0,0,0,0,1.800312,1.800312,1.800312,1.810634
108.4,1.806719,1.781454,0.1781454,0,0,0,0,0,1.806719,1.806719,1.806719,1.816577
108.8,1.813437,1.787922,0.1787922,0,0,0,0,0,1.813437,1.813437,1.813437,1.823173
109.2,1.819844,1.792678,0.1792678,0,0,0,0,0,1.819844,1.819844,1.819844,1.828023
109.6,1.826406,1.80076,0.180076,0,0,0,0,0,1.826406,1.826406,1.826406,1.836265
110,1.833281,1.810116,0.1810116,0,0,0,0,0,1.833281,1.833281,1.833281,1.845805
110.4,1.839687,1.817247,0.1817247,0,0,0,0,0,1.839687,1.839687,1.839687,1.853077
110.8,1.846406,1.823073,0.1823073,0,0,0,0,0,1.846406,1.846406,1.846406,1.859017
111.2,1.853594,1.835587,0.1835587,0,0,0,0,0,1.853593,1.853593,1.853594,1.871778
111.6,1.860469,1.842471,0.1842471,0,0,0,0,0,1.860469,1.860469,1.860469,1.878798
112,1.866562,1.847222,0.1847222,0,0,0,0,0,1.866562,1.866562,1.866562,1.883642
112.4,1.872969,1.85398,0.185398,0,0,0,0,0,1.872969,1.872969,1.872969,1.890534
112.8,1.879687,1.846684,0.1846684,0,0,0,0,0,1.879687,1.879687,1.879687,1.883093
113.2,1.886719,1.855679,0.1855679,0,0,0,0,0,1.886719,1.886719,1.886719,1.892266
113.6,1.893437,1.861634,0.1861635,0,0,0,0,0,1.893437,1.893437,1.893437,1.898339
114,1.9,1.867092,0.1867092,0,0,0,0,0,1.9,1.9,1.9,1.903904
114.4,1.90625,1.87243,0.187243,0,0,0,0,0,1.90625,1.90625,1.90625,1.909347
114.8,1.913281,1.883487,0.1883487,0,0,0,0,0,1.913281,1.913281,1.913281,1.920622
115.2,1.92,1.884613,0.1884613,0,0,0,0,0,1.92,1.92,1.92,1.92177
115.6,1.926562,1.891557,0.1891557,0,0,0,0,0,1.926562,1.926562,1.926562,1.928851
116,1.933125,1.897597,0.1897597,0,0,0,0,0,1.933125,1.933125,1.933125,1.935011
116.4,1.940156,1.905867,0.1905867,0,0,0,0,0,1.940156,1.940156,1.940156,1.943443
116.8,1.946562,1.911367,0.1911367,0,0,0,0,0,1.946562,1.946562,1.946562,1.949052
117.2,1.953125,1.919406,0.1919405,0,0,0,0,0,1.953125,1.953125,1.953125,1.957249
117.6,1.959687,1.924386,0.1924386,0,0,0,0,0,1.959687,1.959687,1.959687,1.962327
118,1.966562,1.9338,0.19338,0,0,0,0,0,1.966562,1.966562,1.966562,1.971927
118.4,1.973593,1.943267,0.1943267,0,0,0,0,0,1.973593,1.973593,1.973593,1.98158
118.8,1.980156,1.854058,0.1854058,0,0,0,0,0,1.980156,1.980156,1.980156,1.890613
119.2,1.986718,1.861598,0.1861598,0,0,0,0,0,1.986718,1.986718,1.986718,1.898301
119.6,1.992968,1.871682,0.1871682,0,0,0,0,0,1.992968,1.992968,1.992968,1.908584
120,2.000156,1.886912,0.1886912,0,0,0,0,0,2.000156,2.000156,2.000156,1.924115
120.4,2.006406,1.894542,0.1894542,0,0,0,0,0,2.006406,2.006406,2.006406,1.931895
120.8,2.012968,1.906618,0.1906618,0,0,0,0,0,2.012968,2.012968,2.012968,1.94421
121.2,2.019843,1.918694,0.1918694,0,0,0,0,0,2.019843,2.019843,2.019843,1.956523
121.6,2.027031,1.932999,0.1932999,0,0,0,0,0,2.027031,2.027031,2.027031,1.971111
122,2.033281,1.942215,0.1942215,0,0,0,0,0,2.033281,2.033281,2.033281,1.980508
122.4,2.039687,1.953626,0.1953626,0,0,0,0,0,2.039687,2.039687,2.039687,1.992145
122.8,2.046406,1.966468,0.1966468,0,0,0,0,0,2.046406,2.046406,2.046406,2.00524
123.2,2.053281,1.97888,0.197888,0,0,0,0,0,2.053281,2.053281,2.053281,2.017896
123.6,2.06,1.989905,0.1989905,0,0,0,0,0,2.06,2.06,2.06,2.029138
124,2.066718,1.998745,0.1998745,0,0,0,0,0,2.066718,2.066718,2.066718,2.038152
124.4,2.072812,2.004292,0.2004292,0,0,0,0,0,2.072812,2.072812,2.072812,2.043809
124.8,2.079843,2.011155,0.2011155,0,0,0,0,0,2.079843,2.079843,2.079843,2.050807
125.2,2.086875,2.023831,0.2023831,0,0,0,0,0,2.086874,2.086874,2.086875,2.063734
125.6,2.093281,2.031182,0.2031182,0,0,0,0,0,2.093281,2.093281,2.093281,2.071229
126,2.099687,2.037401,0.2037401,0,0,0,0,0,2.099687,2.099687,2.099687,2.07757
126.4,2.106562,2.047037,0.2047037,0,0,0,0,0,2.106562,2.106562,2.106562,2.087397
126.8,2.113437,2.056846,0.2056846,0,0,0,0,0,2.113437,2.113437,2.113437,2.097399
127.2,2.12,2.065538,0.2065538,0,0,0,0,0,2.12,2.12,2.12,2.106262
127.6,2.126249,2.073555,0.2073555,0,0,0,0,0,2.12625,2.12625,2.126249,2.114438
128,2.132968,2.082792,0.2082792,0,0,0,0,0,2.132968,2.132968,2.132968,2.123857
128.4,2.140156,2.09423,0.209423,0,0,0,0,0,2.140156,2.140156,2.140156,2.13552
128.8,2.146718,2.1007,0.21007,0,0,0,0,0,2.146718,2.146718,2.146718,2.142118
129.2,2.153281,2.10847,0.210847,0,0,0,0,0,2.153281,2.153281,2.153281,2.150041
129.6,2.159531,2.114495,0.2114495,0,0,0,0,0,2.159531,2.159531,2.159531,2.156185
130,2.166562,2.124768,0.2124768,0,0,0,0,0,2.166562,2.166562,2.166562,2.16666
130.4,2.173593,2.135493,0.2135493,0,0,0,0,0,2.173593,2.173593,2.173593,2.177597
130.8,2.18,2.138732,0.2138732,0,0,0,0,0,2.18,2.18,2.18,2.180899
131.2,2.186406,2.145538,0.2145538,0,0,0,0,0,2.186406,2.186406,2.186406,2.18784
131.6,2.193437,2.155159,0.2155159,0,0,0,0,0,2.193437,2.193437,2.193437,2.197651
132,2.200156,2.163107,0.2163107,0,0,0,0,0,2.200156,2.200156,2.200156,2.205755
132.4,2.206718,2.170485,0.2170485,0,0,0,0,0,2.206718,2.206718,2.206718,2.213278
132.8,2.212968,2.175507,0.2175507,0,0,0,0,0,2.212968,2.212968,2.212968,2.2184
133.2,2.219687,2.183514,0.2183513,0,0,0,0,0,2.219687,2.219687,2.219687,2.226564
133.6,2.226875,2.193007,0.2193007,0,0,0,0,0,2.226875,2.226875,2.226875,2.236245
134,2.233749,2.19969,0.219969,0,0,0,0,0,2.233749,2.233749,2.233749,2.24306
134.4,2.239531,2.202648,0.2202649,0,0,0,0,0,2.239531,2.239531,2.239531,2.246076
134.8,2.246406,2.212061,0.2212061,0,0,0,0,0,2.246406,2.246406,2.246406,2.255675
135.2,2.253437,2.223674,0.2223674,0,0,0,0,0,2.253437,2.253437,2.253437,2.267516
135.6,2.260156,2.231064,0.2231064,0,0,0,0,0,2.260156,2.260156,2.260156,2.275052
136,2.266718,2.237457,0.2237457,0,0,0,0,0,2.266718,2.266718,2.266718,2.281571
136.4,2.273125,2.242453,0.2242453,0,0,0,0,0,2.273125,2.273125,2.273125,2.286666
136.8,2.279843,2.247622,0.2247622,0,0,0,0,0,2.279843,2.279843,2.279843,2.291937
137.2,2.286875,2.256755,0.2256755,0,0,0,0,0,2.286875,2.286875,2.286875,2.30125
137.6,2.293281,2.262718,0.2262718,0,0,0,0,0,2.293281,2.293281,2.293281,2.30733
138,2.299687,2.267049,0.2267049,0,0,0,0,0,2.299687,2.299687,2.299687,2.311746
138.4,2.306562,2.274688,0.2274688,0,0,0,0,0,2.306562,2.306562,2.306562,2.319536
138.8,2.313906,2.283139,0.2283139,0,0,0,0,0,2.313906,2.313906,2.313906,2.328154
139.2,2.32,2.282346,0.2282346,0,0,0,0,0,2.319999,2.319999,2.32,2.327345
139.6,2.32625,2.289344,0.2289344,0,0,0,0,0,2.32625,2.32625,2.32625,2.334481
140,2.332968,2.29693,0.229693,0,0,0,0,0,2.332968,2.332968,2.332968,2.342216
140.4,2.34,2.304233,0.2304233,0,0,0,0,0,2.34,2.34,2.34,2.349664
140.8,2.346718,2.312761,0.2312761,0,0,0,0,0,2.346719,2.346719,2.346718,2.35836
141.2,2.353125,2.318321,0.2318321,0,0,0,0,0,2.353125,2.353125,2.353125,2.36403
141.6,2.359687,2.320548,0.2320548,0,0,0,0,0,2.359687,2.359687,2.359687,2.3663
142,2.366562,2.329198,0.2329198,0,0,0,0,0,2.366562,2.366562,2.366562,2.375121
142.4,2.373281,2.333872,0.2333872,0,0,0,0,0,2.373281,2.373281,2.373281,2.379887
142.8,2.379843,2.340492,0.2340492,0,0,0,0,0,2.379843,2.379843,2.379843,2.386638
143.2,2.38625,2.346215,0.2346215,0,0,0,0,0,2.38625,2.38625,2.38625,2.392473
143.6,2.393281,2.355639,0.2355639,0,0,0,0,0,2.393281,2.393281,2.393281,2.402084
144,2.400312,2.360187,0.2360187,0,0,0,0,0,2.400312,2.400312,2.400312,2.406721
144.4,2.406406,2.353363,0.2353363,0,0,0,0,0,2.406406,2.406406,2.406406,2.399763
144.8,2.412968,2.36166,0.236166,0,0,0,0,0,2.412968,2.412968,2.412968,2.408223
145.2,2.419843,2.367884,0.2367884,0,0,0,0,0,2.419843,2.419843,2.419843,2.41457
145.6,2.427031,2.375756,0.2375756,0,0,0,0,0,2.427031,2.427031,2.427031,2.422596
146,2.433437,2.37999,0.237999,0,0,0,0,0,2.433437,2.433437,2.433437,2.426914
146.4,2.439999,2.383318,0.2383318,0,0,0,0,0,2.44,2.44,2.439999,2.430308
146.8,2.44625,2.386201,0.2386201,0,0,0,0,0,2.446249,2.446249,2.44625,2.433248
147.2,2.453125,2.362486,0.2362486,0,0,0,0,0,2.453125,2.453125,2.453125,2.409066
147.408,2.456718,1.9094,0.19094,0,0,0,0,0,2.456718,2.456718,2.456718,1.947046
147.546,2.459062,1.480166,0.1480166,0,0,0,0,0,2.459062,2.459062,2.459062,1.509349
147.946,2.465468,1.448074,0.1448074,0,0,0,0,0,2.465468,2.465468,2.465468,1.476625
148.346,2.472187,1.44638,0.144638,0,0,0,0,0,2.472187,2.472187,2.472187,1.474897
148.746,2.479375,1.45137,0.145137,0,0,0,0,0,2.479375,2.479375,2.479375,1.479986
149.146,2.485937,1.454017,0.1454017,0,0,0,0,0,2.485937,2.485937,2.485937,1.482684
149.546,2.492343,1.458931,0.1458931,0,0,0,0,0,2.492343,2.492343,2.492343,1.487696
149.946,2.49875,1.463223,0.1463223,0,0,0,0,0,2.49875,2.49875,2.49875,1.492072
150.346,2.505625,1.468353,0.1468353,0,0,0,0,0,2.505625,2.505625,2.505625,1.497303
150.746,2.512656,1.471418,0.1471418,0,0,0,0,0,2.512656,2.512656,2.512656,1.500429
151.146,2.519218,1.470236,0.1470236,0,0,0,0,0,2.519218,2.519218,2.519218,1.499223
151.546,2.525781,1.470705,0.1470705,0,0,0,0,0,2.525781,2.525781,2.525781,1.499702
151.946,2.532187,1.466254,0.1466254,0,0,0,0,0,2.532187,2.532187,2.532187,1.495163
152.346,2.539375,1.472687,0.1472687,0,0,0,0,0,2.539375,2.539375,2.539375,1.501722
152.746,2.545937,1.479713,0.1479713,0,0,0,0,0,2.545937,2.545937,2.545937,1.508888
153.146,2.552343,1.485027,0.1485027,0,0,0,0,0,2.552343,2.552343,2.552343,1.514306
153.546,2.558906,1.496841,0.1496841,0,0,0,0,0,2.558906,2.558906,2.558906,1.526353
153.946,2.566093,1.508052,0.1508052,0,0,0,0,0,2.566093,2.566093,2.566093,1.537785
154.346,2.572343,1.517126,0.1517126,0,0,0,0,0,2.572343,2.572343,2.572343,1.547038
154.746,2.57875,1.527218,0.1527218,0,0,0,0,0,2.57875,2.57875,2.57875,1.557329
155.146,2.585468,1.537848,0.1537848,0,0,0,0,0,2.585468,2.585468,2.585468,1.568169
155.546,2.592343,1.549076,0.1549076,0,0,0,0,0,2.592343,2.592343,2.592343,1.579618
155.946,2.599375,1.555086,0.1555085,0,0,0,0,0,2.599375,2.599375,2.599375,1.585746
156.346,2.605937,1.562623,0.1562624,0,0,0,0,0,2.605937,2.605937,2.605937,1.593433
156.746,2.612343,1.569467,0.1569467,0,0,0,0,0,2.612343,2.612343,2.612343,1.600411
157.146,2.61875,1.578225,0.1578225,0,0,0,0,0,2.61875,2.61875,2.61875,1.609342
157.546,2.625937,1.590388,0.1590388,0,0,0,0,0,2.625937,2.625937,2.625937,1.621745
157.946,2.632187,1.597803,0.1597802,0,0,0,0,0,2.632187,2.632187,2.632187,1.629305
158.346,2.63875,1.605268,0.1605268,0,0,0,0,0,2.63875,2.63875,2.63875,1.636918
158.746,2.645625,1.611566,0.1611566,0,0,0,0,0,2.645625,2.645625,2.645625,1.64334
159.146,2.652812,1.620394,0.1620394,0,0,0,0,0,2.652812,2.652812,2.652812,1.652342
159.546,2.659062,1.625993,0.1625993,0,0,0,0,0,2.659062,2.659062,2.659062,1.658052
159.946,2.665468,1.632681,0.1632681,0,0,0,0,0,2.665468,2.665468,2.665468,1.664871
160.346,2.672031,1.643309,0.1643309,0,0,0,0,0,2.672031,2.672031,2.672031,1.675709
160.746,2.679062,1.653988,0.1653988,0,0,0,0,0,2.679062,2.679062,2.679062,1.686598
161.146,2.685937,1.663619,0.1663619,0,0,0,0,0,2.685937,2.685937,2.685937,1.696419
161.546,2.6925,1.669646,0.1669646,0,0,0,0,0,2.6925,2.6925,2.6925,1.702565
161.946,2.698593,1.676245,0.1676245,0,0,0,0,0,2.698593,2.698593,2.698593,1.709294
162.346,2.705625,1.687995,0.1687995,0,0,0,0,0,2.705625,2.705625,2.705625,1.721275
162.746,2.712656,1.699008,0.1699008,0,0,0,0,0,2.712656,2.712656,2.712656,1.732506
163.146,2.719062,1.701655,0.1701655,0,0,0,0,0,2.719062,2.719062,2.719062,1.735205
163.546,2.725624,1.702451,0.1702451,0,0,0,0,0,2.725625,2.725625,2.725624,1.736017
163.946,2.732343,1.698594,0.1698594,0,0,0,0,0,2.732343,2.732343,2.732343,1.732084
164.346,2.739062,1.702737,0.1702737,0,0,0,0,0,2.739062,2.739062,2.739062,1.736308
164.746,2.745625,1.709606,0.1709606,0,0,0,0,0,2.745625,2.745625,2.745625,1.743312
165.146,2.752031,1.716829,0.171683,0,0,0,0,0,2.752031,2.752031,2.752031,1.750679
165.546,2.758906,1.724821,0.1724821,0,0,0,0,0,2.758906,2.758906,2.758906,1.758828
165.946,2.766093,1.734241,0.1734241,0,0,0,0,0,2.766093,2.766093,2.766093,1.768433
166.346,2.772656,1.739134,0.1739134,0,0,0,0,0,2.772656,2.772656,2.772656,1.773424
166.746,2.778906,1.742948,0.1742948,0,0,0,0,0,2.778906,2.778906,2.778906,1.777312
167.146,2.785312,1.750696,0.1750696,0,0,0,0,0,2.785312,2.785312,2.785312,1.785214
167.546,2.792343,1.761268,0.1761268,0,0,0,0,0,2.792343,2.792343,2.792343,1.795994
167.946,2.799218,1.769905,0.1769905,0,0,0,0,0,2.799218,2.799218,2.799218,1.8048
168.346,2.805781,1.772983,0.1772983,0,0,0,0,0,2.805781,2.805781,2.805781,1.80794
168.746,2.812343,1.779023,0.1779023,0,0,0,0,0,2.812343,2.812343,2.812343,1.814099
169.146,2.819218,1.782599,0.1782599,0,0,0,0,0,2.819218,2.819218,2.819218,1.817746
169.546,2.825937,1.786657,0.1786657,0,0,0,0,0,2.825937,2.825937,2.825937,1.821883
169.946,2.832343,1.78989,0.178989,0,0,0,0,0,2.832343,2.832343,2.832343,1.825179
170.346,2.83875,1.794227,0.1794227,0,0,0,0,0,2.83875,2.83875,2.83875,1.829603
170.746,2.845468,1.799534,0.1799534,0,0,0,0,0,2.845468,2.845468,2.845468,1.835014
171.146,2.852656,1.804857,0.1804857,0,0,0,0,0,2.852656,2.852656,2.852656,1.840442
171.546,2.859218,1.807141,0.1807141,0,0,0,0,0,2.859218,2.859218,2.859218,1.842771
171.946,2.865312,1.809037,0.1809037,0,0,0,0,0,2.865312,2.865312,2.865312,1.844705
172.346,2.872187,1.811868,0.1811868,0,0,0,0,0,2.872187,2.872187,2.872187,1.847591
172.746,2.879375,1.819348,0.1819348,0,0,0,0,0,2.879375,2.879375,2.879375,1.855219
173.146,2.885781,1.818627,0.1818627,0,0,0,0,0,2.885781,2.885781,2.885781,1.854483
173.546,2.8925,1.826457,0.1826456,0,0,0,0,0,2.892499,2.892499,2.8925,1.862467
173.946,2.899062,1.831914,0.1831914,0,0,0,0,0,2.899062,2.899062,2.899062,1.868032
174.346,2.905781,1.839185,0.1839185,0,0,0,0,0,2.905781,2.905781,2.905781,1.875447
174.746,2.912499,1.847095,0.1847095,0,0,0,0,0,2.912499,2.912499,2.912499,1.883513
175.146,2.918906,1.848809,0.1848809,0,0,0,0,0,2.918906,2.918906,2.918906,1.885261
175.546,2.925468,1.851931,0.1851931,0,0,0,0,0,2.925468,2.925468,2.925468,1.888444
175.946,2.932343,1.85279,0.185279,0,0,0,0,0,2.932343,2.932343,2.932343,1.88932
176.346,2.939531,1.858038,0.1858038,0,0,0,0,0,2.939531,2.939531,2.939531,1.894671
176.746,2.945781,1.856654,0.1856654,0,0,0,0,0,2.945781,2.945781,2.945781,1.89326
177.146,2.952031,1.848694,0.1848694,0,0,0,0,0,2.952031,2.952031,2.952031,1.885143
177.546,2.958906,1.845665,0.1845665,0,0,0,0,0,2.958906,2.958906,2.958906,1.882055
177.946,2.965781,1.849313,0.1849313,0,0,0,0,0,2.965781,2.965781,2.965781,1.885774
178.346,2.972343,1.849717,0.1849717,0,0,0,0,0,2.972343,2.972343,2.972343,1.886187
178.746,2.97875,1.851807,0.1851807,0,0,0,0,0,2.97875,2.97875,2.97875,1.888318
179.146,2.985468,1.853836,0.1853836,0,0,0,0,0,2.985468,2.985468,2.985468,1.890387
179.546,2.992343,1.859564,0.1859564,0,0,0,0,0,2.992343,2.992343,2.992343,1.896227
179.946,2.999062,1.866682,0.1866682,0,0,0,0,0,2.999062,2.999062,2.999062,1.903485
180.346,3.005468,1.870699,0.1870699,0,0,0,0,0,3.005468,3.005468,3.005468,1.907582
180.746,3.012187,1.877121,0.1877121,0,0,0,0,0,3.012187,3.012187,3.012187,1.914131
181.146,3.019062,1.884231,0.1884231,0,0,0,0,0,3.019062,3.019062,3.019062,1.921381
181.546,3.026093,1.893779,0.1893779,0,0,0,0,0,3.026093,3.026093,3.026093,1.931117
181.946,3.032031,1.89721,0.189721,0,0,0,0,0,3.032031,3.032031,3.032031,1.934616
182.346,3.038593,1.903643,0.1903643,0,0,0,0,0,3.038593,3.038593,3.038593,1.941175
182.746,3.045625,1.909858,0.1909858,0,0,0,0,0,3.045624,3.045624,3.045625,1.947513
183.146,3.052656,1.914873,0.1914873,0,0,0,0,0,3.052656,3.052656,3.052656,1.952627
183.546,3.059218,1.898752,0.1898752,0,0,0,0,0,3.059218,3.059218,3.059218,1.936188
183.946,3.065781,1.894557,0.1894557,0,0,0,0,0,3.065781,3.065781,3.065781,1.931911
184.346,3.072031,1.889836,0.1889836,0,0,0,0,0,3.072031,3.072031,3.072031,1.927097
184.746,3.079062,1.893893,0.1893893,0,0,0,0,0,3.079062,3.079062,3.079062,1.931233
185.146,3.085781,1.891812,0.1891812,0,0,0,0,0,3.085781,3.085781,3.085781,1.929112
185.546,3.092031,1.882169,0.1882169,0,0,0,0,0,3.092031,3.092031,3.092031,1.919278
185.946,3.098906,1.883823,0.1883823,0,0,0,0,0,3.098906,3.098906,3.098906,1.920964
186.346,3.106093,1.889296,0.1889296,0,0,0,0,0,3.106093,3.106093,3.106093,1.926546
186.746,3.112343,1.890235,0.1890235,0,0,0,0,0,3.112343,3.112343,3.112343,1.927503
187.146,3.118906,1.893802,0.1893802,0,0,0,0,0,3.118906,3.118906,3.118906,1.93114
187.546,3.125468,1.899817,0.1899817,0,0,0,0,0,3.125468,3.125468,3.125468,1.937274
187.946,3.132187,1.90656,0.190656,0,0,0,0,0,3.132187,3.132187,3.132187,1.94415
188.346,3.139218,1.912603,0.1912603,0,0,0,0,0,3.139218,3.139218,3.139218,1.950312
188.746,3.145781,1.916385,0.1916385,0,0,0,0,0,3.145781,3.145781,3.145781,1.954169
189.146,3.152343,1.919987,0.1919987,0,0,0,0,0,3.152343,3.152343,3.152343,1.957842
189.546,3.158906,1.924362,0.1924362,0,0,0,0,0,3.158906,3.158906,3.158906,1.962303
189.946,3.165937,1.927205,0.1927205,0,0,0,0,0,3.165937,3.165937,3.165937,1.965203
190.346,3.1725,1.929104,0.1929104,0,0,0,0,0,3.1725,3.1725,3.1725,1.967138
190.746,3.178749,1.931513,0.1931513,0,0,0,0,0,3.17875,3.17875,3.178749,1.969595
191.146,3.185468,1.936104,0.1936104,0,0,0,0,0,3.185468,3.185468,3.185468,1.974276
191.546,3.192812,1.94222,0.194222,0,0,0,0,0,3.192812,3.192812,3.192812,1.980513
191.946,3.198906,1.941468,0.1941468,0,0,0,0,0,3.198906,3.198906,3.198906,1.979747
192.346,3.205468,1.808394,0.1808394,0,0,0,0,0,3.205468,3.205468,3.205468,1.844049
192.492,3.207968,1.218979,0.1218979,0,0,0,0,0,3.207968,3.207968,3.207968,1.243013
192.712,3.211562,0.9112741,0.09112741,0,0,0,0,0,3.211562,3.211562,3.211562,0.9292409
193.112,3.218437,0.9225481,0.09225481,0,0,0,0,0,3.218437,3.218437,3.218437,0.9407372
193.512,3.225468,0.9337498,0.09337498,0,0,0,0,0,3.225468,3.225468,3.225468,0.9521598
193.912,3.231875,0.9441513,0.09441513,0,0,0,0,0,3.231875,3.231875,3.231875,0.9627663
194.312,3.238125,0.9529413,0.09529413,0,0,0,0,0,3.238125,3.238125,3.238125,0.9717296
194.712,3.244843,0.9631655,0.09631655,0,0,0,0,0,3.244843,3.244843,3.244843,0.9821555
195.112,3.251875,0.9741486,0.09741486,0,0,0,0,0,3.251875,3.251875,3.251875,0.9933552
195.512,3.258437,0.9825516,0.09825516,0,0,0,0,0,3.258437,3.258437,3.258437,1.001924
195.912,3.264843,0.9925354,0.09925354,0,0,0,0,0,3.264843,3.264843,3.264843,1.012105
196.312,3.271875,1.002961,0.1002961,0,0,0,0,0,3.271874,3.271874,3.271875,1.022735
196.712,3.27875,1.013364,0.1013364,0,0,0,0,0,3.278749,3.278749,3.27875,1.033344
197.112,3.285,1.023219,0.1023219,0,0,0,0,0,3.285,3.285,3.285,1.043393
197.512,3.291562,1.03281,0.103281,0,0,0,0,0,3.291562,3.291562,3.291562,1.053173
197.912,3.298125,1.042579,0.1042579,0,0,0,0,0,3.298125,3.298125,3.298125,1.063134
198.312,3.305312,1.053925,0.1053925,0,0,0,0,0,3.305312,3.305312,3.305312,1.074705
198.712,3.312031,1.063409,0.1063409,0,0,0,0,0,3.312031,3.312031,3.312031,1.084375
199.112,3.318437,1.071417,0.1071417,0,0,0,0,0,3.318437,3.318437,3.318437,1.092541
199.512,3.324687,1.079129,0.1079129,0,0,0,0,0,3.324687,3.324687,3.324687,1.100406
199.912,3.331718,1.090155,0.1090155,0,0,0,0,0,3.331718,3.331718,3.331718,1.111649
200.312,3.33875,1.099898,0.1099899,0,0,0,0,0,3.338749,3.338749,3.33875,1.121584
200.712,3.345156,1.096886,0.1096886,0,0,0,0,0,3.345156,3.345156,3.345156,1.118513
201.112,3.351875,1.10294,0.110294,0,0,0,0,0,3.351875,3.351875,3.351875,1.124686
201.512,3.358593,1.111153,0.1111153,0,0,0,0,0,3.358593,3.358593,3.358593,1.13306
201.912,3.365156,1.118304,0.1118304,0,0,0,0,0,3.365156,3.365156,3.365156,1.140353
202.312,3.371718,1.125498,0.1125498,0,0,0,0,0,3.371718,3.371718,3.371718,1.147689
202.712,3.378125,1.133956,0.1133956,0,0,0,0,0,3.378125,3.378125,3.378125,1.156313
203.112,3.384999,1.142249,0.1142249,0,0,0,0,0,3.385,3.385,3.384999,1.16477
203.512,3.392187,1.146467,0.1146467,0,0,0,0,0,3.392187,3.392187,3.392187,1.169071
203.912,3.398906,1.152757,0.1152757,0,0,0,0,0,3.398906,3.398906,3.398906,1.175485
204.312,3.404843,1.156971,0.1156971,0,0,0,0,0,3.404843,3.404843,3.404843,1.179782
204.712,3.411562,1.164961,0.1164961,0,0,0,0,0,3.411562,3.411562,3.411562,1.187929
205.112,3.418437,1.172085,0.1172085,0,0,0,0,0,3.418437,3.418437,3.418437,1.195194
205.512,3.425156,1.169774,0.1169774,0,0,0,0,0,3.425156,3.425156,3.425156,1.192837
205.912,3.431718,1.173307,0.1173307,0,0,0,0,0,3.431718,3.431718,3.431718,1.19644
206.312,3.438437,1.178183,0.1178183,0,0,0,0,0,3.438437,3.438437,3.438437,1.201412
206.712,3.445156,1.184384,0.1184384,0,0,0,0,0,3.445156,3.445156,3.445156,1.207736
207.112,3.452031,1.190184,0.1190184,0,0,0,0,0,3.452031,3.452031,3.452031,1.21365
207.512,3.458593,1.195566,0.1195566,0,0,0,0,0,3.458593,3.458593,3.458593,1.219138
207.912,3.464843,1.201089,0.1201089,0,0,0,0,0,3.464843,3.464843,3.464843,1.22477
208.312,3.471718,1.20776,0.120776,0,0,0,0,0,3.471718,3.471718,3.471718,1.231572
208.712,3.478906,1.214837,0.1214837,0,0,0,0,0,3.478906,3.478906,3.478906,1.238788
209.112,3.485156,1.214474,0.1214474,0,0,0,0,0,3.485156,3.485156,3.485156,1.238419
209.512,3.491562,1.214907,0.1214907,0,0,0,0,0,3.491562,3.491562,3.491562,1.23886
209.912,3.498281,1.219459,0.1219459,0,0,0,0,0,3.498281,3.498281,3.498281,1.243502
210.312,3.505468,1.228212,0.1228212,0,0,0,0,0,3.505468,3.505468,3.505468,1.252428
210.712,3.511874,1.233797,0.1233797,0,0,0,0,0,3.511874,3.511874,3.511874,1.258123
211.112,3.518437,1.240163,0.1240163,0,0,0,0,0,3.518437,3.518437,3.518437,1.264615
211.512,3.525,1.245096,0.1245096,0,0,0,0,0,3.525,3.525,3.525,1.269645
211.912,3.531875,1.251028,0.1251028,0,0,0,0,0,3.531875,3.531875,3.531875,1.275694
212.312,3.538437,1.256126,0.1256126,0,0,0,0,0,3.538437,3.538437,3.538437,1.280892
212.712,3.545,1.26206,0.126206,0,0,0,0,0,3.545,3.545,3.545,1.286943
213.112,3.551562,1.267381,0.1267381,0,0,0,0,0,3.551562,3.551562,3.551562,1.292369
213.512,3.558437,1.26046,0.126046,0,0,0,0,0,3.558437,3.558437,3.558437,1.285312
213.912,3.565625,1.263583,0.1263583,0,0,0,0,0,3.565624,3.565624,3.565625,1.288496
214.312,3.571718,1.254965,0.1254965,0,0,0,0,0,3.571718,3.571718,3.571718,1.279708
214.712,3.578125,1.256071,0.1256071,0,0,0,0,0,3.578125,3.578125,3.578125,1.280836
215.112,3.585,1.260352,0.1260352,0,0,0,0,0,3.585,3.585,3.585,1.285201
215.512,3.591875,1.265026,0.1265026,0,0,0,0,0,3.591875,3.591875,3.591875,1.289968
215.912,3.598437,1.265483,0.1265483,0,0,0,0,0,3.598437,3.598437,3.598437,1.290434
216.312,3.604843,1.25013,0.125013,0,0,0,0,0,3.604843,3.604843,3.604843,1.274778
216.712,3.611562,1.251274,0.1251274,0,0,0,0,0,3.611562,3.611562,3.611562,1.275944
217.112,3.618437,1.256358,0.1256358,0,0,0,0,0,3.618437,3.618437,3.618437,1.281129
217.512,3.625312,1.261126,0.1261126,0,0,0,0,0,3.625312,3.625312,3.625312,1.28599
217.576,3.626406,1.262257,0.1262257,0,0,0,0,0,3.626406,3.626406,3.626406,1.287144