File: dataFiles/staticInstron_6.raw
"Test Type","Tension"
"Method Name","C:\Users\mmen339\Documents\tension test 1mm_s.im_tens"
"Sample name","C:\Users\mmen339\Documents\sample 4\S4.Failure.is_tens"
"User",""
"Sample note 1",""
"Sample note 2",""
"Sample note 3",""
"Geometry","Rectangular"
"Specimen",1
"Specimen label",""
"Width",10.000000,"mm"
"Thickness",1.000000,"mm"
"Length",100.000000,"mm"
"Diameter",10.000000,"mm"
"Inner diameter",8.000000,"mm"
"Outer diameter",10.000000,"mm"
"Wall thickness",1.000000,"mm"
"Area",0.100000,"cm^2"
"Linear density",100.000000,"tex"
"Sled weight",10.000000,"N"
"Loading span",10.000000,"mm"
"Support span",100.000000,"mm"
"Span ratio","2"
"Fixture type","4-point"
"Included"
"Final width",10.000000,"mm"
"Final thickness",1.000000,"mm"
"Final length",100.000000,"mm"
"Final diameter",10.000000,"mm"
"Final Inner diameter",8.000000,"mm"
"Final outer diameter",10.000000,"mm"
"Final wall thickness",1.000000,"mm"
"Final area",0.100000,"cm^2"
"Final linear density",100.000000,"tex"
"Custom text input  1",""
"Custom text input  2",""
"Custom text input  3",""
"Custom text input  4",""
"Custom text input  5",""
"Custom text input  6",""
"Custom text input  7",""
"Custom text input  8",""
"Custom text input  9",""
"Custom text input 10",""
"Custom text input 11",""
"Custom text input 12",""
"Custom text input 13",""
"Custom text input 14",""
"Custom text input 15",""
"Custom text input 16",""
"Custom text input 17",""
"Custom text input 18",""
"Custom text input 19",""
"Custom text input 20",""
"Custom text input 21",""
"Custom text input 22",""
"Custom text input 23",""
"Custom text input 24",""
"Custom text input 25",""
"Custom text input 26",""
"Custom text input 27",""
"Custom text input 28",""
"Custom text input 29",""
"Custom text input 30",""
"Custom text input 31",""
"Custom text input 32",""
"Custom text input 33",""
"Custom text input 34",""
"Custom text input 35",""
"Custom text input 36",""
"Custom text input 37",""
"Custom text input 38",""
"Custom text input 39",""
"Custom text input 40",""
"Custom text input 41",""
"Custom text input 42",""
"Custom text input 43",""
"Custom text input 44",""
"Custom text input 45",""
"Custom text input 46",""
"Custom text input 47",""
"Custom text input 48",""
"Custom text input 49",""
"Custom text input 50",""
"Custom number input  1",0.000000,""
"Custom number input  2",0.000000,""
"Custom number input  3",0.000000,""
"Custom number input  4",0.000000,""
"Custom number input  5",0.000000,""
"Custom number input  6",0.000000,""
"Custom number input  7",0.000000,""
"Custom number input  8",0.000000,""
"Custom number input  9",0.000000,""
"Custom number input 10",0.000000,""
"Time sec","Extension mm","Load N","Tensile stress MPa","Cycle Count ","Total Cycle Count ","Repetitions Count ","Marked Data ","PIP Count ","Tensile extension mm","Tensile strain %","Corrected Position mm","Tenacity gf/tex"
0,0,-0.0002483182,-2.483182e-005,0,0,0,0,0,0,0,0,-0.0002532142
0.5,0.004999999,0.1138413,0.01138413,0,0,0,0,0,0.004999999,0.004999999,0.004999999,0.1160859
1,0.01671875,0.3814461,0.03814461,0,0,0,0,0,0.01671875,0.01671875,0.01671875,0.3889667
1.5,0.02453125,0.5307495,0.05307495,0,0,0,0,0,0.02453125,0.02453125,0.02453125,0.5412139
2,0.03296874,0.6859532,0.06859532,0,0,0,0,0,0.03296874,0.03296874,0.03296874,0.6994776
2.5,0.04156249,0.835204,0.0835204,0,0,0,0,0,0.04156249,0.04156249,0.04156249,0.8516711
3,0.05046875,0.9769059,0.09769059,0,0,0,0,0,0.05046875,0.05046875,0.05046875,0.9961668
3.5,0.05859374,1.090021,0.1090021,0,0,0,0,0,0.05859374,0.05859374,0.05859374,1.111512
4,0.06640624,1.192191,0.1192191,0,0,0,0,0,0.06640624,0.06640624,0.06640624,1.215697
4.5,0.07515624,1.283044,0.1283045,0,0,0,0,0,0.07515624,0.07515624,0.07515624,1.308341
5,0.08343749,1.374101,0.1374101,0,0,0,0,0,0.08343749,0.08343749,0.08343749,1.401193
5.5,0.09156248,1.457037,0.1457037,0,0,0,0,0,0.09156249,0.09156249,0.09156248,1.485765
6,0.1003125,1.546003,0.1546003,0,0,0,0,0,0.1003125,0.1003125,0.1003125,1.576484
6.5,0.1084375,1.614046,0.1614046,0,0,0,0,0,0.1084375,0.1084375,0.1084375,1.645869
7,0.1165625,1.663596,0.1663596,0,0,0,0,0,0.1165625,0.1165625,0.1165625,1.696396
7.5,0.1248437,1.722439,0.1722439,0,0,0,0,0,0.1248437,0.1248437,0.1248437,1.756399
8,0.13375,1.781344,0.1781344,0,0,0,0,0,0.13375,0.13375,0.13375,1.816466
8.5,0.141875,1.821036,0.1821036,0,0,0,0,0,0.141875,0.141875,0.141875,1.85694
9,0.1496875,1.876731,0.1876731,0,0,0,0,0,0.1496875,0.1496875,0.1496875,1.913733
9.5,0.1585937,1.945518,0.1945518,0,0,0,0,0,0.1585937,0.1585937,0.1585937,1.983876
10,0.1667187,1.990204,0.1990204,0,0,0,0,0,0.1667187,0.1667187,0.1667187,2.029443
10.5,0.1751562,2.041243,0.2041243,0,0,0,0,0,0.1751562,0.1751562,0.1751562,2.081488
11,0.1834375,2.090794,0.2090794,0,0,0,0,0,0.1834375,0.1834375,0.1834375,2.132016
11.5,0.191875,2.138451,0.2138451,0,0,0,0,0,0.191875,0.191875,0.191875,2.180613
12,0.1998437,2.180862,0.2180862,0,0,0,0,0,0.1998437,0.1998437,0.1998437,2.22386
12.5,0.208125,2.207652,0.2207652,0,0,0,0,0,0.208125,0.208125,0.208125,2.251179
13,0.2171875,2.264073,0.2264073,0,0,0,0,0,0.2171875,0.2171875,0.2171875,2.308712
13.5,0.2253125,2.287637,0.2287637,0,0,0,0,0,0.2253125,0.2253125,0.2253125,2.33274
14,0.233125,2.320704,0.2320704,0,0,0,0,0,0.233125,0.233125,0.233125,2.36646
14.5,0.2415625,2.357016,0.2357016,0,0,0,0,0,0.2415625,0.2415625,0.2415625,2.403487
15,0.2501562,2.372207,0.2372207,0,0,0,0,0,0.2501562,0.2501562,0.2501562,2.418978
15.5,0.2582812,2.399544,0.2399544,0,0,0,0,0,0.2582812,0.2582812,0.2582812,2.446854
16,0.2667187,2.441907,0.2441907,0,0,0,0,0,0.2667187,0.2667187,0.2667187,2.490052
16.5,0.2751562,2.489937,0.2489937,0,0,0,0,0,0.2751562,0.2751562,0.2751562,2.539029
17,0.2832812,2.531341,0.253134,0,0,0,0,0,0.2832812,0.2832812,0.2832812,2.581249
17.5,0.2914062,2.544829,0.2544829,0,0,0,0,0,0.2914062,0.2914062,0.2914062,2.595003
18,0.3001562,2.579418,0.2579418,0,0,0,0,0,0.3001562,0.3001562,0.3001562,2.630274
18.5,0.3085937,2.620915,0.2620915,0,0,0,0,0,0.3085937,0.3085937,0.3085937,2.67259
19,0.3162499,2.643481,0.2643481,0,0,0,0,0,0.3162499,0.3162499,0.3162499,2.6956
19.5,0.3248437,2.698897,0.2698897,0,0,0,0,0,0.3248437,0.3248437,0.3248437,2.752109
20,0.3335937,2.750794,0.2750794,0,0,0,0,0,0.3335937,0.3335937,0.3335937,2.805029
20.5,0.341875,2.785146,0.2785146,0,0,0,0,0,0.341875,0.341875,0.341875,2.840058
21,0.3501562,2.821681,0.2821681,0,0,0,0,0,0.3501562,0.3501562,0.3501562,2.877314
21.5,0.3582812,2.870945,0.2870945,0,0,0,0,0,0.3582812,0.3582812,0.3582812,2.927549
22,0.3667187,2.926092,0.2926092,0,0,0,0,0,0.3667187,0.3667187,0.3667187,2.983783
22.5,0.3746875,2.96615,0.2966149,0,0,0,0,0,0.3746875,0.3746875,0.3746875,3.024631
23,0.3834374,3.027799,0.3027799,0,0,0,0,0,0.3834374,0.3834374,0.3834374,3.087495
23.5,0.3920312,3.059722,0.3059722,0,0,0,0,0,0.3920312,0.3920312,0.3920312,3.120049
24,0.3998437,3.086594,0.3086594,0,0,0,0,0,0.3998437,0.3998437,0.3998437,3.14745
24.5,0.4081249,3.131509,0.3131509,0,0,0,0,0,0.4081249,0.4081249,0.4081249,3.193251
25,0.4168749,3.177268,0.3177268,0,0,0,0,0,0.4168749,0.4168749,0.4168749,3.239911
25.5,0.4251562,3.186912,0.3186912,0,0,0,0,0,0.4251562,0.4251562,0.4251562,3.249746
26,0.4332812,3.18287,0.318287,0,0,0,0,0,0.4332812,0.4332812,0.4332812,3.245624
26.5,0.4417187,3.226694,0.3226694,0,0,0,0,0,0.4417187,0.4417187,0.4417187,3.290312
27,0.4503125,3.264847,0.3264847,0,0,0,0,0,0.4503125,0.4503125,0.4503125,3.329218
27.5,0.4581249,3.289359,0.3289359,0,0,0,0,0,0.4581249,0.4581249,0.4581249,3.354213
28,0.4665625,3.316151,0.3316151,0,0,0,0,0,0.4665624,0.4665624,0.4665625,3.381533
28.5,0.4754687,3.325281,0.3325281,0,0,0,0,0,0.4754687,0.4754687,0.4754687,3.390843
29,0.483125,3.32587,0.332587,0,0,0,0,0,0.4831249,0.4831249,0.483125,3.391444
29.5,0.4914061,3.342912,0.3342912,0,0,0,0,0,0.4914061,0.4914061,0.4914061,3.408822
30,0.5003124,3.322452,0.3322452,0,0,0,0,0,0.5003124,0.5003124,0.5003124,3.387959
30.5,0.5085936,3.320444,0.3320444,0,0,0,0,0,0.5085936,0.5085936,0.5085936,3.385911
31,0.5168749,3.334494,0.3334494,0,0,0,0,0,0.5168749,0.5168749,0.5168749,3.400238
31.5,0.5248436,3.34489,0.334489,0,0,0,0,0,0.5248436,0.5248436,0.5248436,3.410838
32,0.5334374,3.375731,0.3375731,0,0,0,0,0,0.5334374,0.5334374,0.5334374,3.442288
32.5,0.5414062,3.391938,0.3391938,0,0,0,0,0,0.5414062,0.5414062,0.5414062,3.458814
33,0.5498437,3.433475,0.3433475,0,0,0,0,0,0.5498437,0.5498437,0.5498437,3.50117
33.5,0.5589062,3.476226,0.3476226,0,0,0,0,0,0.5589062,0.5589062,0.5589062,3.544764
34,0.5665624,3.478481,0.3478481,0,0,0,0,0,0.5665624,0.5665624,0.5665624,3.547064
34.5,0.5746874,3.496884,0.3496884,0,0,0,0,0,0.5746874,0.5746874,0.5746874,3.56583
35,0.5832812,3.538758,0.3538758,0,0,0,0,0,0.5832812,0.5832812,0.5832812,3.608528
35.5,0.5918749,3.576826,0.3576826,0,0,0,0,0,0.5918749,0.5918749,0.5918749,3.647347
36,0.5999999,3.60557,0.360557,0,0,0,0,0,0.5999999,0.5999999,0.5999999,3.676658
36.5,0.6081249,3.65161,0.365161,0,0,0,0,0,0.6081249,0.6081249,0.6081249,3.723606
37,0.6170311,3.706976,0.3706976,0,0,0,0,0,0.6170311,0.6170311,0.6170311,3.780063
37.5,0.6251562,3.738477,0.3738477,0,0,0,0,0,0.6251562,0.6251562,0.6251562,3.812186
38,0.6332811,3.776719,0.3776719,0,0,0,0,0,0.6332811,0.6332811,0.6332811,3.851182
38.5,0.6421874,3.830744,0.3830744,0,0,0,0,0,0.6421874,0.6421874,0.6421874,3.906272
39,0.6498437,3.836596,0.3836596,0,0,0,0,0,0.6498436,0.6498436,0.6498437,3.912239
39.5,0.6581249,3.852113,0.3852113,0,0,0,0,0,0.6581249,0.6581249,0.6581249,3.928062
40,0.6665624,3.839306,0.3839306,0,0,0,0,0,0.6665624,0.6665624,0.6665624,3.915003
40.5,0.6754686,3.873924,0.3873924,0,0,0,0,0,0.6754686,0.6754686,0.6754686,3.950303
41,0.6835936,3.898961,0.3898961,0,0,0,0,0,0.6835936,0.6835936,0.6835936,3.975834
41.5,0.6912499,3.934437,0.3934437,0,0,0,0,0,0.6912499,0.6912499,0.6912499,4.01201
42,0.6999999,3.998095,0.3998095,0,0,0,0,0,0.6999999,0.6999999,0.6999999,4.076922
42.5,0.7084374,4.046716,0.4046716,0,0,0,0,0,0.7084374,0.7084374,0.7084374,4.126502
43,0.7165624,4.077071,0.4077071,0,0,0,0,0,0.7165624,0.7165624,0.7165624,4.157455
43.5,0.7254686,4.124518,0.4124518,0,0,0,0,0,0.7254686,0.7254686,0.7254686,4.205838
44,0.7334374,4.155327,0.4155327,0,0,0,0,0,0.7334374,0.7334374,0.7334374,4.237255
44.5,0.7415624,4.185011,0.4185011,0,0,0,0,0,0.7415624,0.7415624,0.7415624,4.267524
45,0.7498437,4.211401,0.4211401,0,0,0,0,0,0.7498437,0.7498437,0.7498437,4.294434
45.5,0.7587499,4.256183,0.4256183,0,0,0,0,0,0.7587499,0.7587499,0.7587499,4.340099
46,0.7667186,4.265634,0.4265634,0,0,0,0,0,0.7667186,0.7667186,0.7667186,4.349736
46.5,0.7748436,4.308897,0.4308897,0,0,0,0,0,0.7748436,0.7748436,0.7748436,4.393852
47,0.7835936,4.358278,0.4358278,0,0,0,0,0,0.7835937,0.7835937,0.7835936,4.444207
47.5,0.7918749,4.369958,0.4369958,0,0,0,0,0,0.7918749,0.7918749,0.7918749,4.456117
48,0.7999999,4.398918,0.4398918,0,0,0,0,0,0.7999999,0.7999999,0.7999999,4.485648
48.5,0.8085936,4.440811,0.4440811,0,0,0,0,0,0.8085936,0.8085936,0.8085936,4.528367
49,0.8168749,4.456045,0.4456045,0,0,0,0,0,0.8168749,0.8168749,0.8168749,4.543901
49.5,0.8248436,4.463911,0.4463911,0,0,0,0,0,0.8248436,0.8248436,0.8248436,4.551922
50,0.8331249,4.487151,0.4487151,0,0,0,0,0,0.8331249,0.8331249,0.8331249,4.57562
50.5,0.8421874,4.548303,0.4548303,0,0,0,0,0,0.8421874,0.8421874,0.8421874,4.637978
51,0.8501561,4.572779,0.4572779,0,0,0,0,0,0.8501561,0.8501561,0.8501561,4.662937
51.5,0.8581249,4.60697,0.4606971,0,0,0,0,0,0.8581249,0.8581249,0.8581249,4.697803
52,0.8665624,4.650819,0.4650819,0,0,0,0,0,0.8665624,0.8665624,0.8665624,4.742516
52.5,0.8751561,4.704946,0.4704946,0,0,0,0,0,0.8751562,0.8751562,0.8751561,4.797709
53,0.8832811,4.736217,0.4736217,0,0,0,0,0,0.8832811,0.8832811,0.8832811,4.829597
53.5,0.8917187,4.779107,0.4779108,0,0,0,0,0,0.8917187,0.8917187,0.8917187,4.873333
54,0.9001562,4.827058,0.4827058,0,0,0,0,0,0.9001561,0.9001561,0.9001562,4.922229
54.5,0.9084374,4.857267,0.4857267,0,0,0,0,0,0.9084374,0.9084374,0.9084374,4.953033
55,0.9164062,4.881171,0.4881171,0,0,0,0,0,0.9164062,0.9164062,0.9164062,4.977409
55.5,0.9251561,4.873715,0.4873714,0,0,0,0,0,0.9251561,0.9251561,0.9251561,4.969806
56,0.9335937,4.829717,0.4829717,0,0,0,0,0,0.9335937,0.9335937,0.9335937,4.924941
56.5,0.9414061,4.750355,0.4750355,0,0,0,0,0,0.9414061,0.9414061,0.9414061,4.844014
57,0.9498436,4.733347,0.4733347,0,0,0,0,0,0.9498436,0.9498436,0.9498436,4.826671
57.5,0.9585936,4.656115,0.4656115,0,0,0,0,0,0.9585936,0.9585936,0.9585936,4.747916
58,0.9668749,4.644866,0.4644865,0,0,0,0,0,0.9668749,0.9668749,0.9668749,4.736444
58.5,0.9751561,4.655561,0.4655561,0,0,0,0,0,0.9751561,0.9751561,0.9751561,4.747351
59,0.9832811,4.632898,0.4632899,0,0,0,0,0,0.9832811,0.9832811,0.9832811,4.724242
59.436,0.990781,4.30719,0.430719,0,0,0,0,0,0.990781,0.990781,0.990781,4.392111
59.936,0.9987497,4.170924,0.4170924,0,0,0,0,0,0.9987497,0.9987497,0.9987497,4.253159
60.436,1.007344,4.196112,0.4196112,0,0,0,0,0,1.007344,1.007344,1.007344,4.278843
60.936,1.016094,4.227484,0.4227484,0,0,0,0,0,1.016093,1.016093,1.016094,4.310833
61.436,1.02375,4.225922,0.4225922,0,0,0,0,0,1.02375,1.02375,1.02375,4.309242
61.936,1.031875,4.261691,0.4261691,0,0,0,0,0,1.031875,1.031875,1.031875,4.345715
62.436,1.040625,4.304277,0.4304277,0,0,0,0,0,1.040625,1.040625,1.040625,4.389141
62.936,1.049219,4.310012,0.4310012,0,0,0,0,0,1.049219,1.049219,1.049219,4.394989
63.436,1.057344,4.329317,0.4329317,0,0,0,0,0,1.057344,1.057344,1.057344,4.414675
63.936,1.065625,4.364593,0.4364593,0,0,0,0,0,1.065625,1.065625,1.065625,4.450646
64.436,1.074062,4.410705,0.4410705,0,0,0,0,0,1.074062,1.074062,1.074062,4.497667
64.936,1.082187,4.456193,0.4456193,0,0,0,0,0,1.082187,1.082187,1.082187,4.544052
65.436,1.090469,4.494737,0.4494737,0,0,0,0,0,1.090469,1.090469,1.090469,4.583357
65.93601,1.099375,4.488989,0.4488989,0,0,0,0,0,1.099375,1.099375,1.099375,4.577495
66.43601,1.107187,4.477453,0.4477453,0,0,0,0,0,1.107187,1.107187,1.107187,4.565731
66.93601,1.115312,4.507623,0.4507623,0,0,0,0,0,1.115312,1.115312,1.115312,4.596497
67.43601,1.123906,4.544194,0.4544194,0,0,0,0,0,1.123906,1.123906,1.123906,4.633788
67.93601,1.1325,4.552675,0.4552675,0,0,0,0,0,1.1325,1.1325,1.1325,4.642437
68.43601,1.140781,4.570284,0.4570284,0,0,0,0,0,1.140781,1.140781,1.140781,4.660393
68.93601,1.14875,4.569658,0.4569657,0,0,0,0,0,1.14875,1.14875,1.14875,4.659754
69.43601,1.1575,4.452425,0.4452425,0,0,0,0,0,1.1575,1.1575,1.1575,4.54021
69.93601,1.165469,4.43178,0.443178,0,0,0,0,0,1.165469,1.165469,1.165469,4.519157
70.43601,1.17375,4.462134,0.4462134,0,0,0,0,0,1.17375,1.17375,1.17375,4.55011
70.93601,1.182812,4.500136,0.4500136,0,0,0,0,0,1.182812,1.182812,1.182812,4.588862
71.43601,1.190469,4.484591,0.4484591,0,0,0,0,0,1.190469,1.190469,1.190469,4.57301
71.93601,1.19875,4.520905,0.4520905,0,0,0,0,0,1.19875,1.19875,1.19875,4.61004
72.43601,1.207187,4.560663,0.4560663,0,0,0,0,0,1.207187,1.207187,1.207187,4.650582
72.93601,1.215781,4.598537,0.4598537,0,0,0,0,0,1.215781,1.215781,1.215781,4.689203
73.43601,1.224062,4.623229,0.4623229,0,0,0,0,0,1.224062,1.224062,1.224062,4.714382
73.93601,1.232031,4.647141,0.4647141,0,0,0,0,0,1.232031,1.232031,1.232031,4.738765
74.43601,1.240937,4.696792,0.4696792,0,0,0,0,0,1.240937,1.240937,1.240937,4.789395
74.93601,1.249062,4.719347,0.4719347,0,0,0,0,0,1.249062,1.249062,1.249062,4.812395
75.43601,1.257187,4.73693,0.473693,0,0,0,0,0,1.257187,1.257187,1.257187,4.830324
75.93601,1.266094,4.767755,0.4767755,0,0,0,0,0,1.266094,1.266094,1.266094,4.861757
76.43601,1.273906,4.787064,0.4787064,0,0,0,0,0,1.273906,1.273906,1.273906,4.881446
76.93601,1.282031,4.817761,0.4817761,0,0,0,0,0,1.282031,1.282031,1.282031,4.912749
77.43601,1.290468,4.86168,0.486168,0,0,0,0,0,1.290468,1.290468,1.290468,4.957533
77.93601,1.299375,4.898102,0.4898102,0,0,0,0,0,1.299375,1.299375,1.299375,4.994674
78.43601,1.3075,4.887751,0.4887751,0,0,0,0,0,1.3075,1.3075,1.3075,4.984118
78.93601,1.315312,4.891702,0.4891702,0,0,0,0,0,1.315312,1.315312,1.315312,4.988148
79.43601,1.323906,4.931047,0.4931047,0,0,0,0,0,1.323906,1.323906,1.323906,5.028268
79.93601,1.332344,4.947102,0.4947102,0,0,0,0,0,1.332344,1.332344,1.332344,5.04464
80.43601,1.340469,4.957453,0.4957453,0,0,0,0,0,1.340469,1.340469,1.340469,5.055195
80.93601,1.349219,4.973151,0.4973151,0,0,0,0,0,1.349218,1.349218,1.349219,5.071203
81.43601,1.3575,4.977593,0.4977593,0,0,0,0,0,1.3575,1.3575,1.3575,5.075733
81.93601,1.365625,4.998587,0.4998587,0,0,0,0,0,1.365625,1.365625,1.365625,5.097141
82.43601,1.37375,5.029919,0.5029919,0,0,0,0,0,1.37375,1.37375,1.37375,5.129089
82.93601,1.382656,5.06881,0.506881,0,0,0,0,0,1.382656,1.382656,1.382656,5.168747
83.43601,1.390625,5.092206,0.5092206,0,0,0,0,0,1.390625,1.390625,1.390625,5.192605
83.93601,1.398594,5.116015,0.5116014,0,0,0,0,0,1.398594,1.398594,1.398594,5.216883
84.43601,1.407344,5.149445,0.5149444,0,0,0,0,0,1.407344,1.407344,1.407344,5.250972
84.93601,1.415781,5.168697,0.5168697,0,0,0,0,0,1.415781,1.415781,1.415781,5.270604
85.43601,1.423906,5.18322,0.518322,0,0,0,0,0,1.423906,1.423906,1.423906,5.285413
85.93601,1.432031,5.190402,0.5190402,0,0,0,0,0,1.432031,1.432031,1.432031,5.292737
86.43601,1.440937,5.227729,0.5227728,0,0,0,0,0,1.440937,1.440937,1.440937,5.3308
86.93601,1.449062,5.239751,0.5239751,0,0,0,0,0,1.449062,1.449062,1.449062,5.343059
87.43601,1.457187,5.259165,0.5259165,0,0,0,0,0,1.457187,1.457187,1.457187,5.362855
87.93601,1.465937,5.288479,0.5288479,0,0,0,0,0,1.465937,1.465937,1.465937,5.392748
88.43601,1.473906,5.291208,0.5291208,0,0,0,0,0,1.473906,1.473906,1.473906,5.39553
88.93601,1.482031,5.297331,0.5297331,0,0,0,0,0,1.482031,1.482031,1.482031,5.401774
89.43601,1.490469,5.289616,0.5289616,0,0,0,0,0,1.490469,1.490469,1.490469,5.393907
89.93601,1.499219,5.315483,0.5315483,0,0,0,0,0,1.499218,1.499218,1.499219,5.420284
90.43601,1.507343,5.324992,0.5324992,0,0,0,0,0,1.507344,1.507344,1.507343,5.42998
90.93601,1.515312,5.32323,0.5323231,0,0,0,0,0,1.515312,1.515312,1.515312,5.428185
91.43601,1.524062,5.350465,0.5350465,0,0,0,0,0,1.524062,1.524062,1.524062,5.455956
91.93601,1.5325,5.375993,0.5375993,0,0,0,0,0,1.5325,1.5325,1.5325,5.481987
92.43601,1.540469,5.394835,0.5394835,0,0,0,0,0,1.540469,1.540469,1.540469,5.501201
92.93601,1.548906,5.425966,0.5425966,0,0,0,0,0,1.548906,1.548906,1.548906,5.532945
93.43601,1.557344,5.413586,0.5413585,0,0,0,0,0,1.557343,1.557343,1.557344,5.520321
93.93601,1.565312,5.416114,0.5416114,0,0,0,0,0,1.565312,1.565312,1.565312,5.522899
94.43601,1.57375,5.444139,0.5444139,0,0,0,0,0,1.57375,1.57375,1.57375,5.551476
94.93601,1.5825,5.484498,0.5484498,0,0,0,0,0,1.5825,1.5825,1.5825,5.592632
95.43601,1.590781,5.501891,0.5501891,0,0,0,0,0,1.590781,1.590781,1.590781,5.610368
95.93601,1.598906,5.510908,0.5510908,0,0,0,0,0,1.598906,1.598906,1.598906,5.619562
96.43601,1.607344,5.537148,0.5537148,0,0,0,0,0,1.607344,1.607344,1.607344,5.64632
96.93601,1.615781,5.564572,0.5564572,0,0,0,0,0,1.615781,1.615781,1.615781,5.674284
97.43601,1.62375,5.575985,0.5575985,0,0,0,0,0,1.62375,1.62375,1.62375,5.685923
97.93601,1.632344,5.596884,0.5596883,0,0,0,0,0,1.632344,1.632344,1.632344,5.707233
98.43601,1.641094,5.621844,0.5621844,0,0,0,0,0,1.641093,1.641093,1.641094,5.732685
98.93601,1.648906,5.627001,0.5627001,0,0,0,0,0,1.648906,1.648906,1.648906,5.737944
99.43601,1.657031,5.63556,0.563556,0,0,0,0,0,1.657031,1.657031,1.657031,5.746672
99.93601,1.665781,5.674928,0.5674928,0,0,0,0,0,1.665781,1.665781,1.665781,5.786816
100.436,1.674219,5.700107,0.5700107,0,0,0,0,0,1.674219,1.674219,1.674219,5.812492
100.936,1.682187,5.710704,0.5710704,0,0,0,0,0,1.682187,1.682187,1.682187,5.823297
101.436,1.690469,5.741042,0.5741042,0,0,0,0,0,1.690469,1.690469,1.690469,5.854234
101.936,1.699062,5.767003,0.5767003,0,0,0,0,0,1.699062,1.699062,1.699062,5.880706
102.436,1.707344,5.775258,0.5775258,0,0,0,0,0,1.707343,1.707343,1.707344,5.889124
102.936,1.715468,5.782816,0.5782816,0,0,0,0,0,1.715469,1.715469,1.715468,5.896831
103.436,1.724218,5.796298,0.5796298,0,0,0,0,0,1.724218,1.724218,1.724218,5.910579
103.936,1.732187,5.79472,0.579472,0,0,0,0,0,1.732187,1.732187,1.732187,5.90897
104.436,1.740312,5.790893,0.5790893,0,0,0,0,0,1.740312,1.740312,1.740312,5.905067
104.936,1.749062,5.817355,0.5817355,0,0,0,0,0,1.749062,1.749062,1.749062,5.932051
105.436,1.7575,5.828904,0.5828905,0,0,0,0,0,1.7575,1.7575,1.7575,5.943828
105.936,1.765781,5.835928,0.5835928,0,0,0,0,0,1.765781,1.765781,1.765781,5.950991
106.436,1.77375,5.848892,0.5848892,0,0,0,0,0,1.77375,1.77375,1.77375,5.96421
106.936,1.7825,5.89437,0.589437,0,0,0,0,0,1.7825,1.7825,1.7825,6.010585
107.436,1.790625,5.897475,0.5897475,0,0,0,0,0,1.790625,1.790625,1.790625,6.013751
107.936,1.79875,5.875046,0.5875046,0,0,0,0,0,1.79875,1.79875,1.79875,5.99088
108.364,1.806562,5.553347,0.5553347,0,0,0,0,0,1.806562,1.806562,1.806562,5.662838
108.864,1.814531,5.527465,0.5527465,0,0,0,0,0,1.814531,1.814531,1.814531,5.636446
109.364,1.8225,5.531613,0.5531613,0,0,0,0,0,1.8225,1.8225,1.8225,5.640676
109.864,1.830937,5.538926,0.5538926,0,0,0,0,0,1.830937,1.830937,1.830937,5.648132
110.364,1.839531,5.553638,0.5553638,0,0,0,0,0,1.839531,1.839531,1.839531,5.663135
110.864,1.847812,5.553473,0.5553473,0,0,0,0,0,1.847812,1.847812,1.847812,5.662967
111.364,1.855625,5.567924,0.5567924,0,0,0,0,0,1.855625,1.855625,1.855625,5.677703
111.864,1.864531,5.616388,0.5616388,0,0,0,0,0,1.864531,1.864531,1.864531,5.727122
112.364,1.872812,5.639578,0.5639578,0,0,0,0,0,1.872812,1.872812,1.872812,5.75077
112.864,1.880937,5.658516,0.5658516,0,0,0,0,0,1.880937,1.880937,1.880937,5.770081
113.364,1.889531,5.691367,0.5691367,0,0,0,0,0,1.889531,1.889531,1.889531,5.803579
113.864,1.897812,5.721821,0.5721821,0,0,0,0,0,1.897812,1.897812,1.897812,5.834634
114.364,1.905781,5.74371,0.574371,0,0,0,0,0,1.905781,1.905781,1.905781,5.856955
114.864,1.914219,5.775113,0.5775113,0,0,0,0,0,1.914219,1.914219,1.914219,5.888977
115.364,1.923281,5.814023,0.5814023,0,0,0,0,0,1.923281,1.923281,1.923281,5.928653
115.864,1.931406,5.82312,0.582312,0,0,0,0,0,1.931406,1.931406,1.931406,5.93793
116.364,1.939062,5.810873,0.5810874,0,0,0,0,0,1.939062,1.939062,1.939062,5.925442
116.864,1.947656,5.842182,0.5842183,0,0,0,0,0,1.947656,1.947656,1.947656,5.957368
117.364,1.956093,5.868627,0.5868627,0,0,0,0,0,1.956093,1.956093,1.956093,5.984334
117.864,1.964218,5.864707,0.5864707,0,0,0,0,0,1.964218,1.964218,1.964218,5.980337
118.364,1.972968,5.886323,0.5886323,0,0,0,0,0,1.972968,1.972968,1.972968,6.002379
118.864,1.98125,5.91427,0.591427,0,0,0,0,0,1.98125,1.98125,1.98125,6.030877
119.364,1.989375,5.931965,0.5931965,0,0,0,0,0,1.989375,1.989375,1.989375,6.048921
119.864,1.997656,5.956617,0.5956616,0,0,0,0,0,1.997656,1.997656,1.997656,6.074059
120.364,2.006093,5.978354,0.5978354,0,0,0,0,0,2.006093,2.006093,2.006093,6.096225
120.864,2.014843,5.964568,0.5964568,0,0,0,0,0,2.014843,2.014843,2.014843,6.082167
121.364,2.022343,5.953573,0.5953574,0,0,0,0,0,2.022343,2.022343,2.022343,6.070955
121.864,2.031093,5.982009,0.5982009,0,0,0,0,0,2.031093,2.031093,2.031093,6.099952
122.364,2.039687,6.000593,0.6000593,0,0,0,0,0,2.039687,2.039687,2.039687,6.118902
122.864,2.047812,6.009045,0.6009045,0,0,0,0,0,2.047812,2.047812,2.047812,6.127521
123.364,2.05625,6.024953,0.6024953,0,0,0,0,0,2.05625,2.05625,2.05625,6.143743
123.864,2.064531,6.045727,0.6045728,0,0,0,0,0,2.064531,2.064531,2.064531,6.164926
124.364,2.072812,6.056935,0.6056935,0,0,0,0,0,2.072812,2.072812,2.072812,6.176354
124.864,2.080937,6.061786,0.6061786,0,0,0,0,0,2.080937,2.080937,2.080937,6.181301
125.364,2.089531,6.083416,0.6083416,0,0,0,0,0,2.089531,2.089531,2.089531,6.203358
125.864,2.097968,6.080177,0.6080177,0,0,0,0,0,2.097968,2.097968,2.097968,6.200055
126.364,2.105937,6.06319,0.606319,0,0,0,0,0,2.105937,2.105937,2.105937,6.182733
126.864,2.114218,6.079052,0.6079051,0,0,0,0,0,2.114218,2.114218,2.114218,6.198907
127.364,2.122968,6.107485,0.6107485,0,0,0,0,0,2.122968,2.122968,2.122968,6.227902
127.864,2.131093,6.10231,0.610231,0,0,0,0,0,2.131093,2.131093,2.131093,6.222624
128.364,2.139375,6.118154,0.6118154,0,0,0,0,0,2.139375,2.139375,2.139375,6.23878
128.864,2.147812,6.136816,0.6136816,0,0,0,0,0,2.147812,2.147812,2.147812,6.257811
129.364,2.156249,6.155067,0.6155067,0,0,0,0,0,2.15625,2.15625,2.156249,6.276422
129.864,2.164375,6.168681,0.6168681,0,0,0,0,0,2.164375,2.164375,2.164375,6.290304
130.364,2.172656,6.184535,0.6184535,0,0,0,0,0,2.172656,2.172656,2.172656,6.306471
130.864,2.181406,6.211713,0.6211713,0,0,0,0,0,2.181406,2.181406,2.181406,6.334185
131.364,2.189062,6.211539,0.6211539,0,0,0,0,0,2.189062,2.189062,2.189062,6.334007
131.864,2.1975,6.211152,0.6211151,0,0,0,0,0,2.1975,2.1975,2.1975,6.333612
132.364,2.206406,6.242488,0.6242488,0,0,0,0,0,2.206406,2.206406,2.206406,6.365566
132.864,2.214687,6.256363,0.6256363,0,0,0,0,0,2.214687,2.214687,2.214687,6.379714
133.364,2.222812,6.253038,0.6253039,0,0,0,0,0,2.222812,2.222812,2.222812,6.376325
133.864,2.231093,6.278441,0.6278441,0,0,0,0,0,2.231093,2.231093,2.231093,6.402228
134.364,2.239531,6.309409,0.6309409,0,0,0,0,0,2.239531,2.239531,2.239531,6.433806
134.864,2.2475,6.324978,0.6324978,0,0,0,0,0,2.247499,2.247499,2.2475,6.449683
135.364,2.255937,6.354572,0.6354572,0,0,0,0,0,2.255937,2.255937,2.255937,6.47986
135.864,2.265,6.39289,0.639289,0,0,0,0,0,2.265,2.265,2.265,6.518934
136.364,2.272656,6.395385,0.6395385,0,0,0,0,0,2.272656,2.272656,2.272656,6.521478
136.864,2.280781,6.416351,0.6416351,0,0,0,0,0,2.280781,2.280781,2.280781,6.542858
137.364,2.289375,6.44773,0.644773,0,0,0,0,0,2.289375,2.289375,2.289375,6.574855
137.864,2.297968,6.469367,0.6469368,0,0,0,0,0,2.297968,2.297968,2.297968,6.596919
138.364,2.30625,6.452855,0.6452855,0,0,0,0,0,2.30625,2.30625,2.30625,6.580081
138.864,2.314375,6.463369,0.6463369,0,0,0,0,0,2.314374,2.314374,2.314375,6.590802
139.364,2.322968,6.479443,0.6479443,0,0,0,0,0,2.322968,2.322968,2.322968,6.607193
139.864,2.331093,6.465589,0.6465589,0,0,0,0,0,2.331093,2.331093,2.331093,6.593065
140.364,2.339218,6.474802,0.6474802,0,0,0,0,0,2.339218,2.339218,2.339218,6.60246
140.864,2.348125,6.500186,0.6500186,0,0,0,0,0,2.348125,2.348125,2.348125,6.628345
141.364,2.356093,6.504346,0.6504346,0,0,0,0,0,2.356093,2.356093,2.356093,6.632587
141.864,2.364062,6.524947,0.6524947,0,0,0,0,0,2.364062,2.364062,2.364062,6.653594
142.364,2.372812,6.554178,0.6554178,0,0,0,0,0,2.372812,2.372812,2.372812,6.683402
142.864,2.381406,6.566281,0.6566281,0,0,0,0,0,2.381406,2.381406,2.381406,6.695743
143.364,2.389687,6.565974,0.6565974,0,0,0,0,0,2.389687,2.389687,2.389687,6.69543
143.864,2.3975,6.573639,0.6573639,0,0,0,0,0,2.3975,2.3975,2.3975,6.703246
144.364,2.406406,6.608855,0.6608855,0,0,0,0,0,2.406406,2.406406,2.406406,6.739157
144.864,2.414218,6.612221,0.6612221,0,0,0,0,0,2.414218,2.414218,2.414218,6.742589
145.364,2.4225,6.617334,0.6617334,0,0,0,0,0,2.4225,2.4225,2.4225,6.747803
145.864,2.431562,6.642883,0.6642883,0,0,0,0,0,2.431562,2.431562,2.431562,6.773856
146.364,2.439375,6.647439,0.6647439,0,0,0,0,0,2.439375,2.439375,2.439375,6.778502
146.864,2.4475,6.671514,0.6671513,0,0,0,0,0,2.4475,2.4475,2.4475,6.803051
147.364,2.455937,6.694961,0.6694961,0,0,0,0,0,2.455937,2.455937,2.455937,6.826961
147.864,2.464687,6.718196,0.6718196,0,0,0,0,0,2.464687,2.464687,2.464687,6.850653
148.364,2.472812,6.727868,0.6727868,0,0,0,0,0,2.472812,2.472812,2.472812,6.860516
148.864,2.480624,6.722359,0.6722358,0,0,0,0,0,2.480624,2.480624,2.480624,6.854898
149.364,2.489687,6.750528,0.6750528,0,0,0,0,0,2.489687,2.489687,2.489687,6.883623
149.864,2.497812,6.751721,0.6751721,0,0,0,0,0,2.497812,2.497812,2.497812,6.884839
150.364,2.505937,6.756034,0.6756034,0,0,0,0,0,2.505937,2.505937,2.505937,6.889237
150.864,2.514531,6.776333,0.6776333,0,0,0,0,0,2.514531,2.514531,2.514531,6.909936
151.364,2.522656,6.704281,0.6704282,0,0,0,0,0,2.522656,2.522656,2.522656,6.836464
151.864,2.530781,6.676772,0.6676772,0,0,0,0,0,2.530781,2.530781,2.530781,6.808413
152.364,2.539218,6.67535,0.667535,0,0,0,0,0,2.539218,2.539218,2.539218,6.806962
152.864,2.548281,6.694122,0.6694121,0,0,0,0,0,2.548281,2.548281,2.548281,6.826104
153.364,2.556406,6.681817,0.6681817,0,0,0,0,0,2.556406,2.556406,2.556406,6.813557
153.864,2.564062,6.672303,0.6672304,0,0,0,0,0,2.564062,2.564062,2.564062,6.803856
154.364,2.572812,6.708036,0.6708037,0,0,0,0,0,2.572812,2.572812,2.572812,6.840293
154.864,2.581093,6.721901,0.6721901,0,0,0,0,0,2.581093,2.581093,2.581093,6.854432
155.364,2.589375,6.715642,0.6715642,0,0,0,0,0,2.589375,2.589375,2.589375,6.848049
155.864,2.597812,6.693479,0.6693479,0,0,0,0,0,2.597812,2.597812,2.597812,6.825449
156.364,2.60625,6.695229,0.6695229,0,0,0,0,0,2.60625,2.60625,2.60625,6.827233
156.864,2.614375,6.694048,0.6694048,0,0,0,0,0,2.614374,2.614374,2.614375,6.826029
157.364,2.6225,6.703888,0.6703888,0,0,0,0,0,2.6225,2.6225,2.6225,6.836063
157.864,2.63125,6.731506,0.6731507,0,0,0,0,0,2.63125,2.63125,2.63125,6.864226
158.364,2.639843,6.742314,0.6742314,0,0,0,0,0,2.639843,2.639843,2.639843,6.875247
158.864,2.6475,6.736401,0.6736401,0,0,0,0,0,2.6475,2.6475,2.6475,6.869218
159.364,2.655937,6.760596,0.6760597,0,0,0,0,0,2.655937,2.655937,2.655937,6.89389
159.864,2.664531,6.781226,0.6781226,0,0,0,0,0,2.664531,2.664531,2.664531,6.914926
160.364,2.672812,6.79233,0.679233,0,0,0,0,0,2.672812,2.672812,2.672812,6.926249
160.864,2.68125,6.799173,0.6799173,0,0,0,0,0,2.68125,2.68125,2.68125,6.933227
161.364,2.689531,6.817339,0.681734,0,0,0,0,0,2.689531,2.689531,2.689531,6.951752
161.864,2.697812,6.820854,0.6820854,0,0,0,0,0,2.697812,2.697812,2.697812,6.955335
162.364,2.705937,6.825027,0.6825027,0,0,0,0,0,2.705937,2.705937,2.705937,6.95959
162.864,2.714531,6.831889,0.6831889,0,0,0,0,0,2.714531,2.714531,2.714531,6.966588
163.364,2.722968,6.828641,0.6828641,0,0,0,0,0,2.722968,2.722968,2.722968,6.963276
163.864,2.730781,6.82966,0.682966,0,0,0,0,0,2.730781,2.730781,2.730781,6.964314
164.364,2.739218,6.843868,0.6843868,0,0,0,0,0,2.739218,2.739218,2.739218,6.978803
164.864,2.748125,6.861591,0.6861591,0,0,0,0,0,2.748125,2.748125,2.748125,6.996875
165.364,2.756093,6.858729,0.6858729,0,0,0,0,0,2.756094,2.756094,2.756093,6.993957
165.864,2.764218,6.855309,0.6855309,0,0,0,0,0,2.764218,2.764218,2.764218,6.99047
166.364,2.772656,6.859102,0.6859102,0,0,0,0,0,2.772656,2.772656,2.772656,6.994338
166.864,2.78125,6.868414,0.6868414,0,0,0,0,0,2.78125,2.78125,2.78125,7.003833
167.364,2.789218,6.85361,0.685361,0,0,0,0,0,2.789218,2.789218,2.789218,6.988737
167.864,2.797656,6.82366,0.682366,0,0,0,0,0,2.797656,2.797656,2.797656,6.958197
168.364,2.806406,6.799455,0.6799455,0,0,0,0,0,2.806406,2.806406,2.806406,6.933515
168.864,2.814062,6.718382,0.6718382,0,0,0,0,0,2.814062,2.814062,2.814062,6.850843
169.364,2.822499,6.714534,0.6714534,0,0,0,0,0,2.8225,2.8225,2.822499,6.846919
169.864,2.831406,6.729741,0.6729741,0,0,0,0,0,2.831406,2.831406,2.831406,6.862426
170.364,2.839687,6.721985,0.6721985,0,0,0,0,0,2.839687,2.839687,2.839687,6.854517
170.864,2.847812,6.695347,0.6695347,0,0,0,0,0,2.847812,2.847812,2.847812,6.827353
171.364,2.855937,6.700578,0.6700578,0,0,0,0,0,2.855937,2.855937,2.855937,6.832687
171.864,2.864531,6.723627,0.6723627,0,0,0,0,0,2.864531,2.864531,2.864531,6.856191
172.364,2.872656,6.728192,0.6728191,0,0,0,0,0,2.872656,2.872656,2.872656,6.860846
172.864,2.881093,6.739295,0.6739295,0,0,0,0,0,2.881094,2.881094,2.881093,6.872169
173.364,2.89,6.755266,0.6755266,0,0,0,0,0,2.89,2.89,2.89,6.888454
173.864,2.897656,6.692247,0.6692247,0,0,0,0,0,2.897656,2.897656,2.897656,6.824193
174.364,2.905781,6.694936,0.6694936,0,0,0,0,0,2.905781,2.905781,2.905781,6.826935
174.864,2.914374,6.716697,0.6716697,0,0,0,0,0,2.914374,2.914374,2.914374,6.849125
175.364,2.922968,6.735092,0.6735092,0,0,0,0,0,2.922968,2.922968,2.922968,6.867882
175.864,2.931093,6.735403,0.6735403,0,0,0,0,0,2.931093,2.931093,2.931093,6.8682
176.364,2.939218,6.754179,0.6754179,0,0,0,0,0,2.939219,2.939219,2.939218,6.887346
176.864,2.947968,6.785602,0.6785602,0,0,0,0,0,2.947968,2.947968,2.947968,6.919388
177.364,2.956093,6.785298,0.6785298,0,0,0,0,0,2.956093,2.956093,2.956093,6.919078
177.864,2.964218,6.699578,0.6699579,0,0,0,0,0,2.964218,2.964218,2.964218,6.831669
178.364,2.973125,6.688097,0.6688097,0,0,0,0,0,2.973125,2.973125,2.973125,6.819961
178.864,2.980937,6.666957,0.6666957,0,0,0,0,0,2.980937,2.980937,2.980937,6.798404
179.364,2.989218,6.677787,0.6677787,0,0,0,0,0,2.989218,2.989218,2.989218,6.809448
179.864,2.997812,6.688783,0.6688783,0,0,0,0,0,2.997812,2.997812,2.997812,6.82066
180.364,3.006406,6.697075,0.6697075,0,0,0,0,0,3.006406,3.006406,3.006406,6.829116
180.864,3.014531,6.696012,0.6696012,0,0,0,0,0,3.014531,3.014531,3.014531,6.828032
181.364,3.0225,6.686923,0.6686923,0,0,0,0,0,3.0225,3.0225,3.0225,6.818764
181.864,3.03125,6.719901,0.6719902,0,0,0,0,0,3.03125,3.03125,3.03125,6.852392
182.364,3.039374,6.735849,0.6735849,0,0,0,0,0,3.039375,3.039375,3.039374,6.868654
182.864,3.047656,6.749666,0.6749666,0,0,0,0,0,3.047656,3.047656,3.047656,6.882744
183.364,3.056562,6.77667,0.677667,0,0,0,0,0,3.056562,3.056562,3.056562,6.91028
183.864,3.064375,6.77923,0.677923,0,0,0,0,0,3.064375,3.064375,3.064375,6.91289
184.364,3.0725,6.788881,0.6788881,0,0,0,0,0,3.0725,3.0725,3.0725,6.922732
184.864,3.080937,6.792236,0.6792236,0,0,0,0,0,3.080937,3.080937,3.080937,6.926153
185.364,3.089531,6.796583,0.6796583,0,0,0,0,0,3.089531,3.089531,3.089531,6.930586
185.864,3.097968,6.788597,0.6788597,0,0,0,0,0,3.097968,3.097968,3.097968,6.922442
186.364,3.105625,6.784729,0.6784729,0,0,0,0,0,3.105625,3.105625,3.105625,6.918498
186.864,3.114531,6.811757,0.6811757,0,0,0,0,0,3.114531,3.114531,3.114531,6.946059
187.364,3.122812,6.821123,0.6821123,0,0,0,0,0,3.122812,3.122812,3.122812,6.955609
187.864,3.130937,6.823292,0.6823292,0,0,0,0,0,3.130937,3.130937,3.130937,6.957821
188.364,3.139531,6.838554,0.6838554,0,0,0,0,0,3.139531,3.139531,3.139531,6.973384
188.864,3.147656,6.851751,0.6851751,0,0,0,0,0,3.147656,3.147656,3.147656,6.986841
189.364,3.155937,6.875266,0.6875266,0,0,0,0,0,3.155937,3.155937,3.155937,7.01082
189.864,3.164375,6.902345,0.6902345,0,0,0,0,0,3.164375,3.164375,3.164375,7.038434
190.364,3.173281,6.931149,0.6931149,0,0,0,0,0,3.173281,3.173281,3.173281,7.067805
190.864,3.181406,6.930476,0.6930476,0,0,0,0,0,3.181406,3.181406,3.181406,7.067119
191.364,3.189062,6.922612,0.6922612,0,0,0,0,0,3.189062,3.189062,3.189062,7.059099
191.864,3.197656,6.948948,0.6948948,0,0,0,0,0,3.197656,3.197656,3.197656,7.085955
192.364,3.206093,6.915706,0.6915706,0,0,0,0,0,3.206093,3.206093,3.206093,7.052057
192.864,3.214218,6.916691,0.6916691,0,0,0,0,0,3.214218,3.214218,3.214218,7.053062
193.364,3.222968,6.934318,0.6934318,0,0,0,0,0,3.222968,3.222968,3.222968,7.071036
193.864,3.23125,6.956038,0.6956038,0,0,0,0,0,3.23125,3.23125,3.23125,7.093184
194.364,3.239531,6.970941,0.6970941,0,0,0,0,0,3.239531,3.239531,3.239531,7.108382
194.864,3.247499,6.983361,0.6983361,0,0,0,0,0,3.247499,3.247499,3.247499,7.121046
195.364,3.256093,7.005367,0.7005367,0,0,0,0,0,3.256093,3.256093,3.256093,7.143486
195.864,3.264687,7.024142,0.7024142,0,0,0,0,0,3.264687,3.264687,3.264687,7.162632
196.364,3.2725,7.030828,0.7030827,0,0,0,0,0,3.2725,3.2725,3.2725,7.169449
196.864,3.281093,7.060412,0.7060412,0,0,0,0,0,3.281093,3.281093,3.281093,7.199616
197.364,3.289531,7.076906,0.7076907,0,0,0,0,0,3.289531,3.289531,3.289531,7.216436
197.864,3.297812,7.073784,0.7073784,0,0,0,0,0,3.297812,3.297812,3.297812,7.213252
198.364,3.305937,7.071074,0.7071074,0,0,0,0,0,3.305937,3.305937,3.305937,7.210489
198.864,3.314531,7.079216,0.7079216,0,0,0,0,0,3.314531,3.314531,3.314531,7.218791
199.364,3.322656,7.095829,0.7095829,0,0,0,0,0,3.322656,3.322656,3.322656,7.235732
199.864,3.330937,7.107904,0.7107904,0,0,0,0,0,3.330937,3.330937,3.330937,7.248045
200.364,3.339531,7.108011,0.7108011,0,0,0,0,0,3.339531,3.339531,3.339531,7.248154
200.864,3.348125,7.118427,0.7118427,0,0,0,0,0,3.348125,3.348125,3.348125,7.258775
201.364,3.355781,7.108451,0.7108451,0,0,0,0,0,3.355781,3.355781,3.355781,7.248602
201.864,3.364218,7.126186,0.7126186,0,0,0,0,0,3.364218,3.364218,3.364218,7.266687
202.364,3.372968,7.159888,0.7159888,0,0,0,0,0,3.372968,3.372968,3.372968,7.301054
202.864,3.380937,7.167868,0.7167867,0,0,0,0,0,3.380937,3.380937,3.380937,7.309191
203.364,3.389375,7.17985,0.717985,0,0,0,0,0,3.389374,3.389374,3.389375,7.32141
203.864,3.397812,7.191532,0.7191532,0,0,0,0,0,3.397812,3.397812,3.397812,7.333322
204.364,3.406406,7.204445,0.7204444,0,0,0,0,0,3.406406,3.406406,3.406406,7.346489
204.864,3.414218,7.206362,0.7206362,0,0,0,0,0,3.414218,3.414218,3.414218,7.348444
205.364,3.422656,7.234311,0.7234311,0,0,0,0,0,3.422656,3.422656,3.422656,7.376945
205.864,3.431406,7.266494,0.7266494,0,0,0,0,0,3.431406,3.431406,3.431406,7.409761
206.364,3.439062,7.266664,0.7266664,0,0,0,0,0,3.439062,3.439062,3.439062,7.409935
206.864,3.4475,7.293911,0.7293911,0,0,0,0,0,3.4475,3.4475,3.4475,7.43772
207.364,3.456406,7.332747,0.7332747,0,0,0,0,0,3.456406,3.456406,3.456406,7.477321
207.864,3.464687,7.347594,0.7347594,0,0,0,0,0,3.464687,3.464687,3.464687,7.492461
208.364,3.472812,7.360627,0.7360626,0,0,0,0,0,3.472812,3.472812,3.472812,7.505751
208.864,3.480937,7.377667,0.7377667,0,0,0,0,0,3.480937,3.480937,3.480937,7.523127
209.364,3.489375,7.372566,0.7372566,0,0,0,0,0,3.489375,3.489375,3.489375,7.517925
209.864,3.4975,7.377265,0.7377264,0,0,0,0,0,3.497499,3.497499,3.4975,7.522717
210.364,3.506093,7.399525,0.7399524,0,0,0,0,0,3.506093,3.506093,3.506093,7.545415
210.864,3.515,7.413935,0.7413935,0,0,0,0,0,3.515,3.515,3.515,7.56011
211.364,3.522656,7.40982,0.740982,0,0,0,0,0,3.522656,3.522656,3.522656,7.555913
211.864,3.530781,7.417906,0.7417906,0,0,0,0,0,3.530781,3.530781,3.530781,7.564159
212.364,3.539375,7.437277,0.7437277,0,0,0,0,0,3.539375,3.539375,3.539375,7.583912
212.864,3.547968,7.446874,0.7446874,0,0,0,0,0,3.547968,3.547968,3.547968,7.593698
213.364,3.556093,7.437526,0.7437527,0,0,0,0,0,3.556093,3.556093,3.556093,7.584167
213.864,3.564375,7.446916,0.7446916,0,0,0,0,0,3.564374,3.564374,3.564375,7.59374
214.364,3.572968,7.481156,0.7481157,0,0,0,0,0,3.572968,3.572968,3.572968,7.628656
214.864,3.581093,7.475808,0.7475808,0,0,0,0,0,3.581093,3.581093,3.581093,7.623202
215.364,3.589374,7.487672,0.7487672,0,0,0,0,0,3.589375,3.589375,3.589374,7.6353
215.864,3.598124,7.511736,0.7511736,0,0,0,0,0,3.598125,3.598125,3.598124,7.65984
216.364,3.605937,7.505499,0.7505499,0,0,0,0,0,3.605937,3.605937,3.605937,7.653479
216.864,3.614062,7.506171,0.7506171,0,0,0,0,0,3.614062,3.614062,3.614062,7.654164
217.364,3.622812,7.517873,0.7517874,0,0,0,0,0,3.622812,3.622812,3.622812,7.666098
217.864,3.631406,7.520718,0.7520718,0,0,0,0,0,3.631406,3.631406,3.631406,7.668998
218.364,3.639687,7.52124,0.7521241,0,0,0,0,0,3.639687,3.639687,3.639687,7.669531
218.864,3.647499,7.51717,0.751717,0,0,0,0,0,3.6475,3.6475,3.647499,7.66538
219.364,3.656249,7.557976,0.7557976,0,0,0,0,0,3.65625,3.65625,3.656249,7.70699
219.864,3.664375,7.578424,0.7578424,0,0,0,0,0,3.664375,3.664375,3.664375,7.727842
220.364,3.672499,7.593751,0.7593751,0,0,0,0,0,3.672499,3.672499,3.672499,7.743471
220.864,3.681406,7.61787,0.761787,0,0,0,0,0,3.681406,3.681406,3.681406,7.768065
221.364,3.689531,7.59666,0.759666,0,0,0,0,0,3.689531,3.689531,3.689531,7.746438
221.864,3.6975,7.605658,0.7605658,0,0,0,0,0,3.6975,3.6975,3.6975,7.755612
222.364,3.705781,7.616574,0.7616574,0,0,0,0,0,3.705781,3.705781,3.705781,7.766744
222.864,3.714531,7.640935,0.7640935,0,0,0,0,0,3.714531,3.714531,3.714531,7.791586
223.364,3.722812,7.649829,0.7649829,0,0,0,0,0,3.722812,3.722812,3.722812,7.800655
223.864,3.730781,7.658271,0.7658271,0,0,0,0,0,3.730781,3.730781,3.730781,7.809263
224.364,3.739687,7.698078,0.7698078,0,0,0,0,0,3.739687,3.739687,3.739687,7.849854
224.864,3.747812,7.709294,0.7709294,0,0,0,0,0,3.747812,3.747812,3.747812,7.861292
225.364,3.755937,7.692169,0.7692169,0,0,0,0,0,3.755937,3.755937,3.755937,7.843829
225.864,3.764531,7.70626,0.770626,0,0,0,0,0,3.764531,3.764531,3.764531,7.858198
226.364,3.772656,7.724574,0.7724574,0,0,0,0,0,3.772656,3.772656,3.772656,7.876873
226.864,3.780781,7.741759,0.7741759,0,0,0,0,0,3.780781,3.780781,3.780781,7.894397
227.364,3.789218,7.755644,0.7755644,0,0,0,0,0,3.789218,3.789218,3.789218,7.908556
227.864,3.798281,7.730328,0.7730328,0,0,0,0,0,3.798281,3.798281,3.798281,7.88274
228.364,3.806406,7.725216,0.7725216,0,0,0,0,0,3.806406,3.806406,3.806406,7.877528
228.864,3.814062,7.721475,0.7721475,0,0,0,0,0,3.814062,3.814062,3.814062,7.873713
229.364,3.822656,7.740492,0.7740492,0,0,0,0,0,3.822656,3.822656,3.822656,7.893105
229.864,3.831093,7.764028,0.7764028,0,0,0,0,0,3.831093,3.831093,3.831093,7.917105
230.364,3.839218,7.770976,0.7770976,0,0,0,0,0,3.839218,3.839218,3.839218,7.924191
230.864,3.848125,7.798071,0.7798071,0,0,0,0,0,3.848125,3.848125,3.848125,7.951819
231.364,3.85625,7.818656,0.7818657,0,0,0,0,0,3.85625,3.85625,3.85625,7.972811
231.864,3.864531,7.843238,0.7843238,0,0,0,0,0,3.864531,3.864531,3.864531,7.997877
232.364,3.872656,7.866563,0.7866563,0,0,0,0,0,3.872656,3.872656,3.872656,8.021662
232.864,3.88125,7.89893,0.789893,0,0,0,0,0,3.88125,3.88125,3.88125,8.054667
233.364,3.889843,7.920163,0.7920163,0,0,0,0,0,3.889843,3.889843,3.889843,8.076319
233.864,3.8975,7.917749,0.7917749,0,0,0,0,0,3.8975,3.8975,3.8975,8.073857
234.364,3.906093,7.94292,0.794292,0,0,0,0,0,3.906093,3.906093,3.906093,8.099524
234.864,3.914687,7.955858,0.7955858,0,0,0,0,0,3.914687,3.914687,3.914687,8.112718
235.364,3.922812,7.922342,0.7922342,0,0,0,0,0,3.922812,3.922812,3.922812,8.07854
235.864,3.931249,7.9276,0.79276,0,0,0,0,0,3.931249,3.931249,3.931249,8.083901
236.364,3.93953,7.931462,0.7931462,0,0,0,0,0,3.93953,3.93953,3.93953,8.08784
236.864,3.947812,7.939552,0.7939552,0,0,0,0,0,3.947812,3.947812,3.947812,8.096089
237.364,3.955937,7.93878,0.793878,0,0,0,0,0,3.955936,3.955936,3.955937,8.095303
237.864,3.964687,7.918806,0.7918806,0,0,0,0,0,3.964687,3.964687,3.964687,8.074935
238.364,3.972968,7.890639,0.7890639,0,0,0,0,0,3.972968,3.972968,3.972968,8.046213
238.864,3.98078,7.874917,0.7874917,0,0,0,0,0,3.980781,3.980781,3.98078,8.030181
239.364,3.989218,7.871203,0.7871203,0,0,0,0,0,3.989218,3.989218,3.989218,8.026394
239.864,3.998124,7.907861,0.7907861,0,0,0,0,0,3.998124,3.998124,3.998124,8.063774
240.364,4.006093,7.915687,0.7915687,0,0,0,0,0,4.006093,4.006093,4.006093,8.071754
240.864,4.014374,7.926933,0.7926934,0,0,0,0,0,4.014374,4.014374,4.014374,8.083222
241.364,4.022812,7.949748,0.7949748,0,0,0,0,0,4.022811,4.022811,4.022812,8.106487
241.864,4.031249,7.968758,0.7968758,0,0,0,0,0,4.03125,4.03125,4.031249,8.125872
242.364,4.039218,7.978165,0.7978165,0,0,0,0,0,4.039218,4.039218,4.039218,8.135465
242.864,4.047656,7.983235,0.7983235,0,0,0,0,0,4.047656,4.047656,4.047656,8.140634
243.364,4.056405,8.014832,0.8014833,0,0,0,0,0,4.056405,4.056405,4.056405,8.172854
243.864,4.064218,8.013546,0.8013546,0,0,0,0,0,4.064218,4.064218,4.064218,8.171542
244.364,4.072499,8.024221,0.8024221,0,0,0,0,0,4.072499,4.072499,4.072499,8.182428
244.864,4.081562,8.038864,0.8038864,0,0,0,0,0,4.081562,4.081562,4.081562,8.19736
245.364,4.089687,8.026409,0.8026409,0,0,0,0,0,4.089686,4.089686,4.089687,8.18466
245.864,4.097812,8.013804,0.8013804,0,0,0,0,0,4.097812,4.097812,4.097812,8.171806
246.364,4.105937,8.005311,0.800531,0,0,0,0,0,4.105937,4.105937,4.105937,8.163145
246.864,4.114531,8.004824,0.8004824,0,0,0,0,0,4.114531,4.114531,4.114531,8.162649
247.364,4.122499,8.00333,0.800333,0,0,0,0,0,4.122499,4.122499,4.122499,8.161125
247.864,4.130937,8.029789,0.8029789,0,0,0,0,0,4.130937,4.130937,4.130937,8.188107
248.364,4.139999,8.053201,0.8053201,0,0,0,0,0,4.139999,4.139999,4.139999,8.21198
248.864,4.147499,8.042873,0.8042873,0,0,0,0,0,4.1475,4.1475,4.147499,8.201447
249.364,4.155937,8.061703,0.8061703,0,0,0,0,0,4.155937,4.155937,4.155937,8.22065
249.864,4.164687,8.083942,0.8083942,0,0,0,0,0,4.164687,4.164687,4.164687,8.243326
250.364,4.172968,8.093762,0.8093762,0,0,0,0,0,4.172968,4.172968,4.172968,8.253341
250.864,4.181093,8.107902,0.8107902,0,0,0,0,0,4.181093,4.181093,4.181093,8.267759
251.364,4.189218,8.097926,0.8097926,0,0,0,0,0,4.189218,4.189218,4.189218,8.257586
251.864,4.197968,8.114175,0.8114175,0,0,0,0,0,4.197968,4.197968,4.197968,8.274156
252.364,4.206093,8.114105,0.8114105,0,0,0,0,0,4.206093,4.206093,4.206093,8.274085
252.864,4.214218,8.105216,0.8105216,0,0,0,0,0,4.214218,4.214218,4.214218,8.26502
253.364,4.223124,8.127298,0.8127298,0,0,0,0,0,4.223124,4.223124,4.223124,8.287538
253.864,4.230937,8.117783,0.8117783,0,0,0,0,0,4.230937,4.230937,4.230937,8.277835
254.364,4.239218,8.116081,0.8116081,0,0,0,0,0,4.239218,4.239218,4.239218,8.276099
254.864,4.247812,8.126754,0.8126754,0,0,0,0,0,4.247812,4.247812,4.247812,8.286983
255.364,4.256249,8.130463,0.8130463,0,0,0,0,0,4.256249,4.256249,4.256249,8.290765
255.864,4.264687,8.096681,0.8096681,0,0,0,0,0,4.264687,4.264687,4.264687,8.256317
256.364,4.272499,8.092045,0.8092045,0,0,0,0,0,4.272499,4.272499,4.272499,8.25159
256.864,4.281249,8.121675,0.8121675,0,0,0,0,0,4.28125,4.28125,4.281249,8.281803
257.364,4.289374,8.130021,0.8130021,0,0,0,0,0,4.289374,4.289374,4.289374,8.290315
257.864,4.297499,8.147205,0.8147205,0,0,0,0,0,4.297499,4.297499,4.297499,8.307837
258.364,4.306562,8.186951,0.8186951,0,0,0,0,0,4.306562,4.306562,4.306562,8.348367
258.864,4.314531,8.186844,0.8186844,0,0,0,0,0,4.314531,4.314531,4.314531,8.348258
259.364,4.322499,8.209056,0.8209056,0,0,0,0,0,4.322499,4.322499,4.322499,8.370907
259.864,4.33078,8.23532,0.823532,0,0,0,0,0,4.330781,4.330781,4.33078,8.397689
260.364,4.339531,8.264301,0.8264301,0,0,0,0,0,4.33953,4.33953,4.339531,8.427241
260.864,4.347968,8.264991,0.8264991,0,0,0,0,0,4.347968,4.347968,4.347968,8.427945
261.364,4.35578,8.231515,0.8231515,0,0,0,0,0,4.35578,4.35578,4.35578,8.393809
261.864,4.364687,8.240024,0.8240024,0,0,0,0,0,4.364686,4.364686,4.364687,8.402486
262.364,4.372812,8.217595,0.8217595,0,0,0,0,0,4.372812,4.372812,4.372812,8.379615
262.864,4.380937,8.215768,0.8215768,0,0,0,0,0,4.380937,4.380937,4.380937,8.377751
263.364,4.389531,8.223997,0.8223997,0,0,0,0,0,4.389531,4.389531,4.389531,8.386143
263.864,4.397812,8.231355,0.8231355,0,0,0,0,0,4.397812,4.397812,4.397812,8.393646
264.364,4.405937,8.235767,0.8235767,0,0,0,0,0,4.405937,4.405937,4.405937,8.398145
264.864,4.414218,8.251307,0.8251307,0,0,0,0,0,4.414218,4.414218,4.414218,8.413992
265.364,4.42328,8.259287,0.8259287,0,0,0,0,0,4.42328,4.42328,4.42328,8.422129
265.864,4.431406,8.256413,0.8256413,0,0,0,0,0,4.431406,4.431406,4.431406,8.419198
266.364,4.439062,8.215601,0.8215601,0,0,0,0,0,4.439062,4.439062,4.439062,8.377582
266.864,4.447812,8.213976,0.8213976,0,0,0,0,0,4.447812,4.447812,4.447812,8.375924
267.364,4.456249,8.09875,0.809875,0,0,0,0,0,4.456249,4.456249,4.456249,8.258427
267.864,4.464374,8.059996,0.8059996,0,0,0,0,0,4.464375,4.464375,4.464374,8.218908
268.364,4.472968,8.035055,0.8035055,0,0,0,0,0,4.472968,4.472968,4.472968,8.193476
268.864,4.481249,8.032365,0.8032365,0,0,0,0,0,4.481249,4.481249,4.481249,8.190733
269.364,4.489374,8.040757,0.8040757,0,0,0,0,0,4.489374,4.489374,4.489374,8.199291
269.864,4.497499,8.040649,0.8040649,0,0,0,0,0,4.497499,4.497499,4.497499,8.19918
270.364,4.506249,8.029973,0.8029973,0,0,0,0,0,4.506249,4.506249,4.506249,8.188293
270.864,4.514687,7.994036,0.7994035,0,0,0,0,0,4.514687,4.514687,4.514687,8.151648
271.364,4.522499,7.918622,0.7918622,0,0,0,0,0,4.522499,4.522499,4.522499,8.074748
271.864,4.531093,7.869343,0.7869344,0,0,0,0,0,4.531093,4.531093,4.531093,8.024497
272.364,4.53953,7.769663,0.7769663,0,0,0,0,0,4.53953,4.53953,4.53953,7.922851
272.864,4.547812,7.533241,0.7533241,0,0,0,0,0,4.547812,4.547812,4.547812,7.681768
273.364,4.556093,7.164828,0.7164829,0,0,0,0,0,4.556093,4.556093,4.556093,7.306092
273.864,4.56453,6.997079,0.6997079,0,0,0,0,0,4.56453,4.56453,4.56453,7.135035
274.364,4.572656,6.899372,0.6899372,0,0,0,0,0,4.572656,4.572656,4.572656,7.035401
274.864,4.580937,6.876589,0.6876589,0,0,0,0,0,4.580937,4.580937,4.580937,7.01217
275.364,4.589687,6.892694,0.6892694,0,0,0,0,0,4.589687,4.589687,4.589687,7.028592
275.864,4.597968,6.899521,0.6899521,0,0,0,0,0,4.597968,4.597968,4.597968,7.035553
276.364,4.60578,6.917552,0.6917552,0,0,0,0,0,4.60578,4.60578,4.60578,7.05394
276.864,4.614218,6.954107,0.6954107,0,0,0,0,0,4.614218,4.614218,4.614218,7.091216
277.364,4.622968,6.992907,0.6992907,0,0,0,0,0,4.622968,4.622968,4.622968,7.130781
277.864,4.631249,7.011452,0.7011452,0,0,0,0,0,4.631249,4.631249,4.631249,7.149692
278.364,4.639218,7.010137,0.7010137,0,0,0,0,0,4.639218,4.639218,4.639218,7.148351
278.864,4.647655,7.033449,0.7033449,0,0,0,0,0,4.647655,4.647655,4.647655,7.172122
279.364,4.656249,7.061829,0.706183,0,0,0,0,0,4.656249,4.656249,4.656249,7.201062
279.864,4.664218,7.06888,0.706888,0,0,0,0,0,4.664218,4.664218,4.664218,7.208251
280.364,4.672655,7.10026,0.710026,0,0,0,0,0,4.672656,4.672656,4.672655,7.24025
280.864,4.681562,7.104859,0.7104859,0,0,0,0,0,4.681561,4.681561,4.681562,7.24494
281.364,4.689218,7.071583,0.7071583,0,0,0,0,0,4.689218,4.689218,4.689218,7.211008
281.864,4.697499,7.054561,0.7054561,0,0,0,0,0,4.697499,4.697499,4.697499,7.19365
282.364,4.706406,7.062729,0.706273,0,0,0,0,0,4.706406,4.706406,4.706406,7.20198
282.864,4.714687,7.060048,0.7060048,0,0,0,0,0,4.714687,4.714687,4.714687,7.199245
283.364,4.722812,7.067768,0.7067767,0,0,0,0,0,4.722812,4.722812,4.722812,7.207117
283.864,4.731093,7.078757,0.7078757,0,0,0,0,0,4.731093,4.731093,4.731093,7.218323
284.364,4.73953,7.10163,0.7101631,0,0,0,0,0,4.739531,4.739531,4.73953,7.241648
284.864,4.747499,7.109117,0.7109117,0,0,0,0,0,4.747499,4.747499,4.747499,7.249281
285.364,4.756093,7.124203,0.7124203,0,0,0,0,0,4.756093,4.756093,4.756093,7.264665
285.864,4.764999,7.14924,0.714924,0,0,0,0,0,4.764999,4.764999,4.764999,7.290196
286.364,4.772812,7.079953,0.7079953,0,0,0,0,0,4.772812,4.772812,4.772812,7.219543
286.702,4.778124,6.549235,0.6549236,0,0,0,0,0,4.778124,4.778124,4.778124,6.678361
286.738,4.778749,5.886242,0.5886242,0,0,0,0,0,4.778749,4.778749,4.778749,6.002296
287.126,4.785312,5.458,0.5458,0,0,0,0,0,4.785312,4.785312,4.785312,5.565611
287.626,4.794062,5.349439,0.5349439,0,0,0,0,0,4.794062,4.794062,4.794062,5.45491
288.126,4.802187,5.275452,0.5275452,0,0,0,0,0,4.802186,4.802186,4.802187,5.379464
288.626,4.810312,5.217521,0.5217521,0,0,0,0,0,4.810312,4.810312,4.810312,5.320391
289.126,4.818906,5.211251,0.5211251,0,0,0,0,0,4.818906,4.818906,4.818906,5.313997
289.626,4.827343,5.209593,0.5209593,0,0,0,0,0,4.827343,4.827343,4.827343,5.312306
290.126,4.835155,5.164376,0.5164376,0,0,0,0,0,4.835155,4.835155,4.835155,5.266198
290.626,4.843906,5.179625,0.5179625,0,0,0,0,0,4.843905,4.843905,4.843906,5.281748
291.126,4.852187,5.18433,0.518433,0,0,0,0,0,4.852187,4.852187,4.852187,5.286545
291.626,4.860155,5.198107,0.5198107,0,0,0,0,0,4.860155,4.860155,4.860155,5.300594
292.126,4.868593,5.218247,0.5218247,0,0,0,0,0,4.868593,4.868593,4.868593,5.321131
292.626,4.877499,5.255193,0.5255193,0,0,0,0,0,4.877499,4.877499,4.877499,5.358806
293.126,4.885781,5.26623,0.526623,0,0,0,0,0,4.885781,4.885781,4.885781,5.37006
293.626,4.893593,5.280662,0.5280662,0,0,0,0,0,4.893593,4.893593,4.893593,5.384776
294.126,4.90203,5.308826,0.5308826,0,0,0,0,0,4.90203,4.90203,4.90203,5.413496
294.626,4.910624,5.326446,0.5326446,0,0,0,0,0,4.910624,4.910624,4.910624,5.431464
295.126,4.918593,5.317333,0.5317333,0,0,0,0,0,4.918593,4.918593,4.918593,5.422171
295.626,4.927187,5.331774,0.5331774,0,0,0,0,0,4.927187,4.927187,4.927187,5.436896
296.126,4.935624,5.338651,0.533865,0,0,0,0,0,4.935624,4.935624,4.935624,5.443909
296.626,4.943593,5.354976,0.5354975,0,0,0,0,0,4.943593,4.943593,4.943593,5.460556
297.126,4.951874,5.381676,0.5381676,0,0,0,0,0,4.951874,4.951874,4.951874,5.487782
297.626,4.960624,5.416605,0.5416604,0,0,0,0,0,4.960624,4.960624,4.960624,5.523399
298.126,4.969062,5.438429,0.5438429,0,0,0,0,0,4.969062,4.969062,4.969062,5.545654
298.626,4.976874,5.450547,0.5450547,0,0,0,0,0,4.976874,4.976874,4.976874,5.558012
299.126,4.985312,5.472,0.5472,0,0,0,0,0,4.985312,4.985312,4.985312,5.579887
299.626,4.994062,5.509067,0.5509067,0,0,0,0,0,4.994062,4.994062,4.994062,5.617684
300.126,5.002031,5.531456,0.5531456,0,0,0,0,0,5.002031,5.002031,5.002031,5.640516
300.396,5.006406,5.546475,0.5546475,0,0,0,0,0,5.006405,5.006405,5.006406,5.655831