File: dataFiles/staticInstron_2.raw
"Test Type","Tension"
"Method Name","C:\Users\mmen339\Documents\tension test 1mm_s.im_tens"
"Sample name","C:\Users\mmen339\Documents\sample 2\S2.50Extension.is_tens"
"User",""
"Sample note 1",""
"Sample note 2",""
"Sample note 3",""
"Geometry","Rectangular"
"Specimen",1
"Specimen label",""
"Width",10.000000,"mm"
"Thickness",1.000000,"mm"
"Length",100.000000,"mm"
"Diameter",10.000000,"mm"
"Inner diameter",8.000000,"mm"
"Outer diameter",10.000000,"mm"
"Wall thickness",1.000000,"mm"
"Area",0.100000,"cm^2"
"Linear density",100.000000,"tex"
"Sled weight",10.000000,"N"
"Loading span",10.000000,"mm"
"Support span",100.000000,"mm"
"Span ratio","2"
"Fixture type","4-point"
"Included"
"Final width",10.000000,"mm"
"Final thickness",1.000000,"mm"
"Final length",100.000000,"mm"
"Final diameter",10.000000,"mm"
"Final Inner diameter",8.000000,"mm"
"Final outer diameter",10.000000,"mm"
"Final wall thickness",1.000000,"mm"
"Final area",0.100000,"cm^2"
"Final linear density",100.000000,"tex"
"Custom text input  1",""
"Custom text input  2",""
"Custom text input  3",""
"Custom text input  4",""
"Custom text input  5",""
"Custom text input  6",""
"Custom text input  7",""
"Custom text input  8",""
"Custom text input  9",""
"Custom text input 10",""
"Custom text input 11",""
"Custom text input 12",""
"Custom text input 13",""
"Custom text input 14",""
"Custom text input 15",""
"Custom text input 16",""
"Custom text input 17",""
"Custom text input 18",""
"Custom text input 19",""
"Custom text input 20",""
"Custom text input 21",""
"Custom text input 22",""
"Custom text input 23",""
"Custom text input 24",""
"Custom text input 25",""
"Custom text input 26",""
"Custom text input 27",""
"Custom text input 28",""
"Custom text input 29",""
"Custom text input 30",""
"Custom text input 31",""
"Custom text input 32",""
"Custom text input 33",""
"Custom text input 34",""
"Custom text input 35",""
"Custom text input 36",""
"Custom text input 37",""
"Custom text input 38",""
"Custom text input 39",""
"Custom text input 40",""
"Custom text input 41",""
"Custom text input 42",""
"Custom text input 43",""
"Custom text input 44",""
"Custom text input 45",""
"Custom text input 46",""
"Custom text input 47",""
"Custom text input 48",""
"Custom text input 49",""
"Custom text input 50",""
"Custom number input  1",0.000000,""
"Custom number input  2",0.000000,""
"Custom number input  3",0.000000,""
"Custom number input  4",0.000000,""
"Custom number input  5",0.000000,""
"Custom number input  6",0.000000,""
"Custom number input  7",0.000000,""
"Custom number input  8",0.000000,""
"Custom number input  9",0.000000,""
"Custom number input 10",0.000000,""
"Time sec","Extension mm","Load N","Tensile stress MPa","Cycle Count ","Total Cycle Count ","Repetitions Count ","Marked Data ","PIP Count ","Tensile extension mm","Tensile strain %","Corrected Position mm","Tenacity gf/tex"
0,0,0.01685444,0.001685444,0,0,0,0,0,0,0,0,0.01718675
0.3,0.001875,0.02247635,0.002247635,0,0,0,0,0,0.001875,0.001875,0.001875,0.0229195
0.6,0.009374999,0.04830474,0.004830474,0,0,0,0,0,0.009374999,0.009374999,0.009374999,0.04925713
0.9000001,0.015,0.06584038,0.006584038,0,0,0,0,0,0.015,0.015,0.015,0.06713851
1.2,0.01984375,0.07847706,0.007847706,0,0,0,0,0,0.01984375,0.01984375,0.01984375,0.08002433
1.5,0.0246875,0.09060426,0.009060426,0,0,0,0,0,0.0246875,0.0246875,0.0246875,0.09239063
1.8,0.02984375,0.1032119,0.01032119,0,0,0,0,0,0.02984375,0.02984375,0.02984375,0.1052469
2.1,0.03499999,0.1152171,0.01152171,0,0,0,0,0,0.03499999,0.03499999,0.03499999,0.1174887
2.4,0.04046875,0.1263408,0.01263408,0,0,0,0,0,0.04046874,0.04046874,0.04046875,0.1288317
2.7,0.04531249,0.1351727,0.01351727,0,0,0,0,0,0.04531249,0.04531249,0.04531249,0.1378378
3,0.05031249,0.1444968,0.01444968,0,0,0,0,0,0.05031249,0.05031249,0.05031249,0.1473457
3.3,0.05468749,0.1517317,0.01517317,0,0,0,0,0,0.05468749,0.05468749,0.05468749,0.1547233
3.6,0.05984374,0.1606857,0.01606857,0,0,0,0,0,0.05984375,0.05984375,0.05984374,0.1638538
3.9,0.06499999,0.1692228,0.01692228,0,0,0,0,0,0.06499998,0.06499998,0.06499999,0.1725593
4.2,0.07046874,0.1778911,0.01778911,0,0,0,0,0,0.07046874,0.07046874,0.07046874,0.1813984
4.5,0.07515624,0.1842879,0.01842879,0,0,0,0,0,0.07515624,0.07515624,0.07515624,0.1879213
4.8,0.07999999,0.1913127,0.01913127,0,0,0,0,0,0.07999999,0.07999999,0.07999999,0.1950846
5.1,0.08499999,0.1981555,0.01981555,0,0,0,0,0,0.08499999,0.08499999,0.08499999,0.2020624
5.4,0.09031249,0.2049035,0.02049035,0,0,0,0,0,0.09031249,0.09031249,0.09031249,0.2089434
5.7,0.09531248,0.2115405,0.02115405,0,0,0,0,0,0.09531248,0.09531248,0.09531248,0.2157113
6,0.1001562,0.217373,0.0217373,0,0,0,0,0,0.1001562,0.1001562,0.1001562,0.2216588
6.3,0.1051562,0.2229574,0.02229574,0,0,0,0,0,0.1051562,0.1051562,0.1051562,0.2273533
6.6,0.1098437,0.2287594,0.02287594,0,0,0,0,0,0.1098437,0.1098437,0.1098437,0.2332696
6.9,0.1148437,0.2344298,0.02344298,0,0,0,0,0,0.1148437,0.1148437,0.1148437,0.2390519
7.2,0.12,0.2400059,0.02400059,0,0,0,0,0,0.12,0.12,0.12,0.2447379
7.5,0.1253125,0.2465579,0.02465579,0,0,0,0,0,0.1253125,0.1253125,0.1253125,0.2514191
7.8,0.1304687,0.251405,0.0251405,0,0,0,0,0,0.1304687,0.1304687,0.1304687,0.2563618
8.1,0.135,0.2553735,0.02553735,0,0,0,0,0,0.135,0.135,0.135,0.2604085
8.400001,0.1398437,0.2598354,0.02598354,0,0,0,0,0,0.1398437,0.1398437,0.1398437,0.2649584
8.700001,0.1448437,0.2646843,0.02646843,0,0,0,0,0,0.1448437,0.1448437,0.1448437,0.2699029
9,0.1501562,0.2698804,0.02698804,0,0,0,0,0,0.1501562,0.1501562,0.1501562,0.2752014
9.3,0.1553125,0.2743527,0.02743527,0,0,0,0,0,0.1553125,0.1553125,0.1553125,0.2797619
9.6,0.1601562,0.2785263,0.02785263,0,0,0,0,0,0.1601562,0.1601562,0.1601562,0.2840177
9.900001,0.165,0.2828684,0.02828684,0,0,0,0,0,0.165,0.165,0.165,0.2884455
10.2,0.17,0.2874262,0.02874262,0,0,0,0,0,0.17,0.17,0.17,0.2930932
10.5,0.175,0.2909574,0.02909574,0,0,0,0,0,0.175,0.175,0.175,0.296694
10.8,0.18,0.2950496,0.02950496,0,0,0,0,0,0.18,0.18,0.18,0.3008669
11.1,0.1853125,0.2990301,0.02990301,0,0,0,0,0,0.1853125,0.1853125,0.1853125,0.3049259
11.4,0.19,0.3023151,0.03023151,0,0,0,0,0,0.19,0.19,0.19,0.3082756
11.7,0.1948437,0.3050438,0.03050438,0,0,0,0,0,0.1948437,0.1948437,0.1948437,0.3110581
12,0.1998437,0.3077534,0.03077535,0,0,0,0,0,0.1998437,0.1998437,0.1998437,0.3138212
12.3,0.205,0.3107887,0.03107887,0,0,0,0,0,0.205,0.205,0.205,0.3169163
12.6,0.210625,0.3135074,0.03135074,0,0,0,0,0,0.210625,0.210625,0.210625,0.3196886
12.9,0.2153125,0.3160096,0.03160096,0,0,0,0,0,0.2153125,0.2153125,0.2153125,0.3222401
13.2,0.22,0.3186405,0.03186405,0,0,0,0,0,0.22,0.22,0.22,0.3249229
13.5,0.2248437,0.322098,0.0322098,0,0,0,0,0,0.2248437,0.2248437,0.2248437,0.3284485
13.8,0.2298437,0.3219333,0.03219333,0,0,0,0,0,0.2298437,0.2298437,0.2298437,0.3282806
14.1,0.235,0.3241176,0.03241176,0,0,0,0,0,0.235,0.235,0.235,0.330508
14.4,0.2403125,0.3269302,0.03269302,0,0,0,0,0,0.2403125,0.2403125,0.2403125,0.333376
14.7,0.2449999,0.3288761,0.03288762,0,0,0,0,0,0.2449999,0.2449999,0.2449999,0.3353603
15,0.2498437,0.3307543,0.03307543,0,0,0,0,0,0.2498437,0.2498437,0.2498437,0.3372755
15.3,0.255,0.3235691,0.03235691,0,0,0,0,0,0.255,0.255,0.255,0.3299487
15.6,0.2598437,0.326073,0.0326073,0,0,0,0,0,0.2598437,0.2598437,0.2598437,0.3325019
15.9,0.2651562,0.3295493,0.03295493,0,0,0,0,0,0.2651562,0.2651562,0.2651562,0.3360468
16.2,0.2701562,0.3320143,0.03320143,0,0,0,0,0,0.2701562,0.2701562,0.2701562,0.3385604
16.5,0.2751562,0.3346462,0.03346461,0,0,0,0,0,0.2751562,0.2751562,0.2751562,0.3412441
16.8,0.2798437,0.3369255,0.03369255,0,0,0,0,0,0.2798437,0.2798437,0.2798437,0.3435684
17.1,0.2848437,0.3397487,0.03397487,0,0,0,0,0,0.2848437,0.2848437,0.2848437,0.3464473
17.4,0.2899999,0.3425869,0.03425869,0,0,0,0,0,0.2899999,0.2899999,0.2899999,0.3493415
17.7,0.2954687,0.347003,0.0347003,0,0,0,0,0,0.2954687,0.2954687,0.2954687,0.3538446
18,0.3001562,0.3492061,0.03492061,0,0,0,0,0,0.3001562,0.3001562,0.3001562,0.3560911
18.3,0.3048437,0.3512693,0.03512693,0,0,0,0,0,0.3048437,0.3048437,0.3048437,0.358195
18.6,0.3098437,0.3549095,0.03549095,0,0,0,0,0,0.3098437,0.3098437,0.3098437,0.3619069
18.9,0.315,0.3582597,0.03582598,0,0,0,0,0,0.315,0.315,0.315,0.3653233
19.2,0.3201562,0.3606977,0.03606977,0,0,0,0,0,0.3201562,0.3201562,0.3201562,0.3678093
19.5,0.3254687,0.3642058,0.03642058,0,0,0,0,0,0.3254687,0.3254687,0.3254687,0.3713866
19.8,0.3303124,0.3680283,0.03680283,0,0,0,0,0,0.3303124,0.3303124,0.3303124,0.3752844
20.1,0.3353124,0.37163,0.037163,0,0,0,0,0,0.3353125,0.3353125,0.3353124,0.3789572
20.4,0.3403125,0.3737585,0.03737585,0,0,0,0,0,0.3403125,0.3403125,0.3403125,0.3811276
20.7,0.3448437,0.3754324,0.03754324,0,0,0,0,0,0.3448437,0.3448437,0.3448437,0.3828345
21,0.35,0.3798408,0.03798408,0,0,0,0,0,0.35,0.35,0.35,0.3873298
21.3,0.3551562,0.3837809,0.03837809,0,0,0,0,0,0.3551562,0.3551562,0.3551562,0.3913476
21.6,0.3601562,0.3876988,0.03876988,0,0,0,0,0,0.3601562,0.3601562,0.3601562,0.3953428
21.9,0.3648437,0.3902076,0.03902075,0,0,0,0,0,0.3648437,0.3648437,0.3648437,0.397901
22.2,0.3699999,0.3935423,0.03935423,0,0,0,0,0,0.3699999,0.3699999,0.3699999,0.4013015
22.5,0.3753124,0.3974717,0.03974717,0,0,0,0,0,0.3753124,0.3753124,0.3753124,0.4053083
22.8,0.3807812,0.4012641,0.04012641,0,0,0,0,0,0.3807812,0.3807812,0.3807812,0.4091755
23.1,0.3851562,0.4034303,0.04034303,0,0,0,0,0,0.3851562,0.3851562,0.3851562,0.4113844
23.4,0.3899999,0.4072957,0.04072957,0,0,0,0,0,0.39,0.39,0.3899999,0.415326
23.7,0.3948437,0.4109237,0.04109237,0,0,0,0,0,0.3948437,0.3948437,0.3948437,0.4190255
24,0.3998437,0.4122633,0.04122633,0,0,0,0,0,0.3998437,0.3998437,0.3998437,0.4203916
24.3,0.4049999,0.4165892,0.04165892,0,0,0,0,0,0.4049999,0.4049999,0.4049999,0.4248028
24.6,0.4104687,0.4205331,0.04205331,0,0,0,0,0,0.4104687,0.4104687,0.4104687,0.4288244
24.9,0.4153124,0.4199638,0.04199638,0,0,0,0,0,0.4153124,0.4153124,0.4153124,0.4282439
25.2,0.4201562,0.4237253,0.04237253,0,0,0,0,0,0.4201562,0.4201562,0.4201562,0.4320796
25.5,0.4249999,0.42609,0.042609,0,0,0,0,0,0.425,0.425,0.4249999,0.4344909
25.8,0.4298437,0.429001,0.0429001,0,0,0,0,0,0.4298437,0.4298437,0.4298437,0.4374593
26.1,0.4351562,0.4312755,0.04312754,0,0,0,0,0,0.4351562,0.4351562,0.4351562,0.4397786
26.4,0.4403124,0.4354919,0.04354919,0,0,0,0,0,0.4403124,0.4403124,0.4403124,0.4440782
26.7,0.4453124,0.4394307,0.04394307,0,0,0,0,0,0.4453124,0.4453124,0.4453124,0.4480946
27,0.4499999,0.4429968,0.04429968,0,0,0,0,0,0.4499999,0.4499999,0.4499999,0.451731
27.3,0.4549999,0.4455796,0.04455796,0,0,0,0,0,0.455,0.455,0.4549999,0.4543647
27.6,0.46,0.4473089,0.04473089,0,0,0,0,0,0.4599999,0.4599999,0.46,0.4561282
27.9,0.4654687,0.4516866,0.04516866,0,0,0,0,0,0.4654687,0.4654687,0.4654687,0.4605921
28.2,0.4699999,0.4500045,0.04500045,0,0,0,0,0,0.4699999,0.4699999,0.4699999,0.4588769
28.5,0.4749999,0.4510636,0.04510636,0,0,0,0,0,0.475,0.475,0.4749999,0.4599569
28.8,0.4798437,0.4553654,0.04553654,0,0,0,0,0,0.4798437,0.4798437,0.4798437,0.4643435
29.1,0.4848437,0.4586167,0.04586167,0,0,0,0,0,0.4848437,0.4848437,0.4848437,0.4676588
29.4,0.4901562,0.4616725,0.04616725,0,0,0,0,0,0.4901562,0.4901562,0.4901562,0.4707749
29.7,0.4956249,0.4649706,0.04649706,0,0,0,0,0,0.4956249,0.4956249,0.4956249,0.4741381
30,0.5003124,0.4678622,0.04678622,0,0,0,0,0,0.5003124,0.5003124,0.5003124,0.4770867
30.3,0.5051562,0.4714465,0.04714465,0,0,0,0,0,0.5051562,0.5051562,0.5051562,0.4807416
30.6,0.5099999,0.4728134,0.04728134,0,0,0,0,0,0.5099999,0.5099999,0.5099999,0.4821355
30.9,0.5148437,0.4757318,0.04757318,0,0,0,0,0,0.5148437,0.5148437,0.5148437,0.4851114
31.2,0.5199999,0.4781441,0.04781441,0,0,0,0,0,0.5199999,0.5199999,0.5199999,0.4875713
31.5,0.5253124,0.4827388,0.04827388,0,0,0,0,0,0.5253124,0.5253124,0.5253124,0.4922566
31.8,0.5299999,0.4820568,0.04820568,0,0,0,0,0,0.5299999,0.5299999,0.5299999,0.4915611
32.1,0.5348437,0.4863692,0.04863691,0,0,0,0,0,0.5348437,0.5348437,0.5348437,0.4959585
32.4,0.5399999,0.490786,0.0490786,0,0,0,0,0,0.5399999,0.5399999,0.5399999,0.5004624
32.7,0.5451561,0.4938089,0.04938089,0,0,0,0,0,0.5451561,0.5451561,0.5451561,0.5035449
33,0.5504686,0.4979582,0.04979581,0,0,0,0,0,0.5504686,0.5504686,0.5504686,0.507776
33.3,0.5551561,0.5018342,0.05018342,0,0,0,0,0,0.5551562,0.5551562,0.5551561,0.5117285
33.6,0.5599999,0.4993158,0.04993159,0,0,0,0,0,0.5599999,0.5599999,0.5599999,0.5091605
33.9,0.5648436,0.5035862,0.05035862,0,0,0,0,0,0.5648437,0.5648437,0.5648436,0.5135151
34.2,0.5698436,0.5082163,0.05082164,0,0,0,0,0,0.5698436,0.5698436,0.5698436,0.5182365
34.5,0.5749999,0.5116976,0.05116976,0,0,0,0,0,0.5749999,0.5749999,0.5749999,0.5217863
34.8,0.5803124,0.514764,0.0514764,0,0,0,0,0,0.5803124,0.5803124,0.5803124,0.5249132
35.1,0.5853124,0.5180451,0.05180451,0,0,0,0,0,0.5853124,0.5853124,0.5853124,0.5282589
35.4,0.5901561,0.5228463,0.05228463,0,0,0,0,0,0.5901561,0.5901561,0.5901561,0.5331548
35.7,0.5946874,0.5263801,0.05263801,0,0,0,0,0,0.5946874,0.5946874,0.5946874,0.5367583
36,0.5998436,0.5313254,0.05313254,0,0,0,0,0,0.5998436,0.5998436,0.5998436,0.5418011
36.3,0.6051561,0.5356001,0.05356001,0,0,0,0,0,0.6051561,0.6051561,0.6051561,0.5461601
36.6,0.6103124,0.5359871,0.05359871,0,0,0,0,0,0.6103124,0.6103124,0.6103124,0.5465547
36.9,0.6151561,0.5393701,0.05393701,0,0,0,0,0,0.6151561,0.6151561,0.6151561,0.5500044
37.2,0.6199999,0.5436177,0.05436178,0,0,0,0,0,0.6199999,0.6199999,0.6199999,0.5543358
37.5,0.6249999,0.5488152,0.05488152,0,0,0,0,0,0.6249999,0.6249999,0.6249999,0.5596357
37.8,0.6299999,0.5539736,0.05539736,0,0,0,0,0,0.6299999,0.6299999,0.6299999,0.5648959
38.1,0.6354686,0.5581958,0.05581958,0,0,0,0,0,0.6354687,0.6354687,0.6354686,0.5692013
38.4,0.6399999,0.5612281,0.05612281,0,0,0,0,0,0.6399999,0.6399999,0.6399999,0.5722933
38.7,0.6449999,0.5624856,0.05624856,0,0,0,0,0,0.6449999,0.6449999,0.6449999,0.5735757
39,0.6498437,0.5665841,0.05665841,0,0,0,0,0,0.6498436,0.6498436,0.6498437,0.577755
39.3,0.6548436,0.5718832,0.05718832,0,0,0,0,0,0.6548436,0.6548436,0.6548436,0.5831586
39.6,0.6601561,0.5766941,0.05766941,0,0,0,0,0,0.6601561,0.6601561,0.6601561,0.5880643
39.9,0.6656249,0.5801957,0.05801957,0,0,0,0,0,0.6656249,0.6656249,0.6656249,0.5916349
40.2,0.6703124,0.5835463,0.05835463,0,0,0,0,0,0.6703124,0.6703124,0.6703124,0.5950516
40.5,0.6753124,0.5893612,0.05893612,0,0,0,0,0,0.6753124,0.6753124,0.6753124,0.6009812
40.8,0.6798437,0.5933507,0.05933508,0,0,0,0,0,0.6798437,0.6798437,0.6798437,0.6050494
41.1,0.6848436,0.5967196,0.05967196,0,0,0,0,0,0.6848437,0.6848437,0.6848436,0.6084847
41.4,0.6899999,0.601771,0.0601771,0,0,0,0,0,0.6899999,0.6899999,0.6899999,0.6136357
41.7,0.6953124,0.6068498,0.06068498,0,0,0,0,0,0.6953124,0.6953124,0.6953124,0.6188146
42,0.7001561,0.6105284,0.06105284,0,0,0,0,0,0.7001562,0.7001562,0.7001561,0.6225657
42.3,0.7049999,0.6154363,0.06154363,0,0,0,0,0,0.7049999,0.7049999,0.7049999,0.6275704
42.6,0.7099999,0.6186839,0.06186839,0,0,0,0,0,0.7099999,0.7099999,0.7099999,0.630882
42.9,0.7153124,0.6232591,0.06232591,0,0,0,0,0,0.7153124,0.7153124,0.7153124,0.6355474
43.2,0.7203124,0.6280329,0.06280329,0,0,0,0,0,0.7203124,0.7203124,0.7203124,0.6404153
43.5,0.7253124,0.6321461,0.06321461,0,0,0,0,0,0.7253124,0.7253124,0.7253124,0.6446096
43.8,0.7301561,0.6363997,0.06363997,0,0,0,0,0,0.7301561,0.7301561,0.7301561,0.6489471
44.1,0.7348437,0.6391907,0.06391907,0,0,0,0,0,0.7348437,0.7348437,0.7348437,0.6517931
44.4,0.7398436,0.643799,0.0643799,0,0,0,0,0,0.7398437,0.7398437,0.7398436,0.6564923
44.7,0.7449999,0.6491672,0.06491672,0,0,0,0,0,0.7449999,0.7449999,0.7449999,0.6619663
45,0.7504686,0.654445,0.0654445,0,0,0,0,0,0.7504686,0.7504686,0.7504686,0.6673481
45.3,0.7554686,0.6582736,0.06582735,0,0,0,0,0,0.7554686,0.7554686,0.7554686,0.6712522
45.6,0.7599999,0.6631522,0.06631522,0,0,0,0,0,0.7599999,0.7599999,0.7599999,0.676227
45.9,0.7648437,0.6682416,0.06682416,0,0,0,0,0,0.7648436,0.7648436,0.7648437,0.6814168
46.2,0.7698436,0.6739114,0.06739114,0,0,0,0,0,0.7698436,0.7698436,0.7698436,0.6871984
46.5,0.7751561,0.6799537,0.06799537,0,0,0,0,0,0.7751561,0.7751561,0.7751561,0.6933599
46.8,0.7803124,0.6852623,0.06852623,0,0,0,0,0,0.7803124,0.7803124,0.7803124,0.6987731
47.1,0.7853124,0.6888099,0.068881,0,0,0,0,0,0.7853124,0.7853124,0.7853124,0.7023907
47.4,0.7901561,0.693306,0.0693306,0,0,0,0,0,0.7901561,0.7901561,0.7901561,0.7069753
47.7,0.7949999,0.6965573,0.06965573,0,0,0,0,0,0.7949999,0.7949999,0.7949999,0.7102908
48,0.8001562,0.7021713,0.07021713,0,0,0,0,0,0.8001562,0.8001562,0.8001562,0.7160154
48.3,0.8053124,0.7039786,0.07039786,0,0,0,0,0,0.8053124,0.8053124,0.8053124,0.7178584
48.6,0.8103124,0.7087636,0.07087636,0,0,0,0,0,0.8103124,0.8103124,0.8103124,0.7227377
48.9,0.8149999,0.714357,0.0714357,0,0,0,0,0,0.8149999,0.8149999,0.8149999,0.7284414
49.2,0.8198437,0.7175512,0.07175512,0,0,0,0,0,0.8198436,0.8198436,0.8198437,0.7316986
49.5,0.8248436,0.7241012,0.07241012,0,0,0,0,0,0.8248436,0.8248436,0.8248436,0.7383777
49.8,0.8299999,0.7297934,0.07297934,0,0,0,0,0,0.8299999,0.8299999,0.8299999,0.7441821
50.1,0.8356249,0.7346854,0.07346854,0,0,0,0,0,0.8356249,0.8356249,0.8356249,0.7491706
50.4,0.8404686,0.7391332,0.07391332,0,0,0,0,0,0.8404686,0.8404686,0.8404686,0.7537061
50.7,0.8449999,0.7421396,0.07421396,0,0,0,0,0,0.8449999,0.8449999,0.8449999,0.7567718
51,0.8498437,0.7458804,0.07458804,0,0,0,0,0,0.8498437,0.8498437,0.8498437,0.7605863
51.3,0.8548436,0.7509866,0.07509866,0,0,0,0,0,0.8548436,0.8548436,0.8548436,0.7657933
51.6,0.8598436,0.7549461,0.07549462,0,0,0,0,0,0.8598436,0.8598436,0.8598436,0.7698308
51.9,0.8654686,0.7613766,0.07613765,0,0,0,0,0,0.8654686,0.8654686,0.8654686,0.776388
52.2,0.8701562,0.7666442,0.07666442,0,0,0,0,0,0.8701562,0.8701562,0.8701562,0.7817595
52.5,0.8751561,0.7713703,0.07713704,0,0,0,0,0,0.8751562,0.8751562,0.8751561,0.7865788
52.8,0.8798437,0.7756468,0.07756469,0,0,0,0,0,0.8798437,0.8798437,0.8798437,0.7909396
53.1,0.8849999,0.7818218,0.07818218,0,0,0,0,0,0.8849999,0.8849999,0.8849999,0.7972364
53.4,0.8901561,0.7843121,0.07843121,0,0,0,0,0,0.8901561,0.8901561,0.8901561,0.7997758
53.7,0.8951561,0.7893619,0.07893619,0,0,0,0,0,0.8951561,0.8951561,0.8951561,0.8049251
54,0.9001562,0.7947052,0.07947052,0,0,0,0,0,0.9001561,0.9001561,0.9001562,0.8103738
54.3,0.9049999,0.7999101,0.07999101,0,0,0,0,0,0.9049999,0.9049999,0.9049999,0.8156813
54.6,0.9098437,0.8040233,0.08040233,0,0,0,0,0,0.9098437,0.9098437,0.9098437,0.8198755
54.9,0.9149999,0.8105909,0.08105908,0,0,0,0,0,0.9149998,0.9149998,0.9149999,0.8265727
55.2,0.9206249,0.8178282,0.08178282,0,0,0,0,0,0.9206249,0.9206249,0.9206249,0.8339526
55.5,0.9251561,0.8220344,0.08220344,0,0,0,0,0,0.9251561,0.9251561,0.9251561,0.8382418
55.8,0.9298436,0.8274334,0.08274333,0,0,0,0,0,0.9298437,0.9298437,0.9298436,0.8437472
56.1,0.9346874,0.8340402,0.08340402,0,0,0,0,0,0.9346874,0.9346874,0.9346874,0.8504843
56.4,0.9398437,0.8405225,0.08405225,0,0,0,0,0,0.9398437,0.9398437,0.9398437,0.8570945
56.7,0.9451561,0.8472753,0.08472753,0,0,0,0,0,0.9451562,0.9451562,0.9451561,0.8639804
57,0.9503124,0.8537795,0.08537795,0,0,0,0,0,0.9503124,0.9503124,0.9503124,0.8706129
57.3,0.9553124,0.859505,0.0859505,0,0,0,0,0,0.9553124,0.9553124,0.9553124,0.8764512
57.6,0.9603124,0.865258,0.0865258,0,0,0,0,0,0.9603124,0.9603124,0.9603124,0.8823176
57.9,0.9651561,0.8704554,0.08704554,0,0,0,0,0,0.9651561,0.9651561,0.9651561,0.8876175
58.2,0.9698436,0.876268,0.0876268,0,0,0,0,0,0.9698436,0.9698436,0.9698436,0.8935447
58.5,0.9749999,0.8836954,0.08836954,0,0,0,0,0,0.9749999,0.9749999,0.9749999,0.9011185
58.8,0.980156,0.8914434,0.08914434,0,0,0,0,0,0.980156,0.980156,0.980156,0.9090194
59.1,0.9853123,0.8947926,0.08947925,0,0,0,0,0,0.9853123,0.9853123,0.9853123,0.9124345
59.4,0.9898435,0.8958156,0.08958156,0,0,0,0,0,0.9898435,0.9898435,0.9898435,0.9134777
59.7,0.9948435,0.9028441,0.09028441,0,0,0,0,0,0.9948435,0.9948435,0.9948435,0.9206448
60,1.000312,0.9097208,0.09097208,0,0,0,0,0,1.000312,1.000312,1.000312,0.9276571
60.3,1.005625,0.9119885,0.09119885,0,0,0,0,0,1.005625,1.005625,1.005625,0.9299695
60.6,1.010312,0.9157282,0.09157282,0,0,0,0,0,1.010312,1.010312,1.010312,0.9337829
60.9,1.015,0.9230539,0.09230539,0,0,0,0,0,1.015,1.015,1.015,0.9412531
61.2,1.019844,0.9294812,0.09294812,0,0,0,0,0,1.019843,1.019843,1.019844,0.947807
61.5,1.024844,0.9371201,0.093712,0,0,0,0,0,1.024844,1.024844,1.024844,0.9555965
61.8,1.03,0.9426502,0.09426501,0,0,0,0,0,1.03,1.03,1.03,0.9612356
62.1,1.035469,0.9509001,0.09509001,0,0,0,0,0,1.035469,1.035469,1.035469,0.9696482
62.4,1.040312,0.9532763,0.09532763,0,0,0,0,0,1.040312,1.040312,1.040312,0.9720713
62.7,1.045156,0.9585488,0.09585488,0,0,0,0,0,1.045156,1.045156,1.045156,0.9774477
63,1.05,0.9646234,0.09646234,0,0,0,0,0,1.05,1.05,1.05,0.9836421
63.3,1.054844,0.9713112,0.09713113,0,0,0,0,0,1.054844,1.054844,1.054844,0.9904618
63.6,1.060156,0.9787429,0.09787429,0,0,0,0,0,1.060156,1.060156,1.060156,0.99804
63.9,1.065312,0.9874471,0.09874471,0,0,0,0,0,1.065312,1.065312,1.065312,1.006916
64.2,1.070312,0.9946651,0.09946651,0,0,0,0,0,1.070312,1.070312,1.070312,1.014276
64.5,1.075,1.00095,0.100095,0,0,0,0,0,1.075,1.075,1.075,1.020685
64.8,1.08,1.007604,0.1007604,0,0,0,0,0,1.08,1.08,1.08,1.02747
65.10001,1.085156,1.014593,0.1014593,0,0,0,0,0,1.085156,1.085156,1.085156,1.034597
65.4,1.090469,1.022643,0.1022643,0,0,0,0,0,1.090469,1.090469,1.090469,1.042806
65.70001,1.095,1.028104,0.1028104,0,0,0,0,0,1.095,1.095,1.095,1.048375
66,1.1,1.033294,0.1033294,0,0,0,0,0,1.1,1.1,1.1,1.053666
66.3,1.104844,1.03155,0.103155,0,0,0,0,0,1.104844,1.104844,1.104844,1.051888
66.60001,1.109843,1.040341,0.1040341,0,0,0,0,0,1.109843,1.109843,1.109843,1.060853
66.9,1.115,1.048668,0.1048668,0,0,0,0,0,1.115,1.115,1.115,1.069344
67.20001,1.120625,1.056344,0.1056344,0,0,0,0,0,1.120625,1.120625,1.120625,1.077171
67.5,1.125312,1.061095,0.1061095,0,0,0,0,0,1.125312,1.125312,1.125312,1.082016
67.8,1.130156,1.066633,0.1066633,0,0,0,0,0,1.130156,1.130156,1.130156,1.087663
68.10001,1.135,1.071278,0.1071278,0,0,0,0,0,1.135,1.135,1.135,1.0924
68.4,1.139844,1.079678,0.1079677,0,0,0,0,0,1.139844,1.139844,1.139844,1.100965
68.70001,1.145,1.088803,0.1088803,0,0,0,0,0,1.145,1.145,1.145,1.11027
69,1.150156,1.090852,0.1090852,0,0,0,0,0,1.150156,1.150156,1.150156,1.112359
69.3,1.155,1.096213,0.1096213,0,0,0,0,0,1.155,1.155,1.155,1.117826
69.60001,1.159844,1.101766,0.1101766,0,0,0,0,0,1.159844,1.159844,1.159844,1.123489
69.9,1.164844,1.110047,0.1110047,0,0,0,0,0,1.164844,1.164844,1.164844,1.131933
70.20001,1.170156,1.118838,0.1118838,0,0,0,0,0,1.170156,1.170156,1.170156,1.140897
70.5,1.175469,1.125497,0.1125497,0,0,0,0,0,1.175469,1.175469,1.175469,1.147687
70.8,1.180156,1.13215,0.113215,0,0,0,0,0,1.180156,1.180156,1.180156,1.154472
71.10001,1.185,1.138637,0.1138637,0,0,0,0,0,1.185,1.185,1.185,1.161086
71.4,1.189844,1.142512,0.1142512,0,0,0,0,0,1.189844,1.189844,1.189844,1.165038
71.70001,1.194844,1.146935,0.1146935,0,0,0,0,0,1.194844,1.194844,1.194844,1.169549
72,1.2,1.154348,0.1154348,0,0,0,0,0,1.2,1.2,1.2,1.177108
72.3,1.205312,1.161688,0.1161688,0,0,0,0,0,1.205312,1.205312,1.205312,1.184592
72.60001,1.210312,1.167028,0.1167028,0,0,0,0,0,1.210312,1.210312,1.210312,1.190038
72.9,1.215156,1.171232,0.1171232,0,0,0,0,0,1.215156,1.215156,1.215156,1.194324
73.20001,1.219687,1.17559,0.117559,0,0,0,0,0,1.219687,1.219687,1.219687,1.198768
73.5,1.224844,1.185467,0.1185466,0,0,0,0,0,1.224844,1.224844,1.224844,1.208839
73.8,1.230156,1.193925,0.1193925,0,0,0,0,0,1.230156,1.230156,1.230156,1.217465
74.10001,1.235312,1.203566,0.1203566,0,0,0,0,0,1.235312,1.235312,1.235312,1.227296
74.4,1.240156,1.209566,0.1209566,0,0,0,0,0,1.240156,1.240156,1.240156,1.233414
74.70001,1.245,1.21616,0.121616,0,0,0,0,0,1.245,1.245,1.245,1.240138
75,1.25,1.222974,0.1222974,0,0,0,0,0,1.25,1.25,1.25,1.247086
75.3,1.255156,1.231347,0.1231347,0,0,0,0,0,1.255156,1.255156,1.255156,1.255625
75.60001,1.260312,1.240241,0.1240241,0,0,0,0,0,1.260312,1.260312,1.260312,1.264694
75.9,1.265156,1.245292,0.1245292,0,0,0,0,0,1.265156,1.265156,1.265156,1.269844
76.20001,1.27,1.252697,0.1252697,0,0,0,0,0,1.27,1.27,1.27,1.277396
76.5,1.274844,1.257007,0.1257007,0,0,0,0,0,1.274844,1.274844,1.274844,1.281791
76.8,1.279844,1.263803,0.1263803,0,0,0,0,0,1.279843,1.279843,1.279844,1.288721
77.10001,1.285156,1.272482,0.1272482,0,0,0,0,0,1.285156,1.285156,1.285156,1.297571
77.4,1.290468,1.280068,0.1280068,0,0,0,0,0,1.290468,1.290468,1.290468,1.305306
77.70001,1.295312,1.286564,0.1286564,0,0,0,0,0,1.295312,1.295312,1.295312,1.311931
78,1.300312,1.294294,0.1294294,0,0,0,0,0,1.300312,1.300312,1.300312,1.319813
78.3,1.304844,1.300859,0.1300859,0,0,0,0,0,1.304844,1.304844,1.304844,1.326507
78.60001,1.309844,1.310382,0.1310382,0,0,0,0,0,1.309844,1.309844,1.309844,1.336218
78.9,1.315,1.319714,0.1319714,0,0,0,0,0,1.315,1.315,1.315,1.345734
79.192,1.320312,1.200066,0.1200066,0,0,0,0,0,1.320312,1.320312,1.320312,1.223727
79.49201,1.325,1.201893,0.1201893,0,0,0,0,0,1.325,1.325,1.325,1.22559
79.79201,1.33,1.19571,0.119571,0,0,0,0,0,1.33,1.33,1.33,1.219285
80.092,1.334844,1.202741,0.1202741,0,0,0,0,0,1.334844,1.334844,1.334844,1.226455
80.39201,1.340156,1.213321,0.1213321,0,0,0,0,0,1.340156,1.340156,1.340156,1.237243
80.692,1.345156,1.222796,0.1222796,0,0,0,0,0,1.345156,1.345156,1.345156,1.246905
80.99201,1.350156,1.232918,0.1232918,0,0,0,0,0,1.350156,1.350156,1.350156,1.257226
81.29201,1.355156,1.241178,0.1241178,0,0,0,0,0,1.355156,1.355156,1.355156,1.26565
81.592,1.359844,1.250568,0.1250568,0,0,0,0,0,1.359843,1.359843,1.359844,1.275224
81.89201,1.364687,1.258986,0.1258986,0,0,0,0,0,1.364687,1.364687,1.364687,1.283808
82.192,1.369843,1.268644,0.1268644,0,0,0,0,0,1.369843,1.369843,1.369843,1.293656
82.49201,1.375312,1.277388,0.1277388,0,0,0,0,0,1.375312,1.375312,1.375312,1.302573
82.79201,1.380312,1.285891,0.1285891,0,0,0,0,0,1.380312,1.380312,1.380312,1.311244
83.092,1.385,1.293748,0.1293748,0,0,0,0,0,1.385,1.385,1.385,1.319256
83.39201,1.389687,1.301987,0.1301987,0,0,0,0,0,1.389687,1.389687,1.389687,1.327658
83.692,1.394844,1.3127,0.13127,0,0,0,0,0,1.394844,1.394844,1.394844,1.338581
83.99201,1.400156,1.322893,0.1322893,0,0,0,0,0,1.400156,1.400156,1.400156,1.348976
84.29201,1.405312,1.332367,0.1332367,0,0,0,0,0,1.405312,1.405312,1.405312,1.358636
84.592,1.410156,1.33956,0.133956,0,0,0,0,0,1.410156,1.410156,1.410156,1.365972
84.89201,1.415,1.347694,0.1347694,0,0,0,0,0,1.415,1.415,1.415,1.374266
85.192,1.419844,1.352962,0.1352962,0,0,0,0,0,1.419844,1.419844,1.419844,1.379637
85.49201,1.425,1.36137,0.136137,0,0,0,0,0,1.425,1.425,1.425,1.388211
85.79201,1.43,1.363082,0.1363082,0,0,0,0,0,1.43,1.43,1.43,1.389957
86.092,1.435156,1.372221,0.1372221,0,0,0,0,0,1.435156,1.435156,1.435156,1.399276
86.39201,1.439844,1.379392,0.1379392,0,0,0,0,0,1.439844,1.439844,1.439844,1.406588
86.692,1.444687,1.389396,0.1389396,0,0,0,0,0,1.444687,1.444687,1.444687,1.416789
86.99201,1.449687,1.40019,0.140019,0,0,0,0,0,1.449687,1.449687,1.449687,1.427797
87.29201,1.455,1.401422,0.1401422,0,0,0,0,0,1.455,1.455,1.455,1.429052
87.592,1.460469,1.407557,0.1407557,0,0,0,0,0,1.460469,1.460469,1.460469,1.435309
87.89201,1.465156,1.413384,0.1413384,0,0,0,0,0,1.465156,1.465156,1.465156,1.441251
88.192,1.469844,1.420734,0.1420734,0,0,0,0,0,1.469844,1.469844,1.469844,1.448745
88.49201,1.474687,1.426523,0.1426523,0,0,0,0,0,1.474687,1.474687,1.474687,1.454648
88.79201,1.479844,1.436503,0.1436503,0,0,0,0,0,1.479843,1.479843,1.479844,1.464825
89.092,1.484687,1.446122,0.1446122,0,0,0,0,0,1.484687,1.484687,1.484687,1.474634
89.39201,1.490156,1.458184,0.1458184,0,0,0,0,0,1.490156,1.490156,1.490156,1.486934
89.692,1.495,1.462087,0.1462087,0,0,0,0,0,1.495,1.495,1.495,1.490914
89.99201,1.5,1.461747,0.1461747,0,0,0,0,0,1.5,1.5,1.5,1.490567
90.29201,1.504844,1.460967,0.1460967,0,0,0,0,0,1.504844,1.504844,1.504844,1.489771
90.592,1.509687,1.467161,0.1467161,0,0,0,0,0,1.509687,1.509687,1.509687,1.496087
90.89201,1.515,1.476903,0.1476903,0,0,0,0,0,1.515,1.515,1.515,1.506021
91.192,1.52,1.486158,0.1486158,0,0,0,0,0,1.52,1.52,1.52,1.515459
91.49201,1.525,1.49453,0.149453,0,0,0,0,0,1.525,1.525,1.525,1.523997
91.79201,1.529844,1.500855,0.1500855,0,0,0,0,0,1.529844,1.529844,1.529844,1.530446
92.092,1.534844,1.510922,0.1510922,0,0,0,0,0,1.534844,1.534844,1.534844,1.540712
92.39201,1.539844,1.519785,0.1519785,0,0,0,0,0,1.539844,1.539844,1.539844,1.54975
92.692,1.545469,1.530348,0.1530348,0,0,0,0,0,1.545469,1.545469,1.545469,1.56052
92.99201,1.55,1.531006,0.1531006,0,0,0,0,0,1.55,1.55,1.55,1.561192
93.29201,1.554687,1.537648,0.1537648,0,0,0,0,0,1.554687,1.554687,1.554687,1.567965
93.592,1.559687,1.546026,0.1546026,0,0,0,0,0,1.559687,1.559687,1.559687,1.576508
93.89201,1.564687,1.555965,0.1555965,0,0,0,0,0,1.564687,1.564687,1.564687,1.586643
94.192,1.57,1.566843,0.1566843,0,0,0,0,0,1.57,1.57,1.57,1.597735
94.49201,1.575312,1.576196,0.1576196,0,0,0,0,0,1.575312,1.575312,1.575312,1.607273
94.79201,1.580156,1.581741,0.1581742,0,0,0,0,0,1.580156,1.580156,1.580156,1.612927
95.092,1.585156,1.588034,0.1588033,0,0,0,0,0,1.585156,1.585156,1.585156,1.619344
95.39201,1.59,1.595156,0.1595156,0,0,0,0,0,1.59,1.59,1.59,1.626606
95.692,1.594687,1.598211,0.1598211,0,0,0,0,0,1.594687,1.594687,1.594687,1.629722
95.99201,1.599843,1.60647,0.160647,0,0,0,0,0,1.599844,1.599844,1.599843,1.638143
96.29201,1.605,1.616674,0.1616674,0,0,0,0,0,1.605,1.605,1.605,1.648549
96.592,1.610156,1.624745,0.1624745,0,0,0,0,0,1.610156,1.610156,1.610156,1.656779
96.89201,1.614687,1.630002,0.1630002,0,0,0,0,0,1.614687,1.614687,1.614687,1.662139
97.192,1.619844,1.634136,0.1634136,0,0,0,0,0,1.619843,1.619843,1.619844,1.666355
97.49201,1.625156,1.640343,0.1640342,0,0,0,0,0,1.625156,1.625156,1.625156,1.672684
97.79201,1.630469,1.647138,0.1647138,0,0,0,0,0,1.630468,1.630468,1.630469,1.679613
98.092,1.635156,1.65357,0.165357,0,0,0,0,0,1.635156,1.635156,1.635156,1.686172
98.39201,1.64,1.661439,0.1661439,0,0,0,0,0,1.64,1.64,1.64,1.694197
98.692,1.644687,1.667162,0.1667162,0,0,0,0,0,1.644687,1.644687,1.644687,1.700033
98.99201,1.649687,1.675778,0.1675778,0,0,0,0,0,1.649687,1.649687,1.649687,1.708818
99.29201,1.654844,1.685133,0.1685133,0,0,0,0,0,1.654844,1.654844,1.654844,1.718357
99.592,1.660156,1.692289,0.1692289,0,0,0,0,0,1.660156,1.660156,1.660156,1.725655
99.89201,1.665156,1.680434,0.1680434,0,0,0,0,0,1.665156,1.665156,1.665156,1.713565
100.192,1.67,1.683475,0.1683474,0,0,0,0,0,1.67,1.67,1.67,1.716666
100.492,1.674687,1.688054,0.1688054,0,0,0,0,0,1.674687,1.674687,1.674687,1.721336
100.792,1.679687,1.6945,0.16945,0,0,0,0,0,1.679687,1.679687,1.679687,1.727909
101.092,1.685,1.703558,0.1703558,0,0,0,0,0,1.685,1.685,1.685,1.737146
101.392,1.690156,1.713822,0.1713822,0,0,0,0,0,1.690156,1.690156,1.690156,1.747612
101.692,1.695156,1.721385,0.1721385,0,0,0,0,0,1.695156,1.695156,1.695156,1.755324
101.992,1.7,1.729438,0.1729438,0,0,0,0,0,1.7,1.7,1.7,1.763536
102.292,1.704843,1.736172,0.1736172,0,0,0,0,0,1.704844,1.704844,1.704843,1.770403
102.592,1.71,1.739551,0.1739551,0,0,0,0,0,1.71,1.71,1.71,1.773849
102.892,1.715468,1.749904,0.1749904,0,0,0,0,0,1.715469,1.715469,1.715468,1.784405
103.192,1.72,1.755572,0.1755572,0,0,0,0,0,1.72,1.72,1.72,1.790185
103.492,1.724844,1.764007,0.1764007,0,0,0,0,0,1.724844,1.724844,1.724844,1.798786
103.792,1.729687,1.772024,0.1772024,0,0,0,0,0,1.729687,1.729687,1.729687,1.806962
104.092,1.734687,1.779865,0.1779865,0,0,0,0,0,1.734687,1.734687,1.734687,1.814958
104.392,1.74,1.785535,0.1785535,0,0,0,0,0,1.74,1.74,1.74,1.820739
104.692,1.745312,1.791717,0.1791717,0,0,0,0,0,1.745312,1.745312,1.745312,1.827042
104.992,1.750156,1.794272,0.1794272,0,0,0,0,0,1.750156,1.750156,1.750156,1.829648
105.292,1.755156,1.796203,0.1796203,0,0,0,0,0,1.755156,1.755156,1.755156,1.831617
105.592,1.76,1.80162,0.180162,0,0,0,0,0,1.76,1.76,1.76,1.837141
105.892,1.764687,1.800841,0.1800841,0,0,0,0,0,1.764687,1.764687,1.764687,1.836347
106.192,1.769844,1.807747,0.1807747,0,0,0,0,0,1.769843,1.769843,1.769844,1.843389
106.492,1.775156,1.813912,0.1813912,0,0,0,0,0,1.775156,1.775156,1.775156,1.849675
106.792,1.779844,1.819462,0.1819462,0,0,0,0,0,1.779844,1.779844,1.779844,1.855335
107.092,1.784687,1.825268,0.1825268,0,0,0,0,0,1.784687,1.784687,1.784687,1.861255
107.392,1.789844,1.831716,0.1831716,0,0,0,0,0,1.789844,1.789844,1.789844,1.867831
107.692,1.795,1.837607,0.1837607,0,0,0,0,0,1.795,1.795,1.795,1.873838
107.992,1.800312,1.803404,0.1803403,0,0,0,0,0,1.800312,1.800312,1.800312,1.83896
108.292,1.805156,1.772196,0.1772196,0,0,0,0,0,1.805156,1.805156,1.805156,1.807137
108.592,1.809844,1.773403,0.1773403,0,0,0,0,0,1.809844,1.809844,1.809844,1.808368
108.892,1.814687,1.779781,0.1779781,0,0,0,0,0,1.814687,1.814687,1.814687,1.814871
109.192,1.819687,1.788793,0.1788793,0,0,0,0,0,1.819687,1.819687,1.819687,1.824062
109.492,1.824844,1.776496,0.1776496,0,0,0,0,0,1.824844,1.824844,1.824844,1.811522
109.792,1.830312,1.783965,0.1783965,0,0,0,0,0,1.830312,1.830312,1.830312,1.819138
110.092,1.835156,1.789403,0.1789403,0,0,0,0,0,1.835156,1.835156,1.835156,1.824683
110.392,1.84,1.786395,0.1786395,0,0,0,0,0,1.84,1.84,1.84,1.821616
110.692,1.844687,1.786939,0.1786939,0,0,0,0,0,1.844687,1.844687,1.844687,1.82217
110.992,1.849531,1.782985,0.1782985,0,0,0,0,0,1.849531,1.849531,1.849531,1.818139
111.292,1.854844,1.790566,0.1790566,0,0,0,0,0,1.854844,1.854844,1.854844,1.82587
111.592,1.860312,1.798832,0.1798832,0,0,0,0,0,1.860312,1.860312,1.860312,1.834298
111.892,1.865,1.804475,0.1804475,0,0,0,0,0,1.865,1.865,1.865,1.840052
112.192,1.87,1.807448,0.1807448,0,0,0,0,0,1.87,1.87,1.87,1.843084
112.492,1.875,1.81323,0.1813231,0,0,0,0,0,1.875,1.875,1.875,1.848981
112.792,1.88,1.821424,0.1821423,0,0,0,0,0,1.88,1.88,1.88,1.857335
113.092,1.885156,1.830283,0.1830283,0,0,0,0,0,1.885156,1.885156,1.885156,1.866369
113.392,1.889843,1.836921,0.1836921,0,0,0,0,0,1.889843,1.889843,1.889843,1.873138
113.692,1.894844,1.844227,0.1844227,0,0,0,0,0,1.894844,1.894844,1.894844,1.880588
113.992,1.899687,1.85368,0.185368,0,0,0,0,0,1.899687,1.899687,1.899687,1.890227
114.292,1.904843,1.863349,0.1863349,0,0,0,0,0,1.904843,1.904843,1.904843,1.900087
114.592,1.91,1.873237,0.1873237,0,0,0,0,0,1.91,1.91,1.91,1.91017
114.892,1.915468,1.882994,0.1882994,0,0,0,0,0,1.915468,1.915468,1.915468,1.92012
115.192,1.920312,1.888974,0.1888974,0,0,0,0,0,1.920312,1.920312,1.920312,1.926217
115.492,1.925,1.896164,0.1896164,0,0,0,0,0,1.925,1.925,1.925,1.93355
115.792,1.929531,1.901283,0.1901284,0,0,0,0,0,1.929531,1.929531,1.929531,1.93877
116.092,1.934687,1.910595,0.1910595,0,0,0,0,0,1.934687,1.934687,1.934687,1.948265
116.392,1.939844,1.920174,0.1920174,0,0,0,0,0,1.939844,1.939844,1.939844,1.958033
116.692,1.945312,1.918565,0.1918565,0,0,0,0,0,1.945312,1.945312,1.945312,1.956392
116.992,1.95,1.928097,0.1928097,0,0,0,0,0,1.95,1.95,1.95,1.966112
117.292,1.955,1.937823,0.1937823,0,0,0,0,0,1.955,1.955,1.955,1.976029
117.592,1.959843,1.946193,0.1946193,0,0,0,0,0,1.959843,1.959843,1.959843,1.984564
117.892,1.965156,1.95565,0.195565,0,0,0,0,0,1.965156,1.965156,1.965156,1.994208
118.192,1.970156,1.964199,0.1964199,0,0,0,0,0,1.970156,1.970156,1.970156,2.002926
118.492,1.975156,1.973369,0.1973369,0,0,0,0,0,1.975156,1.975156,1.975156,2.012276
118.792,1.980156,1.981573,0.1981573,0,0,0,0,0,1.980156,1.980156,1.980156,2.020642
119.092,1.984843,1.98766,0.198766,0,0,0,0,0,1.984843,1.984843,1.984843,2.026849
119.392,1.989843,1.994415,0.1994415,0,0,0,0,0,1.989843,1.989843,1.989843,2.033737
119.692,1.995,1.95154,0.195154,0,0,0,0,0,1.995,1.995,1.995,1.990017
119.992,2.000312,2.002681,0.2002681,0,0,0,0,0,2.000312,2.000312,2.000312,2.042166
120.292,2.005312,1.956727,0.1956727,0,0,0,0,0,2.005312,2.005312,2.005312,1.995306
120.592,2.009843,1.917288,0.1917288,0,0,0,0,0,2.009843,2.009843,2.009843,1.955089
120.892,2.014687,1.991377,0.1991377,0,0,0,0,0,2.014687,2.014687,2.014687,2.030639
121.192,2.019843,2.018661,0.2018661,0,0,0,0,0,2.019843,2.019843,2.019843,2.058461
121.492,2.025156,2.022954,0.2022954,0,0,0,0,0,2.025156,2.025156,2.025156,2.062839
121.792,2.030312,2.029047,0.2029047,0,0,0,0,0,2.030312,2.030312,2.030312,2.069052
122.092,2.035156,2.037649,0.2037649,0,0,0,0,0,2.035156,2.035156,2.035156,2.077824
122.392,2.04,2.045424,0.2045424,0,0,0,0,0,2.04,2.04,2.04,2.085752
122.692,2.045,2.053726,0.2053726,0,0,0,0,0,2.045,2.045,2.045,2.094217
122.992,2.049843,2.06151,0.2061509,0,0,0,0,0,2.049843,2.049843,2.049843,2.102155
123.292,2.055,2.071446,0.2071446,0,0,0,0,0,2.055,2.055,2.055,2.112287
123.592,2.060156,2.080524,0.2080524,0,0,0,0,0,2.060156,2.060156,2.060156,2.121544
123.892,2.064843,2.087032,0.2087032,0,0,0,0,0,2.064843,2.064843,2.064843,2.128181
124.192,2.069687,2.093195,0.2093195,0,0,0,0,0,2.069687,2.069687,2.069687,2.134465
124.492,2.074687,2.096542,0.2096542,0,0,0,0,0,2.074687,2.074687,2.074687,2.137877
124.792,2.08,2.105005,0.2105005,0,0,0,0,0,2.079999,2.079999,2.08,2.146508
125.092,2.085624,2.115267,0.2115267,0,0,0,0,0,2.085624,2.085624,2.085624,2.156972
125.392,2.090156,2.113291,0.2113291,0,0,0,0,0,2.090156,2.090156,2.090156,2.154957
125.692,2.095,2.116053,0.2116053,0,0,0,0,0,2.095,2.095,2.095,2.157773
125.992,2.099687,2.120936,0.2120936,0,0,0,0,0,2.099687,2.099687,2.099687,2.162753
126.292,2.104843,2.129776,0.2129776,0,0,0,0,0,2.104843,2.104843,2.104843,2.171767
126.592,2.109843,2.134652,0.2134652,0,0,0,0,0,2.109843,2.109843,2.109843,2.176739
126.892,2.115156,2.143658,0.2143658,0,0,0,0,0,2.115156,2.115156,2.115156,2.185923
127.192,2.12,2.148422,0.2148422,0,0,0,0,0,2.12,2.12,2.12,2.190781
127.492,2.125,2.152967,0.2152967,0,0,0,0,0,2.125,2.125,2.125,2.195415
127.792,2.129843,2.158139,0.2158139,0,0,0,0,0,2.129843,2.129843,2.129843,2.20069
128.092,2.134687,2.164582,0.2164582,0,0,0,0,0,2.134687,2.134687,2.134687,2.207259
128.392,2.140156,2.176093,0.2176093,0,0,0,0,0,2.140156,2.140156,2.140156,2.218997
128.692,2.145,2.17969,0.217969,0,0,0,0,0,2.145,2.145,2.145,2.222666
128.992,2.15,2.186546,0.2186546,0,0,0,0,0,2.15,2.15,2.15,2.229656
129.292,2.154843,2.19117,0.219117,0,0,0,0,0,2.154843,2.154843,2.154843,2.234371
129.592,2.159687,2.195545,0.2195545,0,0,0,0,0,2.159687,2.159687,2.159687,2.238832
129.892,2.164843,2.202232,0.2202232,0,0,0,0,0,2.164843,2.164843,2.164843,2.245652
130.192,2.170312,2.210321,0.2210321,0,0,0,0,0,2.170312,2.170312,2.170312,2.2539
130.492,2.175,2.20975,0.220975,0,0,0,0,0,2.174999,2.174999,2.175,2.253318
130.792,2.179843,2.203165,0.2203165,0,0,0,0,0,2.179843,2.179843,2.179843,2.246603
131.092,2.184687,2.195118,0.2195118,0,0,0,0,0,2.184687,2.184687,2.184687,2.238397
131.392,2.189843,2.200215,0.2200215,0,0,0,0,0,2.189843,2.189843,2.189843,2.243594
131.692,2.194999,2.206321,0.2206321,0,0,0,0,0,2.194999,2.194999,2.194999,2.249821
131.992,2.200312,2.207625,0.2207625,0,0,0,0,0,2.200312,2.200312,2.200312,2.251151
132.292,2.205156,2.205755,0.2205755,0,0,0,0,0,2.205156,2.205156,2.205156,2.249244
132.592,2.210156,2.210317,0.2210317,0,0,0,0,0,2.210156,2.210156,2.210156,2.253896
132.892,2.215,2.214297,0.2214297,0,0,0,0,0,2.215,2.215,2.215,2.257954
133.192,2.219687,2.217969,0.2217969,0,0,0,0,0,2.219687,2.219687,2.219687,2.261699
133.492,2.224999,2.226037,0.2226037,0,0,0,0,0,2.224999,2.224999,2.224999,2.269926
133.792,2.230156,2.232473,0.2232473,0,0,0,0,0,2.230156,2.230156,2.230156,2.276489
134.092,2.235156,2.238784,0.2238784,0,0,0,0,0,2.235156,2.235156,2.235156,2.282924
134.392,2.239687,2.242452,0.2242452,0,0,0,0,0,2.239687,2.239687,2.239687,2.286665
134.692,2.244843,2.249093,0.2249093,0,0,0,0,0,2.244843,2.244843,2.244843,2.293437
134.992,2.25,2.256228,0.2256228,0,0,0,0,0,2.25,2.25,2.25,2.300713
135.292,2.255625,2.2668,0.22668,0,0,0,0,0,2.255625,2.255625,2.255625,2.311492
135.592,2.26,2.268954,0.2268954,0,0,0,0,0,2.26,2.26,2.26,2.313689
135.892,2.265,2.276585,0.2276585,0,0,0,0,0,2.265,2.265,2.265,2.32147
136.192,2.269843,2.282019,0.2282019,0,0,0,0,0,2.269843,2.269843,2.269843,2.327012
136.492,2.274843,2.275317,0.2275317,0,0,0,0,0,2.274843,2.274843,2.274843,2.320177
136.792,2.279843,2.278926,0.2278926,0,0,0,0,0,2.279843,2.279843,2.279843,2.323858
137.092,2.285312,2.287976,0.2287976,0,0,0,0,0,2.285312,2.285312,2.285312,2.333086
137.392,2.290156,2.288764,0.2288764,0,0,0,0,0,2.290156,2.290156,2.290156,2.33389
137.692,2.295,2.291401,0.2291401,0,0,0,0,0,2.295,2.295,2.295,2.336579
137.992,2.299843,2.294558,0.2294558,0,0,0,0,0,2.299843,2.299843,2.299843,2.339798
138.292,2.304843,2.300517,0.2300517,0,0,0,0,0,2.304843,2.304843,2.304843,2.345874
138.592,2.31,2.308904,0.2308904,0,0,0,0,0,2.31,2.31,2.31,2.354427
138.892,2.315156,2.318665,0.2318665,0,0,0,0,0,2.315156,2.315156,2.315156,2.364381
139.192,2.320156,2.325886,0.2325886,0,0,0,0,0,2.320156,2.320156,2.320156,2.371743
139.492,2.324843,2.330315,0.2330315,0,0,0,0,0,2.324843,2.324843,2.324843,2.376261
139.792,2.329843,2.335829,0.2335829,0,0,0,0,0,2.329843,2.329843,2.329843,2.381883
140.092,2.335,2.342382,0.2342382,0,0,0,0,0,2.335,2.335,2.335,2.388565
140.392,2.340468,2.350031,0.2350031,0,0,0,0,0,2.340468,2.340468,2.340468,2.396364
140.692,2.345,2.353001,0.2353001,0,0,0,0,0,2.345,2.345,2.345,2.399393
140.992,2.349843,2.359126,0.2359126,0,0,0,0,0,2.349843,2.349843,2.349843,2.405639
141.292,2.354687,2.360704,0.2360704,0,0,0,0,0,2.354687,2.354687,2.354687,2.407248
141.592,2.359843,2.365809,0.2365809,0,0,0,0,0,2.359843,2.359843,2.359843,2.412454
141.892,2.365,2.372158,0.2372158,0,0,0,0,0,2.365,2.365,2.365,2.418928
142.192,2.370468,2.382396,0.2382396,0,0,0,0,0,2.370468,2.370468,2.370468,2.429368
142.492,2.375156,2.38571,0.238571,0,0,0,0,0,2.375156,2.375156,2.375156,2.432747
142.792,2.380156,2.390319,0.2390319,0,0,0,0,0,2.380156,2.380156,2.380156,2.437447
143.092,2.385,2.395462,0.2395462,0,0,0,0,0,2.385,2.385,2.385,2.442691
143.392,2.389687,2.40092,0.240092,0,0,0,0,0,2.389687,2.389687,2.389687,2.448257
143.692,2.394843,2.410562,0.2410562,0,0,0,0,0,2.394843,2.394843,2.394843,2.45809
143.992,2.400156,2.420145,0.2420145,0,0,0,0,0,2.400156,2.400156,2.400156,2.467861
144.292,2.404843,2.423324,0.2423324,0,0,0,0,0,2.404843,2.404843,2.404843,2.471103
144.592,2.409687,2.429772,0.2429772,0,0,0,0,0,2.409687,2.409687,2.409687,2.477678
144.892,2.414687,2.429265,0.2429265,0,0,0,0,0,2.414687,2.414687,2.414687,2.47716
145.192,2.420156,2.438385,0.2438385,0,0,0,0,0,2.420156,2.420156,2.420156,2.486461
145.492,2.425312,2.444254,0.2444254,0,0,0,0,0,2.425312,2.425312,2.425312,2.492445
145.792,2.430156,2.446044,0.2446044,0,0,0,0,0,2.430156,2.430156,2.430156,2.494271
146.092,2.434843,2.45012,0.245012,0,0,0,0,0,2.434844,2.434844,2.434843,2.498427
146.392,2.439687,2.455318,0.2455318,0,0,0,0,0,2.439687,2.439687,2.439687,2.503727
146.692,2.444687,2.46331,0.246331,0,0,0,0,0,2.444687,2.444687,2.444687,2.511878
146.992,2.449843,2.472094,0.2472094,0,0,0,0,0,2.449843,2.449843,2.449843,2.520835
147.292,2.455156,2.47754,0.2477539,0,0,0,0,0,2.455156,2.455156,2.455156,2.526387
147.592,2.460156,2.483108,0.2483108,0,0,0,0,0,2.460156,2.460156,2.460156,2.532066
147.892,2.465,2.486585,0.2486585,0,0,0,0,0,2.465,2.465,2.465,2.535611
148.192,2.469687,2.49008,0.249008,0,0,0,0,0,2.469687,2.469687,2.469687,2.539175
148.492,2.474687,2.498882,0.2498882,0,0,0,0,0,2.474687,2.474687,2.474687,2.548151
148.792,2.48,2.509217,0.2509217,0,0,0,0,0,2.48,2.48,2.48,2.558689
149.092,2.485312,2.517783,0.2517783,0,0,0,0,0,2.485312,2.485312,2.485312,2.567424
149.392,2.490156,2.522369,0.2522369,0,0,0,0,0,2.490156,2.490156,2.490156,2.572101
149.692,2.495,2.525265,0.2525265,0,0,0,0,0,2.495,2.495,2.495,2.575054
149.992,2.499843,2.527158,0.2527158,0,0,0,0,0,2.499843,2.499843,2.499843,2.576984
150.292,2.505,2.533511,0.2533511,0,0,0,0,0,2.504999,2.504999,2.505,2.583462
150.592,2.51,2.538072,0.2538072,0,0,0,0,0,2.51,2.51,2.51,2.588113
150.892,2.514843,2.535683,0.2535683,0,0,0,0,0,2.514843,2.514843,2.514843,2.585677
151.192,2.519843,2.528804,0.2528804,0,0,0,0,0,2.519843,2.519843,2.519843,2.578662
151.492,2.524687,2.529981,0.2529981,0,0,0,0,0,2.524687,2.524687,2.524687,2.579863
151.792,2.529843,2.532421,0.2532421,0,0,0,0,0,2.529843,2.529843,2.529843,2.582351
152.092,2.535156,2.536132,0.2536132,0,0,0,0,0,2.535156,2.535156,2.535156,2.586135
152.392,2.540625,2.541517,0.2541518,0,0,0,0,0,2.540625,2.540625,2.540625,2.591627
152.692,2.545312,2.542539,0.2542539,0,0,0,0,0,2.545312,2.545312,2.545312,2.592668
152.992,2.550156,2.544916,0.2544916,0,0,0,0,0,2.550156,2.550156,2.550156,2.595092
153.292,2.554687,2.543082,0.2543083,0,0,0,0,0,2.554687,2.554687,2.554687,2.593222
153.592,2.559687,2.548115,0.2548115,0,0,0,0,0,2.559687,2.559687,2.559687,2.598354
153.892,2.564843,2.555553,0.2555553,0,0,0,0,0,2.564843,2.564843,2.564843,2.605939
154.192,2.57,2.562746,0.2562746,0,0,0,0,0,2.569999,2.569999,2.57,2.613274
154.492,2.574843,2.560827,0.2560827,0,0,0,0,0,2.574843,2.574843,2.574843,2.611317
154.792,2.579843,2.566208,0.2566208,0,0,0,0,0,2.579843,2.579843,2.579843,2.616803
155.092,2.585,2.572085,0.2572085,0,0,0,0,0,2.585,2.585,2.585,2.622797
155.392,2.590312,2.571014,0.2571014,0,0,0,0,0,2.590312,2.590312,2.590312,2.621705
155.692,2.595156,2.575077,0.2575077,0,0,0,0,0,2.595156,2.595156,2.595156,2.625848
155.992,2.600156,2.581345,0.2581345,0,0,0,0,0,2.600156,2.600156,2.600156,2.632239
156.292,2.605156,2.587656,0.2587656,0,0,0,0,0,2.605156,2.605156,2.605156,2.638675
156.592,2.609843,2.592523,0.2592523,0,0,0,0,0,2.609843,2.609843,2.609843,2.643638
156.892,2.614687,2.599315,0.2599314,0,0,0,0,0,2.614687,2.614687,2.614687,2.650563
157.192,2.619843,2.606788,0.2606788,0,0,0,0,0,2.619843,2.619843,2.619843,2.658184
157.492,2.625312,2.617162,0.2617162,0,0,0,0,0,2.625312,2.625312,2.625312,2.668763
157.792,2.630312,2.619544,0.2619544,0,0,0,0,0,2.630312,2.630312,2.630312,2.671191
158.092,2.634843,2.621205,0.2621205,0,0,0,0,0,2.634843,2.634843,2.634843,2.672885
158.392,2.639687,2.625702,0.2625702,0,0,0,0,0,2.639687,2.639687,2.639687,2.677471
158.692,2.644687,2.632841,0.2632841,0,0,0,0,0,2.644687,2.644687,2.644687,2.684751
158.992,2.650156,2.642799,0.2642799,0,0,0,0,0,2.650156,2.650156,2.650156,2.694905
159.292,2.655312,2.649351,0.2649351,0,0,0,0,0,2.655312,2.655312,2.655312,2.701586
159.592,2.660156,2.652601,0.2652601,0,0,0,0,0,2.660156,2.660156,2.660156,2.7049
159.892,2.665,2.655885,0.2655885,0,0,0,0,0,2.664999,2.664999,2.665,2.708249
160.192,2.67,2.658555,0.2658555,0,0,0,0,0,2.67,2.67,2.67,2.710972
160.492,2.675,2.658513,0.2658513,0,0,0,0,0,2.675,2.675,2.675,2.710929
160.792,2.679843,2.663772,0.2663772,0,0,0,0,0,2.679843,2.679843,2.679843,2.716291
161.092,2.685156,2.671306,0.2671306,0,0,0,0,0,2.685156,2.685156,2.685156,2.723974
161.392,2.689843,2.6741,0.26741,0,0,0,0,0,2.689843,2.689843,2.689843,2.726824
161.692,2.694687,2.678164,0.2678164,0,0,0,0,0,2.694687,2.694687,2.694687,2.730967
161.992,2.699687,2.681397,0.2681397,0,0,0,0,0,2.699687,2.699687,2.699687,2.734264
162.292,2.705,2.68786,0.268786,0,0,0,0,0,2.705,2.705,2.705,2.740855
162.592,2.710625,2.697225,0.2697225,0,0,0,0,0,2.710625,2.710625,2.710625,2.750404
162.892,2.715156,2.697036,0.2697036,0,0,0,0,0,2.715156,2.715156,2.715156,2.750212
163.192,2.72,2.696777,0.2696777,0,0,0,0,0,2.72,2.72,2.72,2.749947
163.492,2.724687,2.700273,0.2700273,0,0,0,0,0,2.724687,2.724687,2.724687,2.753512
163.792,2.729843,2.708598,0.2708598,0,0,0,0,0,2.729843,2.729843,2.729843,2.762001
164.092,2.734843,2.715588,0.2715588,0,0,0,0,0,2.734843,2.734843,2.734843,2.76913
164.392,2.740156,2.72588,0.272588,0,0,0,0,0,2.740156,2.740156,2.740156,2.779624
164.692,2.744843,2.730857,0.2730857,0,0,0,0,0,2.744843,2.744843,2.744843,2.784699
164.992,2.749843,2.736445,0.2736445,0,0,0,0,0,2.749843,2.749843,2.749843,2.790397
165.292,2.754843,2.74326,0.274326,0,0,0,0,0,2.754843,2.754843,2.754843,2.797347
165.592,2.759687,2.749412,0.2749412,0,0,0,0,0,2.759687,2.759687,2.759687,2.80362
165.892,2.765,2.758203,0.2758203,0,0,0,0,0,2.765,2.765,2.765,2.812584
166.192,2.77,2.763222,0.2763222,0,0,0,0,0,2.77,2.77,2.77,2.817702
166.492,2.775156,2.766519,0.2766519,0,0,0,0,0,2.775156,2.775156,2.775156,2.821064
166.792,2.779843,2.765162,0.2765162,0,0,0,0,0,2.779843,2.779843,2.779843,2.819681
167.092,2.784687,2.768695,0.2768695,0,0,0,0,0,2.784687,2.784687,2.784687,2.823283
167.392,2.789843,2.774675,0.2774675,0,0,0,0,0,2.789843,2.789843,2.789843,2.829381
167.692,2.795312,2.781283,0.2781284,0,0,0,0,0,2.795312,2.795312,2.795312,2.83612
167.992,2.8,2.780756,0.2780756,0,0,0,0,0,2.8,2.8,2.8,2.835582
168.292,2.804687,2.783346,0.2783346,0,0,0,0,0,2.804687,2.804687,2.804687,2.838223
168.592,2.809687,2.788788,0.2788788,0,0,0,0,0,2.809687,2.809687,2.809687,2.843772
168.892,2.814687,2.794592,0.2794592,0,0,0,0,0,2.814687,2.814687,2.814687,2.849691
169.192,2.82,2.802432,0.2802432,0,0,0,0,0,2.82,2.82,2.82,2.857685
169.492,2.825312,2.809465,0.2809465,0,0,0,0,0,2.825312,2.825312,2.825312,2.864857
169.792,2.830156,2.811551,0.281155,0,0,0,0,0,2.830156,2.830156,2.830156,2.866984
170.092,2.835156,2.815442,0.2815441,0,0,0,0,0,2.835156,2.835156,2.835156,2.870951
170.392,2.840156,2.815771,0.2815771,0,0,0,0,0,2.840156,2.840156,2.840156,2.871287
170.692,2.844687,2.815613,0.2815613,0,0,0,0,0,2.844687,2.844687,2.844687,2.871126
170.992,2.849843,2.820657,0.2820657,0,0,0,0,0,2.849843,2.849843,2.849843,2.87627
171.216,2.85375,2.823362,0.2823362,0,0,0,0,0,2.85375,2.85375,2.85375,2.879029