File: dataFiles/staticInstron_3.raw
"Test Type","Tension"
"Method Name","C:\Users\mmen339\Documents\tension test 1mm_s.im_tens"
"Sample name","C:\Users\mmen339\Documents\sample 3\S3.20%Extension.is_tens"
"User",""
"Sample note 1",""
"Sample note 2",""
"Sample note 3",""
"Geometry","Rectangular"
"Specimen",1
"Specimen label",""
"Width",10.000000,"mm"
"Thickness",1.000000,"mm"
"Length",100.000000,"mm"
"Diameter",10.000000,"mm"
"Inner diameter",8.000000,"mm"
"Outer diameter",10.000000,"mm"
"Wall thickness",1.000000,"mm"
"Area",0.100000,"cm^2"
"Linear density",100.000000,"tex"
"Sled weight",10.000000,"N"
"Loading span",10.000000,"mm"
"Support span",100.000000,"mm"
"Span ratio","2"
"Fixture type","4-point"
"Included"
"Final width",10.000000,"mm"
"Final thickness",1.000000,"mm"
"Final length",100.000000,"mm"
"Final diameter",10.000000,"mm"
"Final Inner diameter",8.000000,"mm"
"Final outer diameter",10.000000,"mm"
"Final wall thickness",1.000000,"mm"
"Final area",0.100000,"cm^2"
"Final linear density",100.000000,"tex"
"Custom text input  1",""
"Custom text input  2",""
"Custom text input  3",""
"Custom text input  4",""
"Custom text input  5",""
"Custom text input  6",""
"Custom text input  7",""
"Custom text input  8",""
"Custom text input  9",""
"Custom text input 10",""
"Custom text input 11",""
"Custom text input 12",""
"Custom text input 13",""
"Custom text input 14",""
"Custom text input 15",""
"Custom text input 16",""
"Custom text input 17",""
"Custom text input 18",""
"Custom text input 19",""
"Custom text input 20",""
"Custom text input 21",""
"Custom text input 22",""
"Custom text input 23",""
"Custom text input 24",""
"Custom text input 25",""
"Custom text input 26",""
"Custom text input 27",""
"Custom text input 28",""
"Custom text input 29",""
"Custom text input 30",""
"Custom text input 31",""
"Custom text input 32",""
"Custom text input 33",""
"Custom text input 34",""
"Custom text input 35",""
"Custom text input 36",""
"Custom text input 37",""
"Custom text input 38",""
"Custom text input 39",""
"Custom text input 40",""
"Custom text input 41",""
"Custom text input 42",""
"Custom text input 43",""
"Custom text input 44",""
"Custom text input 45",""
"Custom text input 46",""
"Custom text input 47",""
"Custom text input 48",""
"Custom text input 49",""
"Custom text input 50",""
"Custom number input  1",0.000000,""
"Custom number input  2",0.000000,""
"Custom number input  3",0.000000,""
"Custom number input  4",0.000000,""
"Custom number input  5",0.000000,""
"Custom number input  6",0.000000,""
"Custom number input  7",0.000000,""
"Custom number input  8",0.000000,""
"Custom number input  9",0.000000,""
"Custom number input 10",0.000000,""
"Time sec","Extension mm","Load N","Tensile stress MPa","Cycle Count ","Total Cycle Count ","Repetitions Count ","Marked Data ","PIP Count ","Tensile extension mm","Tensile strain %","Corrected Position mm","Tenacity gf/tex"
0,0.00015625,0.01393545,0.001393545,0,0,0,0,0,0.00015625,0.00015625,0.00015625,0.0142102
0.2,0.0015625,0.06047568,0.006047567,0,0,0,0,0,0.0015625,0.0015625,0.0015625,0.06166803
0.4,0.006249999,0.2499409,0.02499409,0,0,0,0,0,0.006249999,0.006249999,0.006249999,0.2548688
0.6,0.009843749,0.3837861,0.03837861,0,0,0,0,0,0.009843749,0.009843749,0.009843749,0.3913529
0.8,0.01328125,0.4966395,0.04966395,0,0,0,0,0,0.01328125,0.01328125,0.01328125,0.5064313
1,0.01640625,0.5981701,0.05981702,0,0,0,0,0,0.01640625,0.01640625,0.01640625,0.6099638
1.2,0.01984375,0.6957315,0.06957316,0,0,0,0,0,0.01984375,0.01984375,0.01984375,0.7094488
1.4,0.02296875,0.7862542,0.07862542,0,0,0,0,0,0.02296875,0.02296875,0.02296875,0.8017561
1.6,0.02625,0.874989,0.0874989,0,0,0,0,0,0.02625,0.02625,0.02625,0.8922405
1.8,0.0296875,0.9626069,0.09626069,0,0,0,0,0,0.0296875,0.0296875,0.0296875,0.9815859
2,0.03312499,1.050748,0.1050748,0,0,0,0,0,0.03312499,0.03312499,0.03312499,1.071465
2.2,0.03671874,1.136153,0.1136153,0,0,0,0,0,0.03671874,0.03671874,0.03671874,1.158554
2.4,0.04046875,1.222552,0.1222552,0,0,0,0,0,0.04046874,0.04046874,0.04046875,1.246656
2.6,0.04359374,1.28593,0.128593,0,0,0,0,0,0.04359374,0.04359374,0.04359374,1.311283
2.8,0.04687499,1.353193,0.1353193,0,0,0,0,0,0.04687499,0.04687499,0.04687499,1.379873
3,0.05,1.411537,0.1411537,0,0,0,0,0,0.04999999,0.04999999,0.05,1.439367
3.2,0.05296874,1.470401,0.1470401,0,0,0,0,0,0.05296874,0.05296874,0.05296874,1.499392
3.4,0.05624999,1.5334,0.15334,0,0,0,0,0,0.05624999,0.05624999,0.05624999,1.563633
3.6,0.05968749,1.598025,0.1598026,0,0,0,0,0,0.05968749,0.05968749,0.05968749,1.629532
3.8,0.06296873,1.65792,0.165792,0,0,0,0,0,0.06296874,0.06296874,0.06296873,1.690607
4,0.06640624,1.718253,0.1718253,0,0,0,0,0,0.06640624,0.06640624,0.06640624,1.75213
4.2,0.06999999,1.778809,0.1778809,0,0,0,0,0,0.06999999,0.06999999,0.06999999,1.81388
4.4,0.07328124,1.831985,0.1831985,0,0,0,0,0,0.07328124,0.07328124,0.07328124,1.868105
4.6,0.07656249,1.881507,0.1881507,0,0,0,0,0,0.07656249,0.07656249,0.07656249,1.918603
4.8,0.07984374,1.931151,0.1931151,0,0,0,0,0,0.07984374,0.07984374,0.07984374,1.969226
5,0.08312499,1.978522,0.1978522,0,0,0,0,0,0.08312499,0.08312499,0.08312499,2.017531
5.2,0.08640624,2.022117,0.2022117,0,0,0,0,0,0.08640624,0.08640624,0.08640624,2.061985
5.4,0.08984374,2.069741,0.2069741,0,0,0,0,0,0.08984374,0.08984374,0.08984374,2.110548
5.6,0.09312499,2.113901,0.2113901,0,0,0,0,0,0.09312499,0.09312499,0.09312499,2.155579
5.8,0.09671874,2.162819,0.2162819,0,0,0,0,0,0.09671874,0.09671874,0.09671874,2.205461
6,0.1001562,2.204017,0.2204017,0,0,0,0,0,0.1001562,0.1001562,0.1001562,2.247472
6.2,0.1034375,2.247925,0.2247925,0,0,0,0,0,0.1034375,0.1034375,0.1034375,2.292246
6.4,0.1065625,2.282607,0.2282607,0,0,0,0,0,0.1065625,0.1065625,0.1065625,2.327612
6.6,0.1098437,2.320716,0.2320716,0,0,0,0,0,0.1098437,0.1098437,0.1098437,2.366472
6.8,0.113125,2.357989,0.2357989,0,0,0,0,0,0.113125,0.113125,0.113125,2.40448
7,0.1164062,2.395202,0.2395202,0,0,0,0,0,0.1164062,0.1164062,0.1164062,2.442426
7.2,0.1198437,2.433383,0.2433383,0,0,0,0,0,0.1198437,0.1198437,0.1198437,2.48136
7.4,0.1235937,2.471528,0.2471528,0,0,0,0,0,0.1235937,0.1235937,0.1235937,2.520257
7.6,0.1270312,2.505654,0.2505654,0,0,0,0,0,0.1270312,0.1270312,0.1270312,2.555057
7.8,0.1301562,2.533794,0.2533794,0,0,0,0,0,0.1301562,0.1301562,0.1301562,2.583751
8,0.1332812,2.563956,0.2563956,0,0,0,0,0,0.1332812,0.1332812,0.1332812,2.614507
8.200001,0.13625,2.588568,0.2588568,0,0,0,0,0,0.13625,0.13625,0.13625,2.639605
8.400001,0.1395312,2.617965,0.2617965,0,0,0,0,0,0.1395312,0.1395312,0.1395312,2.669582
8.6,0.1428125,2.649082,0.2649083,0,0,0,0,0,0.1428125,0.1428125,0.1428125,2.701312
8.8,0.1464062,2.680496,0.2680496,0,0,0,0,0,0.1464062,0.1464062,0.1464062,2.733345
9,0.1498437,2.709664,0.2709664,0,0,0,0,0,0.1498437,0.1498437,0.1498437,2.763088
9.200001,0.1534375,2.738751,0.2738751,0,0,0,0,0,0.1534375,0.1534375,0.1534375,2.792749
9.400001,0.156875,2.765714,0.2765714,0,0,0,0,0,0.156875,0.156875,0.156875,2.820243
9.6,0.1601562,2.789168,0.2789168,0,0,0,0,0,0.1601562,0.1601562,0.1601562,2.84416
9.8,0.1634375,2.80719,0.280719,0,0,0,0,0,0.1634375,0.1634375,0.1634375,2.862537
10,0.1667187,2.827572,0.2827572,0,0,0,0,0,0.1667187,0.1667187,0.1667187,2.883321
10.2,0.1698437,2.847965,0.2847965,0,0,0,0,0,0.1698437,0.1698437,0.1698437,2.904116
10.4,0.173125,2.868596,0.2868596,0,0,0,0,0,0.173125,0.173125,0.173125,2.925154
10.6,0.1764062,2.890125,0.2890125,0,0,0,0,0,0.1764062,0.1764062,0.1764062,2.947107
10.8,0.1798437,2.912326,0.2912326,0,0,0,0,0,0.1798437,0.1798437,0.1798437,2.969746
11,0.1832812,2.93564,0.293564,0,0,0,0,0,0.1832812,0.1832812,0.1832812,2.99352
11.2,0.1865625,2.954724,0.2954724,0,0,0,0,0,0.1865625,0.1865625,0.1865625,3.01298
11.4,0.1898437,2.974173,0.2974173,0,0,0,0,0,0.1898437,0.1898437,0.1898437,3.032813
11.6,0.193125,2.992641,0.2992641,0,0,0,0,0,0.193125,0.193125,0.193125,3.051644
11.8,0.1964062,3.011644,0.3011644,0,0,0,0,0,0.1964062,0.1964062,0.1964062,3.071023
12,0.1996875,3.030267,0.3030267,0,0,0,0,0,0.1996875,0.1996875,0.1996875,3.090013
12.2,0.2032812,3.048904,0.3048904,0,0,0,0,0,0.2032812,0.2032812,0.2032812,3.109017
12.4,0.206875,3.068841,0.3068841,0,0,0,0,0,0.206875,0.206875,0.206875,3.129347
12.6,0.2104687,3.087094,0.3087094,0,0,0,0,0,0.2104687,0.2104687,0.2104687,3.147959
12.8,0.21375,3.101442,0.3101442,0,0,0,0,0,0.21375,0.21375,0.21375,3.162591
13,0.216875,3.115007,0.3115007,0,0,0,0,0,0.216875,0.216875,0.216875,3.176423
13.2,0.22,3.129767,0.3129767,0,0,0,0,0,0.22,0.22,0.22,3.191474
13.4,0.223125,3.143267,0.3143267,0,0,0,0,0,0.223125,0.223125,0.223125,3.205241
13.6,0.2264062,3.159414,0.3159414,0,0,0,0,0,0.2264062,0.2264062,0.2264062,3.221706
13.8,0.2298437,3.17609,0.317609,0,0,0,0,0,0.2298437,0.2298437,0.2298437,3.238711
14,0.2332812,3.192937,0.3192937,0,0,0,0,0,0.2332812,0.2332812,0.2332812,3.25589
14.2,0.2365625,3.207232,0.3207232,0,0,0,0,0,0.2365625,0.2365625,0.2365625,3.270466
14.4,0.2403125,3.224686,0.3224686,0,0,0,0,0,0.2403125,0.2403125,0.2403125,3.288265
14.6,0.2434375,3.235836,0.3235836,0,0,0,0,0,0.2434375,0.2434375,0.2434375,3.299634
14.8,0.246875,3.249998,0.3249998,0,0,0,0,0,0.246875,0.246875,0.246875,3.314076
15,0.25,3.262644,0.3262644,0,0,0,0,0,0.25,0.25,0.25,3.326971
15.2,0.2532812,3.274721,0.3274721,0,0,0,0,0,0.2532812,0.2532812,0.2532812,3.339286
15.4,0.2565625,3.281562,0.3281562,0,0,0,0,0,0.2565625,0.2565625,0.2565625,3.346262
15.6,0.2598437,3.294444,0.3294444,0,0,0,0,0,0.2598437,0.2598437,0.2598437,3.359398
15.8,0.2632812,3.309038,0.3309038,0,0,0,0,0,0.2632812,0.2632812,0.2632812,3.374279
16,0.2668749,3.324145,0.3324145,0,0,0,0,0,0.2668749,0.2668749,0.2668749,3.389685
16.2,0.2701562,3.336049,0.3336049,0,0,0,0,0,0.2701562,0.2701562,0.2701562,3.401824
16.4,0.2734374,3.343027,0.3343027,0,0,0,0,0,0.2734374,0.2734374,0.2734374,3.408939
16.6,0.2767187,3.341113,0.3341113,0,0,0,0,0,0.2767187,0.2767187,0.2767187,3.406987
16.8,0.2799999,3.349872,0.3349872,0,0,0,0,0,0.2799999,0.2799999,0.2799999,3.415919
17,0.2831249,3.36082,0.336082,0,0,0,0,0,0.283125,0.283125,0.2831249,3.427083
17.2,0.2865625,3.37301,0.337301,0,0,0,0,0,0.2865624,0.2865624,0.2865625,3.439513
17.4,0.2898437,3.385439,0.3385439,0,0,0,0,0,0.2898437,0.2898437,0.2898437,3.452187
17.6,0.2935937,3.398539,0.3398539,0,0,0,0,0,0.2935937,0.2935937,0.2935937,3.465545
17.8,0.2970312,3.407216,0.3407216,0,0,0,0,0,0.2970312,0.2970312,0.2970312,3.474393
18,0.3001562,3.418228,0.3418228,0,0,0,0,0,0.3001562,0.3001562,0.3001562,3.485622
18.2,0.3032812,3.425588,0.3425589,0,0,0,0,0,0.3032812,0.3032812,0.3032812,3.493128
18.4,0.3064062,3.433583,0.3433582,0,0,0,0,0,0.3064062,0.3064062,0.3064062,3.50128
18.6,0.3096875,3.445622,0.3445622,0,0,0,0,0,0.3096875,0.3096875,0.3096875,3.513557
18.8,0.3131249,3.454415,0.3454415,0,0,0,0,0,0.3131249,0.3131249,0.3131249,3.522523
19,0.3165625,3.462528,0.3462529,0,0,0,0,0,0.3165624,0.3165624,0.3165625,3.530796
19.2,0.32,3.470669,0.3470669,0,0,0,0,0,0.32,0.32,0.32,3.539097
19.4,0.32375,3.482887,0.3482887,0,0,0,0,0,0.32375,0.32375,0.32375,3.551556
19.6,0.3270312,3.491069,0.3491069,0,0,0,0,0,0.3270312,0.3270312,0.3270312,3.5599
19.8,0.3301562,3.495201,0.3495201,0,0,0,0,0,0.3301562,0.3301562,0.3301562,3.564114
20,0.3334374,3.495384,0.3495384,0,0,0,0,0,0.3334374,0.3334374,0.3334374,3.5643
20.2,0.3367187,3.486228,0.3486228,0,0,0,0,0,0.3367187,0.3367187,0.3367187,3.554963
20.4,0.3398437,3.491912,0.3491912,0,0,0,0,0,0.3398437,0.3398437,0.3398437,3.56076
20.6,0.3429687,3.502014,0.3502014,0,0,0,0,0,0.3429687,0.3429687,0.3429687,3.57106
20.8,0.3464062,3.51379,0.3513789,0,0,0,0,0,0.3464062,0.3464062,0.3464062,3.583068
21,0.35,3.525618,0.3525618,0,0,0,0,0,0.35,0.35,0.35,3.59513
21.2,0.3534374,3.534331,0.3534331,0,0,0,0,0,0.3534375,0.3534375,0.3534374,3.604014
21.4,0.3567187,3.543449,0.3543449,0,0,0,0,0,0.3567187,0.3567187,0.3567187,3.613312
21.6,0.3598437,3.551698,0.3551698,0,0,0,0,0,0.3598437,0.3598437,0.3598437,3.621724
21.8,0.3631249,3.553046,0.3553046,0,0,0,0,0,0.3631249,0.3631249,0.3631249,3.623099
22,0.3664062,3.563229,0.3563229,0,0,0,0,0,0.3664062,0.3664062,0.3664062,3.633482
22.2,0.3698437,3.567642,0.3567642,0,0,0,0,0,0.3698437,0.3698437,0.3698437,3.637982
22.4,0.3732812,3.573864,0.3573864,0,0,0,0,0,0.3732812,0.3732812,0.3732812,3.644327
22.6,0.376875,3.585699,0.3585699,0,0,0,0,0,0.376875,0.376875,0.376875,3.656396
22.8,0.3803124,3.595291,0.3595291,0,0,0,0,0,0.3803124,0.3803124,0.3803124,3.666177
23,0.38375,3.57189,0.357189,0,0,0,0,0,0.38375,0.38375,0.38375,3.642314
23.2,0.3865625,3.570844,0.3570844,0,0,0,0,0,0.3865625,0.3865625,0.3865625,3.641248
23.4,0.3896875,3.565543,0.3565543,0,0,0,0,0,0.3896874,0.3896874,0.3896875,3.635842
23.6,0.3931249,3.579068,0.3579068,0,0,0,0,0,0.3931249,0.3931249,0.3931249,3.649633
23.8,0.3964062,3.590987,0.3590986,0,0,0,0,0,0.3964062,0.3964062,0.3964062,3.661787
24,0.3996874,3.604062,0.3604062,0,0,0,0,0,0.3996874,0.3996874,0.3996874,3.67512
24.2,0.403125,3.616349,0.3616349,0,0,0,0,0,0.403125,0.403125,0.403125,3.68765
24.4,0.4067187,3.62983,0.362983,0,0,0,0,0,0.4067187,0.4067187,0.4067187,3.701396
24.6,0.4103124,3.642504,0.3642504,0,0,0,0,0,0.4103124,0.4103124,0.4103124,3.71432
24.8,0.4135937,3.652334,0.3652334,0,0,0,0,0,0.4135937,0.4135937,0.4135937,3.724344
25,0.4168749,3.649377,0.3649378,0,0,0,0,0,0.4168749,0.4168749,0.4168749,3.721329
25.14,0.4190624,3.518711,0.3518711,0,0,0,0,0,0.4190624,0.4190624,0.4190624,3.588086
25.34,0.4221874,3.529334,0.3529334,0,0,0,0,0,0.4221874,0.4221874,0.4221874,3.59892
25.54,0.4253124,3.539483,0.3539483,0,0,0,0,0,0.4253124,0.4253124,0.4253124,3.609268
25.74,0.4285937,3.549559,0.3549559,0,0,0,0,0,0.4285937,0.4285937,0.4285937,3.619543
25.94,0.4321875,3.555525,0.3555525,0,0,0,0,0,0.4321875,0.4321875,0.4321875,3.625627
26.14,0.4357812,3.564652,0.3564653,0,0,0,0,0,0.4357812,0.4357812,0.4357812,3.634934
26.34,0.4392187,3.575546,0.3575546,0,0,0,0,0,0.4392187,0.4392187,0.4392187,3.646043
26.54,0.4424999,3.585771,0.3585771,0,0,0,0,0,0.4424999,0.4424999,0.4424999,3.656469
26.74,0.4457812,3.592917,0.3592917,0,0,0,0,0,0.4457812,0.4457812,0.4457812,3.663755
26.94,0.4489062,3.5974,0.35974,0,0,0,0,0,0.4489062,0.4489062,0.4489062,3.668327
27.14,0.4521874,3.566893,0.3566893,0,0,0,0,0,0.4521874,0.4521874,0.4521874,3.637219
27.34,0.4554687,3.573203,0.3573203,0,0,0,0,0,0.4554687,0.4554687,0.4554687,3.643653
27.54,0.4589062,3.582105,0.3582105,0,0,0,0,0,0.4589062,0.4589062,0.4589062,3.652731
27.74,0.4626562,3.593196,0.3593196,0,0,0,0,0,0.4626562,0.4626562,0.4626562,3.66404
27.94,0.4657812,3.597656,0.3597656,0,0,0,0,0,0.4657812,0.4657812,0.4657812,3.668588
28.14,0.4689062,3.606892,0.3606892,0,0,0,0,0,0.4689062,0.4689062,0.4689062,3.678006
28.34,0.4721874,3.599719,0.3599719,0,0,0,0,0,0.4721874,0.4721874,0.4721874,3.670692
28.54,0.4754687,3.606781,0.3606781,0,0,0,0,0,0.4754687,0.4754687,0.4754687,3.677893
28.74,0.4787499,3.613419,0.3613419,0,0,0,0,0,0.47875,0.47875,0.4787499,3.684662
28.94,0.4820312,3.617549,0.3617549,0,0,0,0,0,0.4820312,0.4820312,0.4820312,3.688873
29.14,0.4854687,3.627369,0.3627369,0,0,0,0,0,0.4854687,0.4854687,0.4854687,3.698887
29.34,0.4889062,3.638317,0.3638318,0,0,0,0,0,0.4889062,0.4889062,0.4889062,3.710051
29.54,0.4926561,3.649528,0.3649528,0,0,0,0,0,0.4926561,0.4926561,0.4926561,3.721483
29.74,0.4960936,3.660045,0.3660045,0,0,0,0,0,0.4960937,0.4960937,0.4960936,3.732208
29.94,0.4992186,3.667516,0.3667516,0,0,0,0,0,0.4992186,0.4992186,0.4992186,3.739826
30.14,0.5026562,3.677826,0.3677826,0,0,0,0,0,0.5026562,0.5026562,0.5026562,3.750338
30.34,0.5057812,3.684315,0.3684315,0,0,0,0,0,0.5057812,0.5057812,0.5057812,3.756956
30.54,0.5087499,3.690926,0.3690926,0,0,0,0,0,0.5087499,0.5087499,0.5087499,3.763697
30.74,0.5120311,3.702902,0.3702902,0,0,0,0,0,0.5120311,0.5120311,0.5120311,3.775909
30.94,0.5154687,3.71378,0.371378,0,0,0,0,0,0.5154687,0.5154687,0.5154687,3.787002
31.14,0.5189062,3.724573,0.3724573,0,0,0,0,0,0.5189062,0.5189062,0.5189062,3.798007
31.34,0.5224999,3.711584,0.3711584,0,0,0,0,0,0.5224999,0.5224999,0.5224999,3.784763
31.54,0.5259374,3.692196,0.3692195,0,0,0,0,0,0.5259374,0.5259374,0.5259374,3.764992
31.74,0.5290624,3.698579,0.3698579,0,0,0,0,0,0.5290624,0.5290624,0.5290624,3.771501
31.94,0.5324999,3.7088,0.3708799,0,0,0,0,0,0.5324999,0.5324999,0.5324999,3.781923
32.14,0.5357811,3.718847,0.3718847,0,0,0,0,0,0.5357811,0.5357811,0.5357811,3.792168
32.34,0.5390624,3.728258,0.3728258,0,0,0,0,0,0.5390624,0.5390624,0.5390624,3.801765
32.54,0.5423437,3.738491,0.3738491,0,0,0,0,0,0.5423437,0.5423437,0.5423437,3.8122
32.74,0.5459374,3.739468,0.3739468,0,0,0,0,0,0.5459374,0.5459374,0.5459374,3.813196
32.94,0.5490624,3.734797,0.3734797,0,0,0,0,0,0.5490624,0.5490624,0.5490624,3.808433
33.14,0.5524999,3.695717,0.3695717,0,0,0,0,0,0.5524999,0.5524999,0.5524999,3.768583
33.34,0.5557811,3.706345,0.3706345,0,0,0,0,0,0.5557811,0.5557811,0.5557811,3.77942
33.54,0.5592186,3.72044,0.372044,0,0,0,0,0,0.5592186,0.5592186,0.5592186,3.793793
33.74,0.5621874,3.732243,0.3732243,0,0,0,0,0,0.5621874,0.5621874,0.5621874,3.805829
33.94,0.5654686,3.723406,0.3723406,0,0,0,0,0,0.5654686,0.5654686,0.5654686,3.796817
34.14,0.5687499,3.737161,0.3737161,0,0,0,0,0,0.5687499,0.5687499,0.5687499,3.810843
34.34,0.5721874,3.745225,0.3745225,0,0,0,0,0,0.5721874,0.5721874,0.5721874,3.819067
34.54,0.5756249,3.747635,0.3747635,0,0,0,0,0,0.5756249,0.5756249,0.5756249,3.821524
34.74,0.5792187,3.761856,0.3761856,0,0,0,0,0,0.5792187,0.5792187,0.5792187,3.836025
34.94,0.5826561,3.772765,0.3772765,0,0,0,0,0,0.5826561,0.5826561,0.5826561,3.847149
35.14,0.5859374,3.783664,0.3783664,0,0,0,0,0,0.5859374,0.5859374,0.5859374,3.858264
35.34,0.5889062,3.79224,0.379224,0,0,0,0,0,0.5889062,0.5889062,0.5889062,3.867009
35.54,0.5920312,3.800414,0.3800414,0,0,0,0,0,0.5920312,0.5920312,0.5920312,3.875344
35.74,0.5954686,3.809949,0.3809949,0,0,0,0,0,0.5954686,0.5954686,0.5954686,3.885067
35.94,0.5987499,3.822555,0.3822555,0,0,0,0,0,0.5987499,0.5987499,0.5987499,3.897921
36.14,0.6023436,3.835046,0.3835046,0,0,0,0,0,0.6023436,0.6023436,0.6023436,3.910659
36.34,0.6059374,3.849336,0.3849336,0,0,0,0,0,0.6059374,0.6059374,0.6059374,3.925231
36.54,0.6093749,3.861067,0.3861067,0,0,0,0,0,0.6093749,0.6093749,0.6093749,3.937193
36.74,0.6124999,3.862631,0.3862631,0,0,0,0,0,0.6124999,0.6124999,0.6124999,3.938787
36.94,0.6159374,3.873976,0.3873976,0,0,0,0,0,0.6159374,0.6159374,0.6159374,3.950356
37.14,0.6190624,3.884968,0.3884968,0,0,0,0,0,0.6190624,0.6190624,0.6190624,3.961565
37.34,0.6223436,3.895223,0.3895223,0,0,0,0,0,0.6223436,0.6223436,0.6223436,3.972022
37.54,0.6257811,3.904257,0.3904257,0,0,0,0,0,0.6257811,0.6257811,0.6257811,3.981235
37.74,0.6289061,3.913927,0.3913927,0,0,0,0,0,0.6289061,0.6289061,0.6289061,3.991095
37.94,0.6321874,3.92651,0.392651,0,0,0,0,0,0.6321874,0.6321874,0.6321874,4.003925
38.14,0.6357812,3.937719,0.3937719,0,0,0,0,0,0.6357812,0.6357812,0.6357812,4.015357
38.34,0.6392187,3.950813,0.3950813,0,0,0,0,0,0.6392187,0.6392187,0.6392187,4.028708
38.54,0.6423437,3.960486,0.3960486,0,0,0,0,0,0.6423436,0.6423436,0.6423437,4.038571
38.74,0.6456249,3.972314,0.3972313,0,0,0,0,0,0.6456249,0.6456249,0.6456249,4.050632
38.94,0.6487499,3.981851,0.3981851,0,0,0,0,0,0.6487499,0.6487499,0.6487499,4.060359
39.14,0.6521874,3.992649,0.3992649,0,0,0,0,0,0.6521874,0.6521874,0.6521874,4.071369
39.34,0.6554687,3.99963,0.399963,0,0,0,0,0,0.6554686,0.6554686,0.6554687,4.078488
39.54,0.6589061,4.009765,0.4009765,0,0,0,0,0,0.6589061,0.6589061,0.6589061,4.088822
39.74,0.6626562,4.019785,0.4019785,0,0,0,0,0,0.6626561,0.6626561,0.6626562,4.09904
39.94,0.6662499,4.033707,0.4033707,0,0,0,0,0,0.6662499,0.6662499,0.6662499,4.113236
40.14,0.6693749,4.044066,0.4044066,0,0,0,0,0,0.6693749,0.6693749,0.6693749,4.1238
40.34,0.6723437,4.053827,0.4053827,0,0,0,0,0,0.6723437,0.6723437,0.6723437,4.133753
40.54,0.6754686,4.063921,0.4063921,0,0,0,0,0,0.6754686,0.6754686,0.6754686,4.144046
40.74,0.6787499,4.077742,0.4077742,0,0,0,0,0,0.6787499,0.6787499,0.6787499,4.15814
40.94,0.6820312,4.090542,0.4090542,0,0,0,0,0,0.6820312,0.6820312,0.6820312,4.171192
41.14,0.6854687,4.103699,0.4103699,0,0,0,0,0,0.6854687,0.6854687,0.6854687,4.184608
41.34,0.6887499,4.116439,0.411644,0,0,0,0,0,0.6887499,0.6887499,0.6887499,4.1976
41.54,0.6923436,4.130037,0.4130037,0,0,0,0,0,0.6923437,0.6923437,0.6923436,4.211466
41.74,0.6959374,4.144034,0.4144034,0,0,0,0,0,0.6959374,0.6959374,0.6959374,4.225739
41.94,0.6990624,4.155923,0.4155923,0,0,0,0,0,0.6990623,0.6990623,0.6990624,4.237862
42.14,0.7024999,4.168907,0.4168907,0,0,0,0,0,0.7024999,0.7024999,0.7024999,4.251102
42.34,0.7056249,4.177526,0.4177526,0,0,0,0,0,0.7056249,0.7056249,0.7056249,4.259891
42.54,0.7089062,4.189428,0.4189427,0,0,0,0,0,0.7089062,0.7089062,0.7089062,4.272027
42.74,0.7121874,4.195575,0.4195575,0,0,0,0,0,0.7121873,0.7121873,0.7121874,4.278296
42.94,0.7154687,4.207284,0.4207284,0,0,0,0,0,0.7154686,0.7154686,0.7154687,4.290236
43.14,0.7189062,4.222432,0.4222432,0,0,0,0,0,0.7189062,0.7189062,0.7189062,4.305682
43.34,0.7224999,4.236723,0.4236723,0,0,0,0,0,0.7224999,0.7224999,0.7224999,4.320255
43.54,0.7257811,4.248239,0.4248239,0,0,0,0,0,0.7257811,0.7257811,0.7257811,4.331998
43.74,0.7292186,4.263124,0.4263124,0,0,0,0,0,0.7292187,0.7292187,0.7292186,4.347177
43.94,0.7321874,4.274437,0.4274437,0,0,0,0,0,0.7321874,0.7321874,0.7321874,4.358713
44.14,0.7354686,4.286096,0.4286096,0,0,0,0,0,0.7354686,0.7354686,0.7354686,4.370602
44.34,0.7387499,4.298723,0.4298723,0,0,0,0,0,0.7387499,0.7387499,0.7387499,4.383478
44.54,0.7421874,4.313854,0.4313854,0,0,0,0,0,0.7421874,0.7421874,0.7421874,4.398907
44.74,0.7454687,4.327537,0.4327537,0,0,0,0,0,0.7454687,0.7454687,0.7454687,4.41286
44.94,0.7492186,4.343717,0.4343717,0,0,0,0,0,0.7492186,0.7492186,0.7492186,4.429358
45.14,0.7528124,4.359241,0.4359241,0,0,0,0,0,0.7528124,0.7528124,0.7528124,4.445189
45.34,0.7554686,4.368081,0.4368081,0,0,0,0,0,0.7554686,0.7554686,0.7554686,4.454203
45.54,0.7587499,4.382114,0.4382114,0,0,0,0,0,0.7587499,0.7587499,0.7587499,4.468513
45.74,0.7620311,4.395115,0.4395115,0,0,0,0,0,0.7620311,0.7620311,0.7620311,4.48177
45.94,0.7653124,4.407938,0.4407938,0,0,0,0,0,0.7653124,0.7653124,0.7653124,4.494846
46.14,0.7687499,4.420623,0.4420623,0,0,0,0,0,0.7687499,0.7687499,0.7687499,4.507781
46.34,0.7721874,4.436859,0.4436859,0,0,0,0,0,0.7721874,0.7721874,0.7721874,4.524337
46.54,0.7757812,4.45278,0.445278,0,0,0,0,0,0.7757812,0.7757812,0.7757812,4.540572
46.74,0.7793749,4.468349,0.4468349,0,0,0,0,0,0.7793749,0.7793749,0.7793749,4.556448
46.94,0.7824999,4.480194,0.4480194,0,0,0,0,0,0.7824999,0.7824999,0.7824999,4.568527
47.14,0.7859374,4.495357,0.4495357,0,0,0,0,0,0.7859374,0.7859374,0.7859374,4.583988
47.34,0.7890624,4.508423,0.4508424,0,0,0,0,0,0.7890624,0.7890624,0.7890624,4.597312
47.54,0.7924999,4.521273,0.4521273,0,0,0,0,0,0.7924998,0.7924998,0.7924999,4.610416
47.74,0.7956249,4.532811,0.4532811,0,0,0,0,0,0.7956249,0.7956249,0.7956249,4.622181
47.94,0.7987499,4.541842,0.4541841,0,0,0,0,0,0.7987499,0.7987499,0.7987499,4.63139
48.14,0.8023437,4.56013,0.456013,0,0,0,0,0,0.8023437,0.8023437,0.8023437,4.650039
48.34,0.8057812,4.577183,0.4577183,0,0,0,0,0,0.8057812,0.8057812,0.8057812,4.667428
48.54,0.8092186,4.593984,0.4593984,0,0,0,0,0,0.8092186,0.8092186,0.8092186,4.68456
48.74,0.8124999,4.608652,0.4608652,0,0,0,0,0,0.8124999,0.8124999,0.8124999,4.699518
48.94,0.8157811,4.624784,0.4624784,0,0,0,0,0,0.8157811,0.8157811,0.8157811,4.715967
49.14,0.8187499,4.637907,0.4637907,0,0,0,0,0,0.8187499,0.8187499,0.8187499,4.729349
49.34,0.8220311,4.654712,0.4654712,0,0,0,0,0,0.8220311,0.8220311,0.8220311,4.746485
49.54,0.8254686,4.671809,0.4671809,0,0,0,0,0,0.8254686,0.8254686,0.8254686,4.763919
49.74,0.8289061,4.688652,0.4688652,0,0,0,0,0,0.8289061,0.8289061,0.8289061,4.781095
49.94,0.8326562,4.70732,0.470732,0,0,0,0,0,0.8326561,0.8326561,0.8326562,4.80013
50.14,0.8362499,4.7265,0.47265,0,0,0,0,0,0.8362499,0.8362499,0.8362499,4.819688
50.34,0.8392186,4.738033,0.4738033,0,0,0,0,0,0.8392186,0.8392186,0.8392186,4.831449
50.54,0.8423437,4.753587,0.4753587,0,0,0,0,0,0.8423437,0.8423437,0.8423437,4.84731
50.74,0.8454687,4.769029,0.476903,0,0,0,0,0,0.8454686,0.8454686,0.8454687,4.863057
50.94,0.8487499,4.78651,0.478651,0,0,0,0,0,0.8487499,0.8487499,0.8487499,4.880882
51.14,0.8520312,4.804197,0.4804197,0,0,0,0,0,0.8520312,0.8520312,0.8520312,4.898918
51.34,0.8554686,4.822761,0.4822761,0,0,0,0,0,0.8554686,0.8554686,0.8554686,4.917848
51.54,0.8589061,4.839719,0.4839719,0,0,0,0,0,0.8589061,0.8589061,0.8589061,4.93514
51.74,0.8623436,4.859964,0.4859964,0,0,0,0,0,0.8623437,0.8623437,0.8623436,4.955784
51.94,0.8660936,4.880627,0.4880627,0,0,0,0,0,0.8660936,0.8660936,0.8660936,4.976855
52.14,0.8692187,4.892997,0.4892997,0,0,0,0,0,0.8692186,0.8692186,0.8692187,4.989469
52.34,0.8724999,4.910707,0.4910707,0,0,0,0,0,0.8724999,0.8724999,0.8724999,5.007528
52.54,0.8757811,4.926156,0.4926156,0,0,0,0,0,0.8757811,0.8757811,0.8757811,5.023281
52.74,0.8790624,4.944071,0.4944071,0,0,0,0,0,0.8790624,0.8790624,0.8790624,5.04155
52.94,0.8820312,4.958554,0.4958554,0,0,0,0,0,0.8820311,0.8820311,0.8820312,5.056317
53.14,0.8854686,4.968541,0.4968541,0,0,0,0,0,0.8854686,0.8854686,0.8854686,5.066502
53.34,0.8889061,4.990786,0.4990786,0,0,0,0,0,0.8889061,0.8889061,0.8889061,5.089185
53.54,0.8924999,5.013758,0.5013759,0,0,0,0,0,0.8924999,0.8924999,0.8924999,5.112611
53.74,0.8957812,5.031834,0.5031834,0,0,0,0,0,0.8957812,0.8957812,0.8957812,5.131043
53.94,0.8992187,5.051396,0.5051396,0,0,0,0,0,0.8992187,0.8992187,0.8992187,5.15099
54.14,0.9023437,5.069834,0.5069835,0,0,0,0,0,0.9023436,0.9023436,0.9023437,5.169792
54.34,0.9054687,5.086859,0.5086859,0,0,0,0,0,0.9054686,0.9054686,0.9054687,5.187152
54.54,0.9087499,5.105652,0.5105652,0,0,0,0,0,0.9087499,0.9087499,0.9087499,5.206316
54.74,0.9121874,5.126752,0.5126752,0,0,0,0,0,0.9121874,0.9121874,0.9121874,5.227832
54.94,0.9157811,5.147009,0.5147009,0,0,0,0,0,0.9157811,0.9157811,0.9157811,5.248488
55.14,0.9193749,5.170475,0.5170475,0,0,0,0,0,0.9193749,0.9193749,0.9193749,5.272417
55.34,0.9224999,5.186324,0.5186324,0,0,0,0,0,0.9224998,0.9224998,0.9224999,5.288579
55.54,0.9256249,5.203653,0.5203653,0,0,0,0,0,0.9256249,0.9256249,0.9256249,5.306249
55.74,0.9289061,5.225927,0.5225927,0,0,0,0,0,0.9289061,0.9289061,0.9289061,5.328962
55.94,0.9320311,5.246307,0.5246307,0,0,0,0,0,0.9320312,0.9320312,0.9320311,5.349744
56.14,0.9354686,5.266315,0.5266315,0,0,0,0,0,0.9354687,0.9354687,0.9354686,5.370147
56.34,0.9387499,5.288524,0.5288524,0,0,0,0,0,0.9387498,0.9387498,0.9387499,5.392794
56.54,0.9421874,5.31178,0.531178,0,0,0,0,0,0.9421874,0.9421874,0.9421874,5.416508
56.74,0.9456249,5.334461,0.5334461,0,0,0,0,0,0.9456249,0.9456249,0.9456249,5.439637
56.94,0.9493749,5.361012,0.5361012,0,0,0,0,0,0.9493749,0.9493749,0.9493749,5.466711
57.14,0.9526561,5.380198,0.5380198,0,0,0,0,0,0.9526561,0.9526561,0.9526561,5.486275
57.34,0.9559374,5.397738,0.5397738,0,0,0,0,0,0.9559374,0.9559374,0.9559374,5.504161
57.54,0.9592187,5.417121,0.5417121,0,0,0,0,0,0.9592187,0.9592187,0.9592187,5.523926
57.74,0.9624999,5.43885,0.5438851,0,0,0,0,0,0.9624999,0.9624999,0.9624999,5.546084
57.94,0.9654686,5.454213,0.5454213,0,0,0,0,0,0.9654686,0.9654686,0.9654686,5.561749
58.14,0.9687499,5.477089,0.5477089,0,0,0,0,0,0.9687499,0.9687499,0.9687499,5.585076
58.34,0.9721874,5.501739,0.5501739,0,0,0,0,0,0.9721874,0.9721874,0.9721874,5.610212
58.54,0.9756249,5.528031,0.552803,0,0,0,0,0,0.9756249,0.9756249,0.9756249,5.637022
58.74,0.9792185,5.552547,0.5552548,0,0,0,0,0,0.9792185,0.9792185,0.9792185,5.662023
58.94,0.9823436,5.575597,0.5575597,0,0,0,0,0,0.9823436,0.9823436,0.9823436,5.685526
59.14,0.9857811,5.597934,0.5597935,0,0,0,0,0,0.9857811,0.9857811,0.9857811,5.708304
59.34,0.988906,5.619002,0.5619002,0,0,0,0,0,0.988906,0.988906,0.988906,5.729787
59.54,0.9920311,5.638912,0.5638912,0,0,0,0,0,0.9920311,0.9920311,0.9920311,5.75009
59.74,0.9954686,5.663158,0.5663158,0,0,0,0,0,0.9954686,0.9954686,0.9954686,5.774814
59.94,0.9989061,5.688345,0.5688345,0,0,0,0,0,0.9989061,0.9989061,0.9989061,5.800498
60.14,1.002656,5.715782,0.5715782,0,0,0,0,0,1.002656,1.002656,1.002656,5.828475
60.34,1.005937,5.737891,0.5737891,0,0,0,0,0,1.005937,1.005937,1.005937,5.851021
60.54,1.009062,5.758704,0.5758704,0,0,0,0,0,1.009062,1.009062,1.009062,5.872244
60.74,1.012344,5.781081,0.5781081,0,0,0,0,0,1.012344,1.012344,1.012344,5.895062
60.94,1.015469,5.801916,0.5801916,0,0,0,0,0,1.015468,1.015468,1.015469,5.916308
61.14,1.01875,5.824146,0.5824146,0,0,0,0,0,1.01875,1.01875,1.01875,5.938976
61.34,1.022031,5.848064,0.5848064,0,0,0,0,0,1.022031,1.022031,1.022031,5.963366
61.54,1.025312,5.87384,0.587384,0,0,0,0,0,1.025312,1.025312,1.025312,5.98965
61.74,1.02875,5.900613,0.5900613,0,0,0,0,0,1.02875,1.02875,1.02875,6.016951
61.94,1.0325,5.925355,0.5925355,0,0,0,0,0,1.0325,1.0325,1.0325,6.04218
62.14,1.035781,5.952438,0.5952438,0,0,0,0,0,1.035781,1.035781,1.035781,6.069798
62.34,1.039219,5.978022,0.5978022,0,0,0,0,0,1.039219,1.039219,1.039219,6.095886
62.54,1.0425,5.998514,0.5998514,0,0,0,0,0,1.0425,1.0425,1.0425,6.116782
62.74,1.045781,6.018974,0.6018974,0,0,0,0,0,1.045781,1.045781,1.045781,6.137646
62.94,1.04875,6.038873,0.6038873,0,0,0,0,0,1.04875,1.04875,1.04875,6.157937
63.14,1.051875,6.064339,0.6064339,0,0,0,0,0,1.051875,1.051875,1.051875,6.183905
63.34,1.055312,6.094308,0.6094308,0,0,0,0,0,1.055312,1.055312,1.055312,6.214465
63.54,1.058906,6.123819,0.6123819,0,0,0,0,0,1.058906,1.058906,1.058906,6.244558
63.74,1.0625,6.153202,0.6153201,0,0,0,0,0,1.0625,1.0625,1.0625,6.274519
63.94,1.065937,6.181778,0.6181778,0,0,0,0,0,1.065937,1.065937,1.065937,6.303659
64.14,1.069062,6.206156,0.6206155,0,0,0,0,0,1.069062,1.069062,1.069062,6.328517
64.34,1.072344,6.233678,0.6233678,0,0,0,0,0,1.072344,1.072344,1.072344,6.356582
64.54,1.075625,6.25921,0.625921,0,0,0,0,0,1.075625,1.075625,1.075625,6.382617
64.74,1.07875,6.28304,0.628304,0,0,0,0,0,1.07875,1.07875,1.07875,6.406918
64.94,1.082187,6.312219,0.6312219,0,0,0,0,0,1.082187,1.082187,1.082187,6.436672
65.14,1.085625,6.341968,0.6341969,0,0,0,0,0,1.085625,1.085625,1.085625,6.467008
65.34,1.089375,6.379214,0.6379214,0,0,0,0,0,1.089375,1.089375,1.089375,6.504988
65.54,1.092344,6.39834,0.639834,0,0,0,0,0,1.092344,1.092344,1.092344,6.524491
65.74001,1.095469,6.42288,0.642288,0,0,0,0,0,1.095469,1.095469,1.095469,6.549514
65.94,1.09875,6.453685,0.6453685,0,0,0,0,0,1.09875,1.09875,1.09875,6.580927
66.14,1.102031,6.483288,0.6483288,0,0,0,0,0,1.102031,1.102031,1.102031,6.611114
66.34001,1.105469,6.513295,0.6513295,0,0,0,0,0,1.105469,1.105469,1.105469,6.641712
66.54,1.10875,6.544871,0.6544871,0,0,0,0,0,1.10875,1.10875,1.10875,6.673911
66.722,1.111875,6.573914,0.6573914,0,0,0,0,0,1.111875,1.111875,1.111875,6.703526