File: dataFilesDay2/instron data/staticInstron_1.raw
"Test Type","Tension"
"Method Name","C:\Users\mmen339\Documents\tension test 1mm_s.im_tens"
"Sample name","C:\Users\mmen339\Documents\sample 2\S2.is_tens"
"User",""
"Sample note 1",""
"Sample note 2",""
"Sample note 3",""
"Geometry","Rectangular"
"Specimen",1
"Specimen label",""
"Width",10.000000,"mm"
"Thickness",1.000000,"mm"
"Length",100.000000,"mm"
"Diameter",10.000000,"mm"
"Inner diameter",8.000000,"mm"
"Outer diameter",10.000000,"mm"
"Wall thickness",1.000000,"mm"
"Area",0.100000,"cm^2"
"Linear density",100.000000,"tex"
"Sled weight",10.000000,"N"
"Loading span",10.000000,"mm"
"Support span",100.000000,"mm"
"Span ratio","2"
"Fixture type","4-point"
"Included"
"Final width",10.000000,"mm"
"Final thickness",1.000000,"mm"
"Final length",100.000000,"mm"
"Final diameter",10.000000,"mm"
"Final Inner diameter",8.000000,"mm"
"Final outer diameter",10.000000,"mm"
"Final wall thickness",1.000000,"mm"
"Final area",0.100000,"cm^2"
"Final linear density",100.000000,"tex"
"Custom text input  1",""
"Custom text input  2",""
"Custom text input  3",""
"Custom text input  4",""
"Custom text input  5",""
"Custom text input  6",""
"Custom text input  7",""
"Custom text input  8",""
"Custom text input  9",""
"Custom text input 10",""
"Custom text input 11",""
"Custom text input 12",""
"Custom text input 13",""
"Custom text input 14",""
"Custom text input 15",""
"Custom text input 16",""
"Custom text input 17",""
"Custom text input 18",""
"Custom text input 19",""
"Custom text input 20",""
"Custom text input 21",""
"Custom text input 22",""
"Custom text input 23",""
"Custom text input 24",""
"Custom text input 25",""
"Custom text input 26",""
"Custom text input 27",""
"Custom text input 28",""
"Custom text input 29",""
"Custom text input 30",""
"Custom text input 31",""
"Custom text input 32",""
"Custom text input 33",""
"Custom text input 34",""
"Custom text input 35",""
"Custom text input 36",""
"Custom text input 37",""
"Custom text input 38",""
"Custom text input 39",""
"Custom text input 40",""
"Custom text input 41",""
"Custom text input 42",""
"Custom text input 43",""
"Custom text input 44",""
"Custom text input 45",""
"Custom text input 46",""
"Custom text input 47",""
"Custom text input 48",""
"Custom text input 49",""
"Custom text input 50",""
"Custom number input  1",0.000000,""
"Custom number input  2",0.000000,""
"Custom number input  3",0.000000,""
"Custom number input  4",0.000000,""
"Custom number input  5",0.000000,""
"Custom number input  6",0.000000,""
"Custom number input  7",0.000000,""
"Custom number input  8",0.000000,""
"Custom number input  9",0.000000,""
"Custom number input 10",0.000000,""
"Time sec","Extension mm","Load N","Tensile stress MPa","Cycle Count ","Total Cycle Count ","Repetitions Count ","Marked Data ","PIP Count ","Tensile extension mm","Tensile strain %","Corrected Position mm","Tenacity gf/tex"
0,0,0.001672463,0.0001672463,0,0,0,0,0,0,0,0,0.001705438
0.1,0.0003125,0.002061279,0.0002061279,0,0,0,0,0,0.0003125,0.0003125,0.0003125,0.00210192
0.2,0.0009374999,0.005290306,0.0005290306,0,0,0,0,0,0.0009374999,0.0009374999,0.0009374999,0.005394611
0.3,0.00234375,0.01206092,0.001206092,0,0,0,0,0,0.00234375,0.00234375,0.00234375,0.01229872
0.4,0.004218749,0.02095802,0.002095802,0,0,0,0,0,0.004218749,0.004218749,0.004218749,0.02137123
0.5,0.006406249,0.0312023,0.00312023,0,0,0,0,0,0.006406249,0.006406249,0.006406249,0.03181749
0.6,0.008593748,0.04119773,0.004119773,0,0,0,0,0,0.008593748,0.008593748,0.008593748,0.04200999
0.7000001,0.0109375,0.05036946,0.005036946,0,0,0,0,0,0.0109375,0.0109375,0.0109375,0.05136255
0.8,0.0128125,0.058081,0.0058081,0,0,0,0,0,0.0128125,0.0128125,0.0128125,0.05922613
0.9000001,0.0146875,0.0653355,0.00653355,0,0,0,0,0,0.0146875,0.0146875,0.0146875,0.06662367
1,0.0165625,0.07140797,0.007140797,0,0,0,0,0,0.0165625,0.0165625,0.0165625,0.07281587
1.1,0.01828125,0.0764815,0.00764815,0,0,0,0,0,0.01828125,0.01828125,0.01828125,0.07798943
1.2,0.02015625,0.08257073,0.008257073,0,0,0,0,0,0.02015625,0.02015625,0.02015625,0.08419871
1.3,0.021875,0.08882032,0.008882032,0,0,0,0,0,0.021875,0.021875,0.021875,0.09057152
1.4,0.02359375,0.09361509,0.009361509,0,0,0,0,0,0.02359375,0.02359375,0.02359375,0.09546082
1.5,0.0253125,0.098852,0.009885199,0,0,0,0,0,0.0253125,0.0253125,0.0253125,0.100801
1.6,0.026875,0.1031636,0.01031636,0,0,0,0,0,0.026875,0.026875,0.026875,0.1051976
1.7,0.0284375,0.1068037,0.01068037,0,0,0,0,0,0.0284375,0.0284375,0.0284375,0.1089094
1.8,0.03,0.1115153,0.01115153,0,0,0,0,0,0.03,0.03,0.03,0.113714
1.9,0.03156249,0.1164359,0.01164359,0,0,0,0,0,0.03156249,0.03156249,0.03156249,0.1187315
2,0.03296874,0.1200023,0.01200023,0,0,0,0,0,0.03296874,0.03296874,0.03296874,0.1223682
2.1,0.03468749,0.1246855,0.01246855,0,0,0,0,0,0.0346875,0.0346875,0.03468749,0.1271438
2.2,0.03640624,0.1290985,0.01290985,0,0,0,0,0,0.03640625,0.03640625,0.03640624,0.1316438
2.3,0.03796874,0.1325265,0.01325265,0,0,0,0,0,0.03796874,0.03796874,0.03796874,0.1351394
2.4,0.03968749,0.1363668,0.01363668,0,0,0,0,0,0.03968749,0.03968749,0.03968749,0.1390555
2.5,0.04124999,0.1409829,0.01409829,0,0,0,0,0,0.04124999,0.04124999,0.04124999,0.1437626
2.6,0.04296874,0.1443819,0.01443819,0,0,0,0,0,0.04296874,0.04296874,0.04296874,0.1472286
2.7,0.04468749,0.1487729,0.01487729,0,0,0,0,0,0.04468749,0.04468749,0.04468749,0.1517061
2.8,0.04640624,0.1363653,0.01363653,0,0,0,0,0,0.04640624,0.04640624,0.04640624,0.1390539
2.9,0.04812499,0.1392741,0.01392741,0,0,0,0,0,0.04812499,0.04812499,0.04812499,0.14202
3,0.04984374,0.1425346,0.01425346,0,0,0,0,0,0.04984374,0.04984374,0.04984374,0.1453448
3.1,0.05156249,0.1459079,0.01459079,0,0,0,0,0,0.05156249,0.05156249,0.05156249,0.1487846
3.2,0.05343749,0.1499001,0.01499001,0,0,0,0,0,0.05343749,0.05343749,0.05343749,0.1528556
3.3,0.05515624,0.152573,0.0152573,0,0,0,0,0,0.05515625,0.05515625,0.05515624,0.1555812
3.4,0.05687499,0.1566871,0.01566871,0,0,0,0,0,0.05687499,0.05687499,0.05687499,0.1597764
3.5,0.05843749,0.1601395,0.01601395,0,0,0,0,0,0.05843749,0.05843749,0.05843749,0.1632968
3.6,0.06015624,0.1628022,0.01628022,0,0,0,0,0,0.06015624,0.06015624,0.06015624,0.1660121
3.7,0.06171874,0.1647219,0.01647219,0,0,0,0,0,0.06171874,0.06171874,0.06171874,0.1679696
3.8,0.06328124,0.1679904,0.01679904,0,0,0,0,0,0.06328124,0.06328124,0.06328124,0.1713026
3.9,0.06468749,0.170314,0.0170314,0,0,0,0,0,0.06468749,0.06468749,0.06468749,0.173672
4,0.06640624,0.1727336,0.01727336,0,0,0,0,0,0.06640624,0.06640624,0.06640624,0.1761392
4.1,0.06812499,0.1761366,0.01761366,0,0,0,0,0,0.06812499,0.06812499,0.06812499,0.1796094
4.2,0.06968748,0.1789551,0.01789551,0,0,0,0,0,0.06968749,0.06968749,0.06968748,0.1824834
4.3,0.07156248,0.1805938,0.01805938,0,0,0,0,0,0.07156248,0.07156248,0.07156248,0.1841544
4.4,0.07328124,0.1829498,0.01829498,0,0,0,0,0,0.07328124,0.07328124,0.07328124,0.1865569
4.5,0.07484374,0.1858695,0.01858695,0,0,0,0,0,0.07484373,0.07484373,0.07484374,0.1895341
4.6,0.07656249,0.1884838,0.01884838,0,0,0,0,0,0.07656249,0.07656249,0.07656249,0.1922
4.7,0.07828123,0.1912191,0.01912191,0,0,0,0,0,0.07828123,0.07828123,0.07828123,0.1949892
4.8,0.07999999,0.1935814,0.01935814,0,0,0,0,0,0.07999999,0.07999999,0.07999999,0.1973981
4.9,0.08187499,0.1970023,0.01970023,0,0,0,0,0,0.08187499,0.08187499,0.08187499,0.2008864
5,0.08343749,0.2000634,0.02000634,0,0,0,0,0,0.08343749,0.08343749,0.08343749,0.2040079
5.1,0.08515624,0.20171,0.020171,0,0,0,0,0,0.08515624,0.08515624,0.08515624,0.205687
5.2,0.08671873,0.2045247,0.02045247,0,0,0,0,0,0.08671873,0.08671873,0.08671873,0.2085572
5.3,0.08828124,0.2072371,0.02072371,0,0,0,0,0,0.08828124,0.08828124,0.08828124,0.2113231
5.4,0.08984374,0.2093849,0.02093849,0,0,0,0,0,0.08984374,0.08984374,0.08984374,0.2135132
5.5,0.09140624,0.2117228,0.02117228,0,0,0,0,0,0.09140624,0.09140624,0.09140624,0.2158971
5.6,0.09312499,0.2136804,0.02136804,0,0,0,0,0,0.09312499,0.09312499,0.09312499,0.2178934
5.7,0.09468749,0.2160211,0.02160211,0,0,0,0,0,0.09468748,0.09468748,0.09468749,0.2202802
5.8,0.09640623,0.2186969,0.02186969,0,0,0,0,0,0.09640624,0.09640624,0.09640623,0.2230087
5.9,0.09812498,0.2204201,0.02204201,0,0,0,0,0,0.09812498,0.09812498,0.09812498,0.224766
6,0.09984374,0.2235673,0.02235673,0,0,0,0,0,0.09984374,0.09984374,0.09984374,0.2279752
6.1,0.1015625,0.2259115,0.02259115,0,0,0,0,0,0.1015625,0.1015625,0.1015625,0.2303656
6.2,0.103125,0.2274162,0.02274162,0,0,0,0,0,0.103125,0.103125,0.103125,0.2318999
6.3,0.105,0.2308364,0.02308364,0,0,0,0,0,0.105,0.105,0.105,0.2353877
6.4,0.106875,0.2331115,0.02331115,0,0,0,0,0,0.106875,0.106875,0.106875,0.2377076
6.5,0.10875,0.2363865,0.02363865,0,0,0,0,0,0.10875,0.10875,0.10875,0.2410471
6.6,0.1104687,0.2382951,0.02382951,0,0,0,0,0,0.1104687,0.1104687,0.1104687,0.2429934
6.7,0.111875,0.2388585,0.02388585,0,0,0,0,0,0.111875,0.111875,0.111875,0.2435679
6.8,0.1134375,0.2413365,0.02413365,0,0,0,0,0,0.1134375,0.1134375,0.1134375,0.2460948
6.9,0.1151562,0.2430989,0.02430989,0,0,0,0,0,0.1151562,0.1151562,0.1151562,0.2478919
7,0.1167187,0.2453127,0.02453127,0,0,0,0,0,0.1167187,0.1167187,0.1167187,0.2501493
7.1,0.118125,0.2470817,0.02470817,0,0,0,0,0,0.118125,0.118125,0.118125,0.2519532
7.2,0.1196875,0.2489863,0.02489863,0,0,0,0,0,0.1196875,0.1196875,0.1196875,0.2538954
7.3,0.12125,0.2509229,0.02509229,0,0,0,0,0,0.12125,0.12125,0.12125,0.2558702
7.4,0.1229687,0.2530283,0.02530283,0,0,0,0,0,0.1229687,0.1229687,0.1229687,0.258017
7.5,0.1245312,0.2550875,0.02550875,0,0,0,0,0,0.1245312,0.1245312,0.1245312,0.2601169
7.6,0.12625,0.2569937,0.02569937,0,0,0,0,0,0.12625,0.12625,0.12625,0.2620607
7.7,0.1279687,0.2595362,0.02595362,0,0,0,0,0,0.1279687,0.1279687,0.1279687,0.2646533
7.8,0.1296875,0.2614528,0.02614528,0,0,0,0,0,0.1296875,0.1296875,0.1296875,0.2666077
7.9,0.1314062,0.2630551,0.02630551,0,0,0,0,0,0.1314062,0.1314062,0.1314062,0.2682416
8,0.133125,0.2654274,0.02654273,0,0,0,0,0,0.133125,0.133125,0.133125,0.2706606
8.1,0.1348437,0.2674714,0.02674714,0,0,0,0,0,0.1348437,0.1348437,0.1348437,0.2727449
8.200001,0.136875,0.2701459,0.02701459,0,0,0,0,0,0.136875,0.136875,0.136875,0.2754721
8.3,0.13875,0.2725198,0.02725198,0,0,0,0,0,0.13875,0.13875,0.13875,0.2778929
8.400001,0.1403125,0.2736926,0.02736926,0,0,0,0,0,0.1403125,0.1403125,0.1403125,0.2790887
8.5,0.141875,0.2752978,0.02752978,0,0,0,0,0,0.141875,0.141875,0.141875,0.2807256
8.6,0.1434375,0.2770084,0.02770084,0,0,0,0,0,0.1434375,0.1434375,0.1434375,0.28247
8.700001,0.1451562,0.2793618,0.02793618,0,0,0,0,0,0.1451562,0.1451562,0.1451562,0.2848698
8.8,0.1467187,0.2807058,0.02807058,0,0,0,0,0,0.1467187,0.1467187,0.1467187,0.2862403
8.900001,0.1482812,0.2820408,0.02820408,0,0,0,0,0,0.1482812,0.1482812,0.1482812,0.2876016
9,0.1498437,0.2835748,0.02835748,0,0,0,0,0,0.1498437,0.1498437,0.1498437,0.2891658
9.1,0.1515625,0.2849856,0.02849856,0,0,0,0,0,0.1515625,0.1515625,0.1515625,0.2906044
9.200001,0.153125,0.2870965,0.02870965,0,0,0,0,0,0.153125,0.153125,0.153125,0.2927569
9.3,0.1546875,0.2882726,0.02882726,0,0,0,0,0,0.1546875,0.1546875,0.1546875,0.2939563
9.400001,0.1564062,0.2905204,0.02905205,0,0,0,0,0,0.1564062,0.1564062,0.1564062,0.2962484
9.5,0.1579687,0.291956,0.0291956,0,0,0,0,0,0.1579687,0.1579687,0.1579687,0.2977123
9.6,0.1595312,0.2941802,0.02941802,0,0,0,0,0,0.1595312,0.1595312,0.1595312,0.2999804
9.700001,0.16125,0.2947703,0.02947703,0,0,0,0,0,0.16125,0.16125,0.16125,0.300582
9.8,0.163125,0.2966187,0.02966187,0,0,0,0,0,0.163125,0.163125,0.163125,0.3024669
9.900001,0.1648437,0.2989984,0.02989984,0,0,0,0,0,0.1648437,0.1648437,0.1648437,0.3048936
10,0.1665625,0.3008609,0.03008609,0,0,0,0,0,0.1665625,0.1665625,0.1665625,0.3067927
10.1,0.1682812,0.3023412,0.03023412,0,0,0,0,0,0.1682812,0.1682812,0.1682812,0.3083022
10.2,0.1696875,0.3037036,0.03037036,0,0,0,0,0,0.1696875,0.1696875,0.1696875,0.3096915
10.3,0.1714062,0.3054632,0.03054632,0,0,0,0,0,0.1714062,0.1714062,0.1714062,0.3114857
10.4,0.173125,0.3069137,0.03069136,0,0,0,0,0,0.173125,0.173125,0.173125,0.3129648
10.5,0.1748437,0.3086751,0.03086751,0,0,0,0,0,0.1748437,0.1748437,0.1748437,0.314761
10.6,0.1764062,0.3101185,0.03101185,0,0,0,0,0,0.1764062,0.1764062,0.1764062,0.3162328
10.7,0.1779687,0.311694,0.0311694,0,0,0,0,0,0.1779687,0.1779687,0.1779687,0.3178394
10.8,0.1796875,0.3134037,0.03134037,0,0,0,0,0,0.1796875,0.1796875,0.1796875,0.3195828
10.9,0.1814062,0.3147545,0.03147545,0,0,0,0,0,0.1814062,0.1814062,0.1814062,0.3209602
11,0.1829687,0.3163732,0.03163732,0,0,0,0,0,0.1829687,0.1829687,0.1829687,0.3226109
11.1,0.1846875,0.3179452,0.03179452,0,0,0,0,0,0.1846875,0.1846875,0.1846875,0.3242138
11.2,0.1865625,0.3196898,0.03196898,0,0,0,0,0,0.1865625,0.1865625,0.1865625,0.3259929
11.3,0.1882812,0.3214034,0.03214034,0,0,0,0,0,0.1882812,0.1882812,0.1882812,0.3277403
11.4,0.1901562,0.3237873,0.03237873,0,0,0,0,0,0.1901562,0.1901562,0.1901562,0.3301712
11.5,0.191875,0.3251771,0.03251771,0,0,0,0,0,0.191875,0.191875,0.191875,0.3315884
11.6,0.1935937,0.3266601,0.03266601,0,0,0,0,0,0.1935937,0.1935937,0.1935937,0.3331006
11.7,0.1953125,0.3278101,0.03278101,0,0,0,0,0,0.1953125,0.1953125,0.1953125,0.3342733
11.8,0.1970312,0.3301276,0.03301276,0,0,0,0,0,0.1970312,0.1970312,0.1970312,0.3366364
11.9,0.1984375,0.3307492,0.03307492,0,0,0,0,0,0.1984375,0.1984375,0.1984375,0.3372703
12,0.1998437,0.3321696,0.03321696,0,0,0,0,0,0.1998437,0.1998437,0.1998437,0.3387187
12.1,0.2014062,0.3332412,0.03332412,0,0,0,0,0,0.2014062,0.2014062,0.2014062,0.3398115
12.2,0.2029687,0.3346279,0.03346279,0,0,0,0,0,0.2029687,0.2029687,0.2029687,0.3412255
12.3,0.2046875,0.3364141,0.03364141,0,0,0,0,0,0.2046875,0.2046875,0.2046875,0.3430469
12.4,0.20625,0.3378249,0.03378249,0,0,0,0,0,0.20625,0.20625,0.20625,0.3444855
12.5,0.2079687,0.3393529,0.03393529,0,0,0,0,0,0.2079687,0.2079687,0.2079687,0.3460436
12.6,0.2095312,0.3413018,0.03413018,0,0,0,0,0,0.2095312,0.2095312,0.2095312,0.348031
12.7,0.2110937,0.3422258,0.03422258,0,0,0,0,0,0.2110937,0.2110937,0.2110937,0.3489732
12.8,0.2128125,0.3438934,0.03438934,0,0,0,0,0,0.2128125,0.2128125,0.2128125,0.3506737
12.9,0.2145312,0.3450116,0.03450116,0,0,0,0,0,0.2145312,0.2145312,0.2145312,0.3518139
13,0.21625,0.3467235,0.03467235,0,0,0,0,0,0.21625,0.21625,0.21625,0.3535595
13.1,0.218125,0.3486917,0.03486917,0,0,0,0,0,0.218125,0.218125,0.218125,0.3555666
13.2,0.2198437,0.34989,0.034989,0,0,0,0,0,0.2198437,0.2198437,0.2198437,0.3567885
13.3,0.2217187,0.3509864,0.03509864,0,0,0,0,0,0.2217187,0.2217187,0.2217187,0.3579066
13.4,0.2234375,0.3525556,0.03525556,0,0,0,0,0,0.2234375,0.2234375,0.2234375,0.3595067
13.5,0.2251562,0.353542,0.0353542,0,0,0,0,0,0.2251562,0.2251562,0.2251562,0.3605125
13.6,0.2267187,0.354992,0.0354992,0,0,0,0,0,0.2267187,0.2267187,0.2267187,0.3619911
13.7,0.2284375,0.3566121,0.03566121,0,0,0,0,0,0.2284375,0.2284375,0.2284375,0.3636432
13.8,0.2301562,0.3574972,0.03574972,0,0,0,0,0,0.2301562,0.2301562,0.2301562,0.3645457
13.9,0.2317187,0.3588204,0.03588204,0,0,0,0,0,0.2317187,0.2317187,0.2317187,0.3658949
14,0.2332812,0.3605074,0.03605074,0,0,0,0,0,0.2332812,0.2332812,0.2332812,0.3676152
14.1,0.2348437,0.3609227,0.03609227,0,0,0,0,0,0.2348437,0.2348437,0.2348437,0.3680388
14.2,0.2364062,0.3621485,0.03621485,0,0,0,0,0,0.2364062,0.2364062,0.2364062,0.3692887
14.3,0.238125,0.3626148,0.03626148,0,0,0,0,0,0.238125,0.238125,0.238125,0.3697642
14.4,0.2396875,0.3647239,0.03647239,0,0,0,0,0,0.2396875,0.2396875,0.2396875,0.3719148
14.5,0.24125,0.3662548,0.03662548,0,0,0,0,0,0.24125,0.24125,0.24125,0.373476
14.6,0.2429687,0.3677221,0.03677221,0,0,0,0,0,0.2429687,0.2429687,0.2429687,0.3749722
14.7,0.2446875,0.3683797,0.03683797,0,0,0,0,0,0.2446875,0.2446875,0.2446875,0.3756428
14.8,0.2465624,0.3703241,0.03703241,0,0,0,0,0,0.2465624,0.2465624,0.2465624,0.3776255
14.9,0.2482812,0.3722265,0.03722265,0,0,0,0,0,0.2482812,0.2482812,0.2482812,0.3795654
15,0.25,0.3731941,0.03731941,0,0,0,0,0,0.25,0.25,0.25,0.3805521
15.1,0.2518749,0.3751497,0.03751497,0,0,0,0,0,0.251875,0.251875,0.2518749,0.3825462
15.2,0.2534374,0.3764615,0.03764615,0,0,0,0,0,0.2534374,0.2534374,0.2534374,0.3838839
15.3,0.255,0.3774559,0.03774559,0,0,0,0,0,0.255,0.255,0.255,0.3848979
15.4,0.2565625,0.3784637,0.03784637,0,0,0,0,0,0.2565625,0.2565625,0.2565625,0.3859255
15.5,0.258125,0.3793052,0.03793052,0,0,0,0,0,0.2581249,0.2581249,0.258125,0.3867837
15.6,0.2596875,0.3806695,0.03806695,0,0,0,0,0,0.2596875,0.2596875,0.2596875,0.3881749
15.7,0.2614062,0.3810038,0.03810038,0,0,0,0,0,0.2614062,0.2614062,0.2614062,0.3885157
15.8,0.2631249,0.3825604,0.03825604,0,0,0,0,0,0.2631249,0.2631249,0.2631249,0.390103
15.9,0.2648437,0.3843468,0.03843468,0,0,0,0,0,0.2648437,0.2648437,0.2648437,0.3919246
16,0.2664062,0.3853963,0.03853963,0,0,0,0,0,0.2664062,0.2664062,0.2664062,0.3929949
16.1,0.2681249,0.3860297,0.03860297,0,0,0,0,0,0.2681249,0.2681249,0.2681249,0.3936407
16.2,0.2698437,0.387461,0.0387461,0,0,0,0,0,0.2698437,0.2698437,0.2698437,0.3951003
16.3,0.2714062,0.3881812,0.03881812,0,0,0,0,0,0.2714062,0.2714062,0.2714062,0.3958347
16.4,0.2732812,0.3891925,0.03891926,0,0,0,0,0,0.2732812,0.2732812,0.2732812,0.3968659
16.5,0.2751562,0.3904271,0.03904271,0,0,0,0,0,0.2751562,0.2751562,0.2751562,0.3981248
16.6,0.276875,0.3917616,0.03917616,0,0,0,0,0,0.276875,0.276875,0.276875,0.3994857
16.7,0.2785937,0.3921019,0.03921019,0,0,0,0,0,0.2785937,0.2785937,0.2785937,0.3998327
16.8,0.2801562,0.3934414,0.03934414,0,0,0,0,0,0.2801562,0.2801562,0.2801562,0.4011985
16.9,0.2815624,0.3944168,0.03944168,0,0,0,0,0,0.2815624,0.2815624,0.2815624,0.4021932
17,0.2831249,0.3948761,0.03948761,0,0,0,0,0,0.283125,0.283125,0.2831249,0.4026615
17.1,0.2848437,0.3960955,0.03960956,0,0,0,0,0,0.2848437,0.2848437,0.2848437,0.403905
17.2,0.2865625,0.3971937,0.03971937,0,0,0,0,0,0.2865624,0.2865624,0.2865625,0.4050248
17.3,0.288125,0.3984467,0.03984467,0,0,0,0,0,0.2881249,0.2881249,0.288125,0.4063025
17.4,0.2896875,0.3994552,0.03994552,0,0,0,0,0,0.2896875,0.2896875,0.2896875,0.407331
17.5,0.2912499,0.4004132,0.04004132,0,0,0,0,0,0.29125,0.29125,0.2912499,0.4083078
17.6,0.2929687,0.4017252,0.04017252,0,0,0,0,0,0.2929687,0.2929687,0.2929687,0.4096457
17.7,0.2946875,0.4025393,0.04025393,0,0,0,0,0,0.2946874,0.2946874,0.2946875,0.4104758
17.8,0.2964062,0.4039575,0.04039575,0,0,0,0,0,0.2964062,0.2964062,0.2964062,0.411922
17.9,0.2979687,0.4059466,0.04059466,0,0,0,0,0,0.2979687,0.2979687,0.2979687,0.4139503
18,0.2998437,0.4066503,0.04066503,0,0,0,0,0,0.2998437,0.2998437,0.2998437,0.4146679
18.1,0.3015625,0.4078269,0.04078269,0,0,0,0,0,0.3015625,0.3015625,0.3015625,0.4158677
18.2,0.3034374,0.4096419,0.04096419,0,0,0,0,0,0.3034374,0.3034374,0.3034374,0.4177184
18.3,0.3053125,0.4108502,0.04108502,0,0,0,0,0,0.3053125,0.3053125,0.3053125,0.4189506
18.4,0.3070312,0.4121291,0.04121291,0,0,0,0,0,0.3070312,0.3070312,0.3070312,0.4202547
18.5,0.3087499,0.4132127,0.04132127,0,0,0,0,0,0.3087499,0.3087499,0.3087499,0.4213597
18.6,0.3104687,0.4150818,0.04150818,0,0,0,0,0,0.3104687,0.3104687,0.3104687,0.4232656
18.7,0.311875,0.4145972,0.04145972,0,0,0,0,0,0.311875,0.311875,0.311875,0.4227715
18.8,0.3135937,0.4154509,0.04154509,0,0,0,0,0,0.3135937,0.3135937,0.3135937,0.423642
18.9,0.3153124,0.4176595,0.04176595,0,0,0,0,0,0.3153124,0.3153124,0.3153124,0.4258942
19,0.3168749,0.4180043,0.04180043,0,0,0,0,0,0.316875,0.316875,0.3168749,0.4262457
19.1,0.3184374,0.4183758,0.04183758,0,0,0,0,0,0.3184374,0.3184374,0.3184374,0.4266246
19.2,0.3201562,0.4200208,0.04200209,0,0,0,0,0,0.3201562,0.3201562,0.3201562,0.4283021
19.3,0.3215625,0.4205826,0.04205826,0,0,0,0,0,0.3215625,0.3215625,0.3215625,0.4288749
19.4,0.3229687,0.4214622,0.04214622,0,0,0,0,0,0.3229687,0.3229687,0.3229687,0.4297718
19.5,0.3245312,0.4223557,0.04223557,0,0,0,0,0,0.3245312,0.3245312,0.3245312,0.4306829
19.6,0.32625,0.424136,0.0424136,0,0,0,0,0,0.32625,0.32625,0.32625,0.4324983
19.7,0.3279687,0.4252908,0.04252908,0,0,0,0,0,0.3279687,0.3279687,0.3279687,0.4336759
19.8,0.3296874,0.4262529,0.04262529,0,0,0,0,0,0.3296874,0.3296874,0.3296874,0.434657
19.9,0.3314062,0.4274596,0.04274596,0,0,0,0,0,0.3314062,0.3314062,0.3314062,0.4358875
20,0.3331249,0.4286001,0.04286001,0,0,0,0,0,0.3331249,0.3331249,0.3331249,0.4370504
20.1,0.3348437,0.4304762,0.04304763,0,0,0,0,0,0.3348437,0.3348437,0.3348437,0.4389636
20.2,0.3367187,0.4313141,0.04313141,0,0,0,0,0,0.3367187,0.3367187,0.3367187,0.4398179
20.3,0.3384374,0.4319562,0.04319562,0,0,0,0,0,0.3384374,0.3384374,0.3384374,0.4404728
20.4,0.3399999,0.4328042,0.04328042,0,0,0,0,0,0.3399999,0.3399999,0.3399999,0.4413375
20.5,0.3417187,0.4339308,0.04339308,0,0,0,0,0,0.3417187,0.3417187,0.3417187,0.4424863
20.6,0.3432812,0.434759,0.0434759,0,0,0,0,0,0.3432812,0.3432812,0.3432812,0.4433308
20.7,0.3451562,0.4353202,0.04353202,0,0,0,0,0,0.3451562,0.3451562,0.3451562,0.4439031
20.8,0.3467187,0.4161244,0.04161244,0,0,0,0,0,0.3467187,0.3467187,0.3467187,0.4243288
20.9,0.3482812,0.4153366,0.04153366,0,0,0,0,0,0.3482812,0.3482812,0.3482812,0.4235255
21,0.35,0.4154766,0.04154766,0,0,0,0,0,0.35,0.35,0.35,0.4236682
21.1,0.3517187,0.4163267,0.04163267,0,0,0,0,0,0.3517187,0.3517187,0.3517187,0.4245351
21.2,0.3532812,0.4171306,0.04171306,0,0,0,0,0,0.3532812,0.3532812,0.3532812,0.4253549
21.3,0.3549999,0.4175936,0.04175936,0,0,0,0,0,0.3549999,0.3549999,0.3549999,0.425827
21.4,0.3567187,0.4183336,0.04183336,0,0,0,0,0,0.3567187,0.3567187,0.3567187,0.4265816
21.5,0.3585937,0.4194502,0.04194502,0,0,0,0,0,0.3585937,0.3585937,0.3585937,0.4277202
21.6,0.3601562,0.4206865,0.04206865,0,0,0,0,0,0.3601562,0.3601562,0.3601562,0.4289809
21.7,0.3617187,0.421225,0.0421225,0,0,0,0,0,0.3617187,0.3617187,0.3617187,0.42953
21.8,0.3634375,0.4225384,0.04225384,0,0,0,0,0,0.3634375,0.3634375,0.3634375,0.4308693
21.9,0.3651562,0.4233942,0.04233942,0,0,0,0,0,0.3651562,0.3651562,0.3651562,0.431742
22,0.3667187,0.4246559,0.04246559,0,0,0,0,0,0.3667187,0.3667187,0.3667187,0.4330285
22.1,0.3684374,0.4251914,0.04251914,0,0,0,0,0,0.3684374,0.3684374,0.3684374,0.4335746
22.2,0.3699999,0.4259076,0.04259076,0,0,0,0,0,0.3699999,0.3699999,0.3699999,0.4343049
22.3,0.3717187,0.4271846,0.04271846,0,0,0,0,0,0.3717187,0.3717187,0.3717187,0.435607
22.4,0.3734374,0.4280865,0.04280865,0,0,0,0,0,0.3734374,0.3734374,0.3734374,0.4365267
22.5,0.3748437,0.4285652,0.04285652,0,0,0,0,0,0.3748437,0.3748437,0.3748437,0.4370148
22.6,0.3765624,0.429471,0.0429471,0,0,0,0,0,0.3765624,0.3765624,0.3765624,0.4379386
22.7,0.3781249,0.4301893,0.04301893,0,0,0,0,0,0.378125,0.378125,0.3781249,0.438671
22.8,0.3796874,0.4312352,0.04312352,0,0,0,0,0,0.3796874,0.3796874,0.3796874,0.4397376
22.9,0.3812499,0.4315896,0.04315896,0,0,0,0,0,0.3812499,0.3812499,0.3812499,0.4400989
23,0.3831249,0.4326788,0.04326788,0,0,0,0,0,0.3831249,0.3831249,0.3831249,0.4412096
23.1,0.3848437,0.4335964,0.04335964,0,0,0,0,0,0.3848437,0.3848437,0.3848437,0.4421452
23.2,0.3864062,0.4346116,0.04346116,0,0,0,0,0,0.3864062,0.3864062,0.3864062,0.4431805
23.3,0.388125,0.4359969,0.04359969,0,0,0,0,0,0.3881249,0.3881249,0.388125,0.4445931
23.4,0.3898437,0.4364658,0.04364658,0,0,0,0,0,0.3898437,0.3898437,0.3898437,0.4450712
23.5,0.3917187,0.4376802,0.04376802,0,0,0,0,0,0.3917187,0.3917187,0.3917187,0.4463096
23.6,0.3937499,0.4385317,0.04385317,0,0,0,0,0,0.39375,0.39375,0.3937499,0.4471779
23.7,0.3953124,0.4391949,0.04391949,0,0,0,0,0,0.3953124,0.3953124,0.3953124,0.4478541
23.8,0.3970312,0.4388279,0.04388279,0,0,0,0,0,0.3970312,0.3970312,0.3970312,0.4474799
23.9,0.3985937,0.4396198,0.04396198,0,0,0,0,0,0.3985937,0.3985937,0.3985937,0.4482875
24,0.4003124,0.4403898,0.04403898,0,0,0,0,0,0.4003125,0.4003125,0.4003124,0.4490726
24.1,0.4017187,0.4409667,0.04409667,0,0,0,0,0,0.4017187,0.4017187,0.4017187,0.4496609
24.2,0.4032812,0.4419426,0.04419426,0,0,0,0,0,0.4032812,0.4032812,0.4032812,0.450656
24.3,0.4046875,0.4415924,0.04415924,0,0,0,0,0,0.4046875,0.4046875,0.4046875,0.4502989
24.4,0.40625,0.4433718,0.04433718,0,0,0,0,0,0.4062499,0.4062499,0.40625,0.4521134
24.5,0.4079687,0.443984,0.0443984,0,0,0,0,0,0.4079687,0.4079687,0.4079687,0.4527377
24.6,0.4096874,0.4442368,0.04442368,0,0,0,0,0,0.4096874,0.4096874,0.4096874,0.4529955
24.7,0.4114062,0.4450972,0.04450972,0,0,0,0,0,0.4114062,0.4114062,0.4114062,0.4538728
24.8,0.4131249,0.4462847,0.04462847,0,0,0,0,0,0.4131249,0.4131249,0.4131249,0.4550838
24.9,0.4148437,0.4475499,0.04475499,0,0,0,0,0,0.4148437,0.4148437,0.4148437,0.4563738
25,0.4165625,0.4475926,0.04475925,0,0,0,0,0,0.4165625,0.4165625,0.4165625,0.4564174
25.1,0.4185937,0.4477572,0.04477572,0,0,0,0,0,0.4185937,0.4185937,0.4185937,0.4565853
25.2,0.4203125,0.4489499,0.04489499,0,0,0,0,0,0.4203125,0.4203125,0.4203125,0.4578015
25.3,0.4220312,0.4503005,0.04503005,0,0,0,0,0,0.4220312,0.4220312,0.4220312,0.4591787
25.4,0.4235937,0.4509589,0.04509589,0,0,0,0,0,0.4235937,0.4235937,0.4235937,0.4598501
25.5,0.4251562,0.451556,0.0451556,0,0,0,0,0,0.4251562,0.4251562,0.4251562,0.460459
25.6,0.4267187,0.4520855,0.04520855,0,0,0,0,0,0.4267187,0.4267187,0.4267187,0.4609989
25.7,0.4284375,0.453547,0.0453547,0,0,0,0,0,0.4284375,0.4284375,0.4284375,0.4624892
25.8,0.4301562,0.4535311,0.04535311,0,0,0,0,0,0.4301562,0.4301562,0.4301562,0.4624731
25.9,0.4318749,0.4547554,0.04547554,0,0,0,0,0,0.4318749,0.4318749,0.4318749,0.4637214
26,0.4334374,0.4548665,0.04548665,0,0,0,0,0,0.4334374,0.4334374,0.4334374,0.4638347
26.1,0.4349999,0.4560264,0.04560264,0,0,0,0,0,0.4349999,0.4349999,0.4349999,0.4650175
26.2,0.4365624,0.4567013,0.04567013,0,0,0,0,0,0.4365624,0.4365624,0.4365624,0.4657057
26.3,0.4382812,0.4569644,0.04569644,0,0,0,0,0,0.4382812,0.4382812,0.4382812,0.465974
26.4,0.4399999,0.4576162,0.04576162,0,0,0,0,0,0.4399999,0.4399999,0.4399999,0.4666386
26.5,0.4417187,0.4570939,0.04570939,0,0,0,0,0,0.4417187,0.4417187,0.4417187,0.4661061
26.6,0.4434375,0.4586845,0.04586845,0,0,0,0,0,0.4434375,0.4434375,0.4434375,0.467728
26.7,0.445,0.4588166,0.04588166,0,0,0,0,0,0.445,0.445,0.445,0.4678627
26.8,0.4465625,0.4596556,0.04596556,0,0,0,0,0,0.4465624,0.4465624,0.4465625,0.4687182
26.9,0.4484374,0.460878,0.0460878,0,0,0,0,0,0.4484374,0.4484374,0.4484374,0.4699648
27,0.4501562,0.4625083,0.04625084,0,0,0,0,0,0.4501562,0.4501562,0.4501562,0.4716273
27.1,0.4518749,0.4631632,0.04631633,0,0,0,0,0,0.4518749,0.4518749,0.4518749,0.4722951
27.2,0.4534374,0.4642498,0.04642498,0,0,0,0,0,0.4534374,0.4534374,0.4534374,0.4734031
27.3,0.4548437,0.4646699,0.04646699,0,0,0,0,0,0.4548437,0.4548437,0.4548437,0.4738314
27.4,0.4564062,0.4655649,0.0465565,0,0,0,0,0,0.4564062,0.4564062,0.4564062,0.4747441
27.5,0.4581249,0.4660844,0.04660844,0,0,0,0,0,0.4581249,0.4581249,0.4581249,0.4752738
27.6,0.4598437,0.4670675,0.04670675,0,0,0,0,0,0.4598437,0.4598437,0.4598437,0.4762763
27.7,0.4614062,0.4672075,0.04672075,0,0,0,0,0,0.4614062,0.4614062,0.4614062,0.476419
27.8,0.4629687,0.4670404,0.04670404,0,0,0,0,0,0.4629687,0.4629687,0.4629687,0.4762487
27.9,0.4646874,0.4671898,0.04671898,0,0,0,0,0,0.4646874,0.4646874,0.4646874,0.476401
28,0.4664062,0.4683184,0.04683184,0,0,0,0,0,0.4664062,0.4664062,0.4664062,0.4775518
28.1,0.4679687,0.4695497,0.04695497,0,0,0,0,0,0.4679687,0.4679687,0.4679687,0.4788075
28.2,0.4698437,0.4704938,0.04704938,0,0,0,0,0,0.4698437,0.4698437,0.4698437,0.4797702
28.3,0.4715624,0.4710484,0.04710484,0,0,0,0,0,0.4715624,0.4715624,0.4715624,0.4803357
28.4,0.4732812,0.4725703,0.04725703,0,0,0,0,0,0.4732812,0.4732812,0.4732812,0.4818876
28.5,0.4751562,0.4731637,0.04731637,0,0,0,0,0,0.4751562,0.4751562,0.4751562,0.4824927
28.6,0.4770312,0.4735428,0.04735428,0,0,0,0,0,0.4770312,0.4770312,0.4770312,0.4828793
28.7,0.4787499,0.4739899,0.04739899,0,0,0,0,0,0.47875,0.47875,0.4787499,0.4833352
28.8,0.4804687,0.4742845,0.04742846,0,0,0,0,0,0.4804687,0.4804687,0.4804687,0.4836356
28.9,0.4820312,0.474408,0.0474408,0,0,0,0,0,0.4820312,0.4820312,0.4820312,0.4837616
29,0.4834374,0.4750594,0.04750594,0,0,0,0,0,0.4834374,0.4834374,0.4834374,0.4844258
29.1,0.4849999,0.4761482,0.04761482,0,0,0,0,0,0.4849999,0.4849999,0.4849999,0.485536
29.2,0.4865624,0.4768621,0.04768621,0,0,0,0,0,0.4865624,0.4865624,0.4865624,0.486264
29.3,0.4881249,0.4773294,0.04773294,0,0,0,0,0,0.4881249,0.4881249,0.4881249,0.4867405
29.4,0.4896874,0.4768825,0.04768825,0,0,0,0,0,0.4896874,0.4896874,0.4896874,0.4862848
29.5,0.4914061,0.4780483,0.04780483,0,0,0,0,0,0.4914061,0.4914061,0.4914061,0.4874735
29.6,0.4929687,0.4790395,0.04790395,0,0,0,0,0,0.4929686,0.4929686,0.4929687,0.4884844
29.7,0.4946874,0.4798776,0.04798776,0,0,0,0,0,0.4946874,0.4946874,0.4946874,0.4893389
29.8,0.4964062,0.4813095,0.04813095,0,0,0,0,0,0.4964062,0.4964062,0.4964062,0.4907991
29.9,0.4981249,0.4818515,0.04818515,0,0,0,0,0,0.4981249,0.4981249,0.4981249,0.4913518
30,0.4998437,0.4831018,0.04831018,0,0,0,0,0,0.4998437,0.4998437,0.4998437,0.4926267
30.1,0.5014061,0.4841027,0.04841027,0,0,0,0,0,0.5014061,0.5014061,0.5014061,0.4936474
30.2,0.5031249,0.4851687,0.04851687,0,0,0,0,0,0.5031249,0.5031249,0.5031249,0.4947344
30.3,0.5049999,0.4854535,0.04854535,0,0,0,0,0,0.5049999,0.5049999,0.5049999,0.4950248
30.4,0.5067186,0.4867531,0.04867531,0,0,0,0,0,0.5067186,0.5067186,0.5067186,0.49635
30.5,0.5085936,0.4878279,0.04878279,0,0,0,0,0,0.5085936,0.5085936,0.5085936,0.4974461
30.6,0.5101562,0.4886401,0.04886401,0,0,0,0,0,0.5101562,0.5101562,0.5101562,0.4982742
30.7,0.5115624,0.4889547,0.04889547,0,0,0,0,0,0.5115624,0.5115624,0.5115624,0.498595
30.8,0.5132811,0.4901091,0.04901091,0,0,0,0,0,0.5132812,0.5132812,0.5132811,0.4997722
30.9,0.5149999,0.4907305,0.04907305,0,0,0,0,0,0.5149999,0.5149999,0.5149999,0.5004058
31,0.5165624,0.4910412,0.04910412,0,0,0,0,0,0.5165624,0.5165624,0.5165624,0.5007226
31.1,0.5182811,0.4922181,0.04922181,0,0,0,0,0,0.5182811,0.5182811,0.5182811,0.5019228
31.2,0.5198437,0.4912613,0.04912613,0,0,0,0,0,0.5198436,0.5198436,0.5198437,0.5009472
31.3,0.5215624,0.492274,0.0492274,0,0,0,0,0,0.5215624,0.5215624,0.5215624,0.5019798
31.4,0.5232812,0.4926709,0.04926709,0,0,0,0,0,0.5232812,0.5232812,0.5232812,0.5023845
31.5,0.5248436,0.49308,0.049308,0,0,0,0,0,0.5248436,0.5248436,0.5248436,0.5028017
31.6,0.5262499,0.493292,0.0493292,0,0,0,0,0,0.5262499,0.5262499,0.5262499,0.5030178
31.7,0.5279686,0.4941758,0.04941758,0,0,0,0,0,0.5279686,0.5279686,0.5279686,0.5039191
31.8,0.5298437,0.4942834,0.04942834,0,0,0,0,0,0.5298437,0.5298437,0.5298437,0.5040289
31.9,0.5315624,0.4948553,0.04948553,0,0,0,0,0,0.5315624,0.5315624,0.5315624,0.504612
32,0.5334374,0.4953149,0.04953149,0,0,0,0,0,0.5334374,0.5334374,0.5334374,0.5050806
32.1,0.5351562,0.4961951,0.04961951,0,0,0,0,0,0.5351562,0.5351562,0.5351562,0.5059782
32.2,0.5368749,0.4968757,0.04968757,0,0,0,0,0,0.5368749,0.5368749,0.5368749,0.5066722
32.3,0.5384374,0.4974816,0.04974816,0,0,0,0,0,0.5384374,0.5384374,0.5384374,0.5072901
32.4,0.5401562,0.4978872,0.04978872,0,0,0,0,0,0.5401561,0.5401561,0.5401562,0.5077037
32.5,0.5417187,0.4978725,0.04978725,0,0,0,0,0,0.5417187,0.5417187,0.5417187,0.5076886
32.6,0.5432811,0.498743,0.0498743,0,0,0,0,0,0.5432811,0.5432811,0.5432811,0.5085763
32.7,0.5448437,0.4988651,0.04988651,0,0,0,0,0,0.5448437,0.5448437,0.5448437,0.5087008
32.8,0.5465624,0.4992227,0.04992227,0,0,0,0,0,0.5465624,0.5465624,0.5465624,0.5090655
32.9,0.5481249,0.5002436,0.05002436,0,0,0,0,0,0.5481249,0.5481249,0.5481249,0.5101065
33,0.5496874,0.5008017,0.05008017,0,0,0,0,0,0.5496874,0.5496874,0.5496874,0.5106756
33.1,0.5514062,0.5011167,0.05011167,0,0,0,0,0,0.5514062,0.5514062,0.5514062,0.5109968
33.2,0.5531249,0.5023456,0.05023456,0,0,0,0,0,0.5531249,0.5531249,0.5531249,0.5122499
33.3,0.5548436,0.5031361,0.05031361,0,0,0,0,0,0.5548436,0.5548436,0.5548436,0.513056
33.4,0.5564062,0.5040212,0.05040212,0,0,0,0,0,0.5564061,0.5564061,0.5564062,0.5139586
33.5,0.5581249,0.5047053,0.05047053,0,0,0,0,0,0.5581249,0.5581249,0.5581249,0.5146562
33.6,0.5599999,0.5055445,0.05055445,0,0,0,0,0,0.5599999,0.5599999,0.5599999,0.5155119
33.7,0.5620312,0.5068596,0.05068596,0,0,0,0,0,0.5620311,0.5620311,0.5620312,0.516853
33.8,0.5639062,0.5073818,0.05073819,0,0,0,0,0,0.5639061,0.5639061,0.5639062,0.5173855
33.9,0.5654686,0.5076683,0.05076683,0,0,0,0,0,0.5654686,0.5654686,0.5654686,0.5176775
34,0.5667186,0.5085841,0.05085841,0,0,0,0,0,0.5667186,0.5667186,0.5667186,0.5186114
34.1,0.5681249,0.5086568,0.05086568,0,0,0,0,0,0.5681249,0.5681249,0.5681249,0.5186856
34.2,0.5696874,0.5090547,0.05090547,0,0,0,0,0,0.5696874,0.5696874,0.5696874,0.5190914
34.3,0.5714062,0.5099551,0.05099551,0,0,0,0,0,0.5714061,0.5714061,0.5714062,0.5200095
34.4,0.5731249,0.5107072,0.05107072,0,0,0,0,0,0.5731249,0.5731249,0.5731249,0.5207765
34.5,0.5746874,0.5114453,0.05114453,0,0,0,0,0,0.5746874,0.5746874,0.5746874,0.5215291
34.6,0.5762499,0.5116676,0.05116675,0,0,0,0,0,0.5762499,0.5762499,0.5762499,0.5217557
34.7,0.5779687,0.5128173,0.05128173,0,0,0,0,0,0.5779687,0.5779687,0.5779687,0.5229281
34.8,0.5796874,0.5132089,0.05132089,0,0,0,0,0,0.5796874,0.5796874,0.5796874,0.5233274
34.9,0.5814062,0.5142596,0.05142596,0,0,0,0,0,0.5814062,0.5814062,0.5814062,0.5243989
35,0.5831249,0.5156951,0.05156951,0,0,0,0,0,0.5831249,0.5831249,0.5831249,0.5258626
35.1,0.5848436,0.5158472,0.05158472,0,0,0,0,0,0.5848436,0.5848436,0.5848436,0.5260178
35.2,0.5865624,0.5163249,0.05163249,0,0,0,0,0,0.5865624,0.5865624,0.5865624,0.5265049
35.3,0.5884374,0.5181096,0.05181096,0,0,0,0,0,0.5884374,0.5884374,0.5884374,0.5283247
35.4,0.5903124,0.5193133,0.05193133,0,0,0,0,0,0.5903124,0.5903124,0.5903124,0.5295522
35.5,0.5920312,0.5197952,0.05197952,0,0,0,0,0,0.5920312,0.5920312,0.5920312,0.5300435
35.6,0.5935936,0.5210652,0.05210652,0,0,0,0,0,0.5935937,0.5935937,0.5935936,0.5313386
35.7,0.5951562,0.5208739,0.05208739,0,0,0,0,0,0.5951561,0.5951561,0.5951562,0.5311435
35.8,0.5967186,0.520965,0.0520965,0,0,0,0,0,0.5967186,0.5967186,0.5967186,0.5312365
35.9,0.5984374,0.5223123,0.05223123,0,0,0,0,0,0.5984374,0.5984374,0.5984374,0.5326104
36,0.6001561,0.5229494,0.05229494,0,0,0,0,0,0.6001561,0.6001561,0.6001561,0.53326
36.1,0.6017187,0.5234356,0.05234355,0,0,0,0,0,0.6017187,0.6017187,0.6017187,0.5337557
36.2,0.6035937,0.524762,0.0524762,0,0,0,0,0,0.6035936,0.6035936,0.6035937,0.5351084
36.3,0.6051561,0.524722,0.0524722,0,0,0,0,0,0.6051561,0.6051561,0.6051561,0.5350676
36.4,0.6067186,0.5251045,0.05251045,0,0,0,0,0,0.6067187,0.6067187,0.6067186,0.5354576
36.5,0.6082812,0.5254731,0.05254731,0,0,0,0,0,0.6082812,0.6082812,0.6082812,0.5358334
36.6,0.6096874,0.5256975,0.05256975,0,0,0,0,0,0.6096874,0.6096874,0.6096874,0.5360623
36.7,0.6112499,0.5266578,0.05266578,0,0,0,0,0,0.6112499,0.6112499,0.6112499,0.5370415
36.8,0.6131249,0.5279427,0.05279427,0,0,0,0,0,0.6131249,0.6131249,0.6131249,0.5383518
36.9,0.6148436,0.5294268,0.05294269,0,0,0,0,0,0.6148436,0.6148436,0.6148436,0.5398651
37,0.6164061,0.5294406,0.05294406,0,0,0,0,0,0.6164061,0.6164061,0.6164061,0.5398791
37.1,0.6181249,0.5312378,0.05312378,0,0,0,0,0,0.6181249,0.6181249,0.6181249,0.5417117
37.2,0.6199999,0.5316823,0.05316823,0,0,0,0,0,0.6199999,0.6199999,0.6199999,0.5421651
37.3,0.6218749,0.5322835,0.05322836,0,0,0,0,0,0.6218749,0.6218749,0.6218749,0.5427781
37.4,0.6234374,0.5331108,0.05331108,0,0,0,0,0,0.6234374,0.6234374,0.6234374,0.5436217
37.5,0.6251562,0.5336336,0.05336336,0,0,0,0,0,0.6251562,0.6251562,0.6251562,0.5441548
37.6,0.6267186,0.5346844,0.05346844,0,0,0,0,0,0.6267186,0.6267186,0.6267186,0.5452264
37.7,0.6284374,0.5349275,0.05349275,0,0,0,0,0,0.6284374,0.6284374,0.6284374,0.5454743
37.8,0.6298436,0.5353807,0.05353808,0,0,0,0,0,0.6298436,0.6298436,0.6298436,0.5459364
37.9,0.6314061,0.5352386,0.05352386,0,0,0,0,0,0.6314061,0.6314061,0.6314061,0.5457915
38,0.6329687,0.5356254,0.05356254,0,0,0,0,0,0.6329687,0.6329687,0.6329687,0.5461859
38.1,0.6346874,0.5363471,0.05363471,0,0,0,0,0,0.6346874,0.6346874,0.6346874,0.5469218
38.2,0.6364061,0.5372285,0.05372285,0,0,0,0,0,0.6364061,0.6364061,0.6364061,0.5478206
38.3,0.6381249,0.5387563,0.05387563,0,0,0,0,0,0.6381249,0.6381249,0.6381249,0.5493785
38.4,0.6398436,0.5390787,0.05390787,0,0,0,0,0,0.6398436,0.6398436,0.6398436,0.5497074
38.5,0.6415624,0.5395767,0.05395767,0,0,0,0,0,0.6415624,0.6415624,0.6415624,0.5502151
38.6,0.6434374,0.5402784,0.05402784,0,0,0,0,0,0.6434374,0.6434374,0.6434374,0.5509307
38.7,0.6453124,0.5392824,0.05392824,0,0,0,0,0,0.6453124,0.6453124,0.6453124,0.549915
38.8,0.6470311,0.5411492,0.05411492,0,0,0,0,0,0.6470311,0.6470311,0.6470311,0.5518186
38.9,0.6487499,0.5416667,0.05416667,0,0,0,0,0,0.6487499,0.6487499,0.6487499,0.5523463
39,0.6503124,0.5417923,0.05417924,0,0,0,0,0,0.6503124,0.6503124,0.6503124,0.5524744
39.1,0.6517186,0.5422818,0.05422818,0,0,0,0,0,0.6517186,0.6517186,0.6517186,0.5529736
39.2,0.6532812,0.5429761,0.05429761,0,0,0,0,0,0.6532812,0.6532812,0.6532812,0.5536816
39.3,0.6549999,0.5436252,0.05436252,0,0,0,0,0,0.6549999,0.6549999,0.6549999,0.5543434
39.4,0.6567186,0.5443326,0.05443326,0,0,0,0,0,0.6567186,0.6567186,0.6567186,0.5550648
39.5,0.6582811,0.5448809,0.05448809,0,0,0,0,0,0.6582811,0.6582811,0.6582811,0.5556239
39.6,0.6598437,0.5453165,0.05453165,0,0,0,0,0,0.6598437,0.6598437,0.6598437,0.5560681
39.7,0.6614061,0.5462445,0.05462445,0,0,0,0,0,0.6614062,0.6614062,0.6614061,0.5570143
39.8,0.6631249,0.547402,0.0547402,0,0,0,0,0,0.6631249,0.6631249,0.6631249,0.5581947
39.9,0.6646874,0.5479554,0.05479554,0,0,0,0,0,0.6646874,0.6646874,0.6646874,0.558759
40,0.6664061,0.5484133,0.05484133,0,0,0,0,0,0.6664061,0.6664061,0.6664061,0.5592259
40.1,0.6681249,0.5492291,0.05492292,0,0,0,0,0,0.6681249,0.6681249,0.6681249,0.5600579
40.2,0.6698436,0.5495869,0.05495869,0,0,0,0,0,0.6698436,0.6698436,0.6698436,0.5604227
40.3,0.6715624,0.5500185,0.05500185,0,0,0,0,0,0.6715624,0.6715624,0.6715624,0.5608628
40.4,0.6731249,0.5511994,0.05511994,0,0,0,0,0,0.6731249,0.6731249,0.6731249,0.562067
40.5,0.6749999,0.5515889,0.05515889,0,0,0,0,0,0.6749999,0.6749999,0.6749999,0.5624641
40.6,0.6767187,0.5522944,0.05522944,0,0,0,0,0,0.6767187,0.6767187,0.6767187,0.5631835
40.7,0.6785936,0.5524414,0.05524414,0,0,0,0,0,0.6785936,0.6785936,0.6785936,0.5633335
40.8,0.6801562,0.5531193,0.05531193,0,0,0,0,0,0.6801562,0.6801562,0.6801562,0.5640247
40.9,0.6817186,0.5539404,0.05539404,0,0,0,0,0,0.6817186,0.6817186,0.6817186,0.564862
41,0.6834374,0.5548862,0.05548862,0,0,0,0,0,0.6834374,0.6834374,0.6834374,0.5658265
41.1,0.6851561,0.5555408,0.05555408,0,0,0,0,0,0.6851562,0.6851562,0.6851561,0.5664939
41.2,0.6867186,0.5561632,0.05561632,0,0,0,0,0,0.6867186,0.6867186,0.6867186,0.5671286
41.3,0.6884374,0.556635,0.0556635,0,0,0,0,0,0.6884373,0.6884373,0.6884374,0.5676097
41.4,0.6899999,0.5573373,0.05573373,0,0,0,0,0,0.6899999,0.6899999,0.6899999,0.5683259
41.5,0.6917187,0.5577388,0.05577388,0,0,0,0,0,0.6917186,0.6917186,0.6917187,0.5687353
41.6,0.6931249,0.5589726,0.05589726,0,0,0,0,0,0.6931249,0.6931249,0.6931249,0.5699934
41.7,0.6946874,0.5588652,0.05588651,0,0,0,0,0,0.6946874,0.6946874,0.6946874,0.5698839
41.8,0.6962499,0.5596075,0.05596075,0,0,0,0,0,0.6962499,0.6962499,0.6962499,0.5706409
41.9,0.6981249,0.561093,0.0561093,0,0,0,0,0,0.6981249,0.6981249,0.6981249,0.5721556
42,0.6998436,0.561989,0.0561989,0,0,0,0,0,0.6998436,0.6998436,0.6998436,0.5730693
42.1,0.7015624,0.5627668,0.05627669,0,0,0,0,0,0.7015624,0.7015624,0.7015624,0.5738625
42.2,0.7034374,0.5640655,0.05640655,0,0,0,0,0,0.7034374,0.7034374,0.7034374,0.5751868
42.3,0.7053124,0.5653644,0.05653644,0,0,0,0,0,0.7053124,0.7053124,0.7053124,0.5765113
42.4,0.7070312,0.5660718,0.05660718,0,0,0,0,0,0.7070312,0.7070312,0.7070312,0.5772326
42.5,0.7084374,0.5669506,0.05669506,0,0,0,0,0,0.7084374,0.7084374,0.7084374,0.5781288
42.6,0.7099999,0.5675777,0.05675777,0,0,0,0,0,0.7099999,0.7099999,0.7099999,0.5787682
42.7,0.7117186,0.5689103,0.05689103,0,0,0,0,0,0.7117186,0.7117186,0.7117186,0.580127
42.8,0.7134374,0.5695074,0.05695074,0,0,0,0,0,0.7134374,0.7134374,0.7134374,0.5807359
42.9,0.7149999,0.5706022,0.05706022,0,0,0,0,0,0.7149999,0.7149999,0.7149999,0.5818523
43,0.7165624,0.5712471,0.05712471,0,0,0,0,0,0.7165624,0.7165624,0.7165624,0.5825099
43.1,0.7182811,0.5720384,0.05720384,0,0,0,0,0,0.7182811,0.7182811,0.7182811,0.5833169
43.2,0.7196874,0.5718881,0.05718881,0,0,0,0,0,0.7196874,0.7196874,0.7196874,0.5831636
43.3,0.7214061,0.5728622,0.05728621,0,0,0,0,0,0.7214062,0.7214062,0.7214061,0.5841568
43.4,0.7231249,0.5729539,0.05729539,0,0,0,0,0,0.7231249,0.7231249,0.7231249,0.5842504
43.5,0.7248436,0.5741706,0.05741706,0,0,0,0,0,0.7248436,0.7248436,0.7248436,0.5854911
43.6,0.7265624,0.575553,0.0575553,0,0,0,0,0,0.7265624,0.7265624,0.7265624,0.5869007
43.7,0.7282812,0.5758188,0.05758188,0,0,0,0,0,0.7282811,0.7282811,0.7282812,0.5871718
43.8,0.7301561,0.5767589,0.05767589,0,0,0,0,0,0.7301561,0.7301561,0.7301561,0.5881305
43.9,0.7320311,0.57849,0.057849,0,0,0,0,0,0.7320311,0.7320311,0.7320311,0.5898957
44,0.7339062,0.5792906,0.05792906,0,0,0,0,0,0.7339061,0.7339061,0.7339062,0.590712
44.1,0.7353124,0.579535,0.0579535,0,0,0,0,0,0.7353124,0.7353124,0.7353124,0.5909613
44.2,0.7365624,0.5800982,0.05800983,0,0,0,0,0,0.7365624,0.7365624,0.7365624,0.5915356
44.3,0.7381249,0.5806618,0.05806618,0,0,0,0,0,0.7381249,0.7381249,0.7381249,0.5921102
44.4,0.7398436,0.5808006,0.05808006,0,0,0,0,0,0.7398437,0.7398437,0.7398436,0.5922518
44.5,0.7415624,0.5826399,0.05826399,0,0,0,0,0,0.7415624,0.7415624,0.7415624,0.5941273
44.578,0.7428124,0.5826868,0.05826868,0,0,0,0,0,0.7428124,0.7428124,0.7428124,0.5941752