File: dataFiles_day2/staticInstron_5.raw
"Test Type","Tension"
"Method Name","C:\Users\mmen339\Documents\tension test 1mm_s.im_tens"
"Sample name","C:\Users\mmen339\Documents\sample 4\S4.100%Extension_1.is_tens"
"User",""
"Sample note 1",""
"Sample note 2",""
"Sample note 3",""
"Geometry","Rectangular"
"Specimen",1
"Specimen label",""
"Width",10.000000,"mm"
"Thickness",1.000000,"mm"
"Length",100.000000,"mm"
"Diameter",10.000000,"mm"
"Inner diameter",8.000000,"mm"
"Outer diameter",10.000000,"mm"
"Wall thickness",1.000000,"mm"
"Area",0.100000,"cm^2"
"Linear density",100.000000,"tex"
"Sled weight",10.000000,"N"
"Loading span",10.000000,"mm"
"Support span",100.000000,"mm"
"Span ratio","2"
"Fixture type","4-point"
"Included"
"Final width",10.000000,"mm"
"Final thickness",1.000000,"mm"
"Final length",100.000000,"mm"
"Final diameter",10.000000,"mm"
"Final Inner diameter",8.000000,"mm"
"Final outer diameter",10.000000,"mm"
"Final wall thickness",1.000000,"mm"
"Final area",0.100000,"cm^2"
"Final linear density",100.000000,"tex"
"Custom text input  1",""
"Custom text input  2",""
"Custom text input  3",""
"Custom text input  4",""
"Custom text input  5",""
"Custom text input  6",""
"Custom text input  7",""
"Custom text input  8",""
"Custom text input  9",""
"Custom text input 10",""
"Custom text input 11",""
"Custom text input 12",""
"Custom text input 13",""
"Custom text input 14",""
"Custom text input 15",""
"Custom text input 16",""
"Custom text input 17",""
"Custom text input 18",""
"Custom text input 19",""
"Custom text input 20",""
"Custom text input 21",""
"Custom text input 22",""
"Custom text input 23",""
"Custom text input 24",""
"Custom text input 25",""
"Custom text input 26",""
"Custom text input 27",""
"Custom text input 28",""
"Custom text input 29",""
"Custom text input 30",""
"Custom text input 31",""
"Custom text input 32",""
"Custom text input 33",""
"Custom text input 34",""
"Custom text input 35",""
"Custom text input 36",""
"Custom text input 37",""
"Custom text input 38",""
"Custom text input 39",""
"Custom text input 40",""
"Custom text input 41",""
"Custom text input 42",""
"Custom text input 43",""
"Custom text input 44",""
"Custom text input 45",""
"Custom text input 46",""
"Custom text input 47",""
"Custom text input 48",""
"Custom text input 49",""
"Custom text input 50",""
"Custom number input  1",0.000000,""
"Custom number input  2",0.000000,""
"Custom number input  3",0.000000,""
"Custom number input  4",0.000000,""
"Custom number input  5",0.000000,""
"Custom number input  6",0.000000,""
"Custom number input  7",0.000000,""
"Custom number input  8",0.000000,""
"Custom number input  9",0.000000,""
"Custom number input 10",0.000000,""
"Time sec","Extension mm","Load N","Tensile stress MPa","Cycle Count ","Total Cycle Count ","Repetitions Count ","Marked Data ","PIP Count ","Tensile extension mm","Tensile strain %","Corrected Position mm","Tenacity gf/tex"
0,0,0.002111835,0.0002111835,0,0,0,0,0,0,0,0,0.002153473
0.4,0.004531249,0.0638701,0.00638701,0,0,0,0,0,0.004531249,0.004531249,0.004531249,0.06512937
0.8,0.0128125,0.1596804,0.01596804,0,0,0,0,0,0.0128125,0.0128125,0.0128125,0.1628287
1.2,0.01953125,0.2162175,0.02162175,0,0,0,0,0,0.01953125,0.01953125,0.01953125,0.2204805
1.6,0.026875,0.2698568,0.02698568,0,0,0,0,0,0.026875,0.026875,0.026875,0.2751774
2,0.03359374,0.308562,0.0308562,0,0,0,0,0,0.03359374,0.03359374,0.03359374,0.3146457
2.4,0.04,0.3430274,0.03430274,0,0,0,0,0,0.04,0.04,0.04,0.3497906
2.8,0.04624999,0.3725671,0.03725671,0,0,0,0,0,0.04624999,0.04624999,0.04624999,0.3799127
3.2,0.05312499,0.4060733,0.04060733,0,0,0,0,0,0.05312499,0.05312499,0.05312499,0.4140795
3.6,0.05999999,0.4345539,0.0434554,0,0,0,0,0,0.05999999,0.05999999,0.05999999,0.4431217
4,0.06640624,0.4590518,0.04590518,0,0,0,0,0,0.06640624,0.06640624,0.06640624,0.4681025
4.4,0.07312499,0.4828979,0.04828979,0,0,0,0,0,0.07312499,0.07312499,0.07312499,0.4924188
4.8,0.08031249,0.5071882,0.05071882,0,0,0,0,0,0.08031248,0.08031248,0.08031249,0.517188
5.2,0.08671873,0.5252333,0.05252333,0,0,0,0,0,0.08671873,0.08671873,0.08671873,0.5355889
5.6,0.09312499,0.543882,0.0543882,0,0,0,0,0,0.09312499,0.09312499,0.09312499,0.5546052
6,0.09953124,0.561808,0.0561808,0,0,0,0,0,0.09953123,0.09953123,0.09953124,0.5728848
6.4,0.1064062,0.5808827,0.05808827,0,0,0,0,0,0.1064062,0.1064062,0.1064062,0.5923355
6.8,0.1135937,0.6002802,0.06002802,0,0,0,0,0,0.1135937,0.1135937,0.1135937,0.6121154
7.2,0.12,0.6131446,0.06131446,0,0,0,0,0,0.12,0.12,0.12,0.6252334
7.6,0.1260937,0.6264615,0.06264615,0,0,0,0,0,0.1260937,0.1260937,0.1260937,0.638813
8,0.1329687,0.6425958,0.06425957,0,0,0,0,0,0.1329687,0.1329687,0.1329687,0.6552653
8.400001,0.1401562,0.6601299,0.06601299,0,0,0,0,0,0.1401562,0.1401562,0.1401562,0.6731451
8.8,0.1465625,0.670995,0.0670995,0,0,0,0,0,0.1465625,0.1465625,0.1465625,0.6842244
9.200001,0.1532812,0.6844827,0.06844827,0,0,0,0,0,0.1532812,0.1532812,0.1532812,0.6979781
9.6,0.1596875,0.6952691,0.06952691,0,0,0,0,0,0.1596875,0.1596875,0.1596875,0.7089772
10,0.1664062,0.7074112,0.07074112,0,0,0,0,0,0.1664062,0.1664062,0.1664062,0.7213587
10.4,0.173125,0.7203704,0.07203704,0,0,0,0,0,0.173125,0.173125,0.173125,0.7345734
10.8,0.1796875,0.7328558,0.07328558,0,0,0,0,0,0.1796875,0.1796875,0.1796875,0.747305
11.2,0.18625,0.7437523,0.07437523,0,0,0,0,0,0.18625,0.18625,0.18625,0.7584163
11.6,0.1932812,0.7549548,0.07549547,0,0,0,0,0,0.1932812,0.1932812,0.1932812,0.7698396
12,0.2003125,0.7647603,0.07647603,0,0,0,0,0,0.2003125,0.2003125,0.2003125,0.7798385
12.4,0.2065625,0.771792,0.07717919,0,0,0,0,0,0.2065625,0.2065625,0.2065625,0.7870088
12.8,0.2128125,0.781396,0.0781396,0,0,0,0,0,0.2128125,0.2128125,0.2128125,0.7968022
13.2,0.2196875,0.7921015,0.07921015,0,0,0,0,0,0.2196875,0.2196875,0.2196875,0.8077188
13.6,0.2267187,0.8040071,0.08040071,0,0,0,0,0,0.2267187,0.2267187,0.2267187,0.8198591
14,0.2332812,0.8125948,0.08125947,0,0,0,0,0,0.2332812,0.2332812,0.2332812,0.8286161
14.4,0.2398437,0.8176887,0.08176887,0,0,0,0,0,0.2398437,0.2398437,0.2398437,0.8338104
14.8,0.2464062,0.8268775,0.08268775,0,0,0,0,0,0.2464062,0.2464062,0.2464062,0.8431804
15.2,0.2532812,0.8372898,0.08372898,0,0,0,0,0,0.2532812,0.2532812,0.2532812,0.853798
15.6,0.2598437,0.8460147,0.08460148,0,0,0,0,0,0.2598437,0.2598437,0.2598437,0.8626949
16,0.2664062,0.8545497,0.08545496,0,0,0,0,0,0.2664062,0.2664062,0.2664062,0.8713982
16.4,0.2729687,0.8630563,0.08630563,0,0,0,0,0,0.2729687,0.2729687,0.2729687,0.8800725
16.8,0.2801562,0.8736012,0.08736011,0,0,0,0,0,0.2801562,0.2801562,0.2801562,0.8908253
17.2,0.2868749,0.8807689,0.08807689,0,0,0,0,0,0.2868749,0.2868749,0.2868749,0.8981344
17.6,0.2929687,0.8867123,0.08867123,0,0,0,0,0,0.2929687,0.2929687,0.2929687,0.904195
18,0.2995312,0.8963233,0.08963233,0,0,0,0,0,0.2995312,0.2995312,0.2995312,0.9139954
18.4,0.3065625,0.9052915,0.09052914,0,0,0,0,0,0.3065625,0.3065625,0.3065625,0.9231403
18.8,0.3134375,0.9128527,0.09128527,0,0,0,0,0,0.3134375,0.3134375,0.3134375,0.9308507
19.2,0.3201562,0.9181867,0.09181868,0,0,0,0,0,0.3201562,0.3201562,0.3201562,0.9362899
19.6,0.3267187,0.9243425,0.09243425,0,0,0,0,0,0.3267187,0.3267187,0.3267187,0.9425671
20,0.3331249,0.9319407,0.09319407,0,0,0,0,0,0.3331249,0.3331249,0.3331249,0.9503151
20.4,0.3401562,0.9420679,0.09420679,0,0,0,0,0,0.3401562,0.3401562,0.3401562,0.9606419
20.8,0.3467187,0.9487635,0.09487636,0,0,0,0,0,0.3467187,0.3467187,0.3467187,0.9674696
21.2,0.3529687,0.954786,0.0954786,0,0,0,0,0,0.3529687,0.3529687,0.3529687,0.9736108
21.6,0.3598437,0.9638477,0.09638477,0,0,0,0,0,0.3598437,0.3598437,0.3598437,0.9828511
22,0.3670312,0.9718399,0.09718399,0,0,0,0,0,0.3670312,0.3670312,0.3670312,0.9910008
22.4,0.3734374,0.9766897,0.09766898,0,0,0,0,0,0.3734374,0.3734374,0.3734374,0.9959463
22.8,0.3796874,0.9829278,0.09829278,0,0,0,0,0,0.3796874,0.3796874,0.3796874,1.002307
23.2,0.3862499,0.9918615,0.09918615,0,0,0,0,0,0.3862499,0.3862499,0.3862499,1.011417
23.6,0.3931249,1.000468,0.1000468,0,0,0,0,0,0.3931249,0.3931249,0.3931249,1.020194
24,0.4,1.009344,0.1009344,0,0,0,0,0,0.3999999,0.3999999,0.4,1.029244
24.4,0.4067187,1.014206,0.1014206,0,0,0,0,0,0.4067187,0.4067187,0.4067187,1.034202
24.8,0.4131249,1.018954,0.1018954,0,0,0,0,0,0.4131249,0.4131249,0.4131249,1.039044
25.2,0.4198437,1.025968,0.1025968,0,0,0,0,0,0.4198437,0.4198437,0.4198437,1.046196
25.6,0.4267187,1.034904,0.1034904,0,0,0,0,0,0.4267187,0.4267187,0.4267187,1.055308
26,0.4332812,1.041361,0.1041361,0,0,0,0,0,0.4332812,0.4332812,0.4332812,1.061892
26.4,0.4396875,1.046755,0.1046755,0,0,0,0,0,0.4396875,0.4396875,0.4396875,1.067394
26.8,0.4465625,1.053527,0.1053527,0,0,0,0,0,0.4465624,0.4465624,0.4465625,1.074299
27.2,0.4537499,1.059388,0.1059388,0,0,0,0,0,0.4537499,0.4537499,0.4537499,1.080275
27.6,0.4598437,1.063489,0.1063489,0,0,0,0,0,0.4598437,0.4598437,0.4598437,1.084457
28,0.4662499,1.06899,0.106899,0,0,0,0,0,0.4662499,0.4662499,0.4662499,1.090066
28.4,0.4729687,1.076045,0.1076045,0,0,0,0,0,0.4729687,0.4729687,0.4729687,1.09726
28.8,0.48,1.082105,0.1082105,0,0,0,0,0,0.48,0.48,0.48,1.10344
29.2,0.4867187,1.020818,0.1020818,0,0,0,0,0,0.4867187,0.4867187,0.4867187,1.040944
29.6,0.4932812,1.020911,0.1020911,0,0,0,0,0,0.4932812,0.4932812,0.4932812,1.04104
30,0.4996874,1.026191,0.1026191,0,0,0,0,0,0.4996874,0.4996874,0.4996874,1.046424
30.4,0.5064061,1.035449,0.1035449,0,0,0,0,0,0.5064061,0.5064061,0.5064061,1.055864
30.8,0.5131249,1.043985,0.1043985,0,0,0,0,0,0.5131249,0.5131249,0.5131249,1.064569
31.2,0.5196874,1.052033,0.1052033,0,0,0,0,0,0.5196874,0.5196874,0.5196874,1.072775
31.6,0.5264062,1.059815,0.1059815,0,0,0,0,0,0.5264062,0.5264062,0.5264062,1.08071
32,0.5334374,1.069126,0.1069126,0,0,0,0,0,0.5334374,0.5334374,0.5334374,1.090205
32.4,0.5403124,1.077203,0.1077203,0,0,0,0,0,0.5403124,0.5403124,0.5403124,1.098441
32.8,0.5464061,1.083761,0.1083761,0,0,0,0,0,0.5464061,0.5464061,0.5464061,1.105129
33.2,0.5529686,1.092858,0.1092858,0,0,0,0,0,0.5529686,0.5529686,0.5529686,1.114405
33.6,0.5595312,1.101061,0.1101061,0,0,0,0,0,0.5595312,0.5595312,0.5595312,1.12277
34,0.5667186,1.111463,0.1111463,0,0,0,0,0,0.5667186,0.5667186,0.5667186,1.133377
34.4,0.5734374,1.118907,0.1118907,0,0,0,0,0,0.5734374,0.5734374,0.5734374,1.140968
34.8,0.5798436,1.123549,0.1123549,0,0,0,0,0,0.5798436,0.5798436,0.5798436,1.145701
35.2,0.5860936,1.130204,0.1130204,0,0,0,0,0,0.5860937,0.5860937,0.5860936,1.152487
35.6,0.5932812,1.141435,0.1141435,0,0,0,0,0,0.5932811,0.5932811,0.5932812,1.16394
36,0.5999999,1.149334,0.1149334,0,0,0,0,0,0.5999999,0.5999999,0.5999999,1.171995
36.4,0.6064061,1.156635,0.1156635,0,0,0,0,0,0.6064062,0.6064062,0.6064061,1.179439
36.8,0.6131249,1.162656,0.1162656,0,0,0,0,0,0.6131249,0.6131249,0.6131249,1.185579
37.2,0.6203124,1.169992,0.1169992,0,0,0,0,0,0.6203124,0.6203124,0.6203124,1.19306
37.6,0.6264062,1.174974,0.1174974,0,0,0,0,0,0.6264062,0.6264062,0.6264062,1.19814
38,0.6329687,1.183073,0.1183073,0,0,0,0,0,0.6329687,0.6329687,0.6329687,1.206398
38.4,0.6395311,1.19066,0.119066,0,0,0,0,0,0.6395311,0.6395311,0.6395311,1.214135
38.8,0.6465624,1.201083,0.1201083,0,0,0,0,0,0.6465624,0.6465624,0.6465624,1.224764
39.2,0.6537499,1.211723,0.1211724,0,0,0,0,0,0.6537499,0.6537499,0.6537499,1.235614
39.6,0.6601561,1.219571,0.1219571,0,0,0,0,0,0.6601561,0.6601561,0.6601561,1.243616
40,0.6662499,1.224857,0.1224857,0,0,0,0,0,0.6662499,0.6662499,0.6662499,1.249007
40.4,0.6731249,1.235549,0.1235549,0,0,0,0,0,0.6731249,0.6731249,0.6731249,1.259909
40.8,0.6799999,1.245763,0.1245763,0,0,0,0,0,0.6799999,0.6799999,0.6799999,1.270325
41.2,0.6865624,1.254166,0.1254167,0,0,0,0,0,0.6865624,0.6865624,0.6865624,1.278894
41.6,0.6931249,1.26148,0.126148,0,0,0,0,0,0.6931249,0.6931249,0.6931249,1.286351
42,0.6998436,1.270689,0.1270689,0,0,0,0,0,0.6998436,0.6998436,0.6998436,1.295742
42.4,0.7067187,1.279586,0.1279586,0,0,0,0,0,0.7067186,0.7067186,0.7067187,1.304814
42.8,0.7132812,1.288026,0.1288026,0,0,0,0,0,0.7132812,0.7132812,0.7132812,1.313421
43.2,0.7198437,1.296931,0.1296931,0,0,0,0,0,0.7198437,0.7198437,0.7198437,1.322501
43.6,0.7264062,1.296304,0.1296304,0,0,0,0,0,0.7264062,0.7264062,0.7264062,1.321862
44,0.7332811,1.306039,0.1306039,0,0,0,0,0,0.7332811,0.7332811,0.7332811,1.331789
44.4,0.7401562,1.315474,0.1315474,0,0,0,0,0,0.7401562,0.7401562,0.7401562,1.34141
44.8,0.7464061,1.322269,0.1322269,0,0,0,0,0,0.7464061,0.7464061,0.7464061,1.348339
45.2,0.7529687,1.333364,0.1333364,0,0,0,0,0,0.7529687,0.7529687,0.7529687,1.359653
45.6,0.7596874,1.344605,0.1344605,0,0,0,0,0,0.7596874,0.7596874,0.7596874,1.371115
46,0.7668749,1.356969,0.1356969,0,0,0,0,0,0.7668748,0.7668748,0.7668749,1.383724
46.4,0.7734374,1.364711,0.1364711,0,0,0,0,0,0.7734374,0.7734374,0.7734374,1.391618
46.8,0.7799999,1.368204,0.1368204,0,0,0,0,0,0.7799999,0.7799999,0.7799999,1.39518
47.2,0.7865624,1.376279,0.1376279,0,0,0,0,0,0.7865624,0.7865624,0.7865624,1.403414
47.6,0.7932811,1.386751,0.1386751,0,0,0,0,0,0.7932811,0.7932811,0.7932811,1.414093
48,0.7998436,1.396576,0.1396576,0,0,0,0,0,0.7998436,0.7998436,0.7998436,1.424111
48.4,0.8064061,1.406538,0.1406538,0,0,0,0,0,0.8064061,0.8064061,0.8064061,1.434269
48.8,0.8129686,1.417062,0.1417062,0,0,0,0,0,0.8129687,0.8129687,0.8129686,1.445001
49.2,0.8201561,1.429624,0.1429624,0,0,0,0,0,0.8201562,0.8201562,0.8201561,1.457811
49.6,0.8268749,1.436422,0.1436422,0,0,0,0,0,0.8268749,0.8268749,0.8268749,1.464743
50,0.8329686,1.420824,0.1420824,0,0,0,0,0,0.8329687,0.8329687,0.8329686,1.448837
50.4,0.8395311,1.429706,0.1429706,0,0,0,0,0,0.8395311,0.8395311,0.8395311,1.457895
50.8,0.8464062,1.442218,0.1442218,0,0,0,0,0,0.8464062,0.8464062,0.8464062,1.470653
51.2,0.8534374,1.455973,0.1455973,0,0,0,0,0,0.8534374,0.8534374,0.8534374,1.484679
51.6,0.8598436,1.465114,0.1465114,0,0,0,0,0,0.8598436,0.8598436,0.8598436,1.494
52,0.8665624,1.474403,0.1474403,0,0,0,0,0,0.8665624,0.8665624,0.8665624,1.503473
52.4,0.8731249,1.443485,0.1443485,0,0,0,0,0,0.8731248,0.8731248,0.8731249,1.471945
52.8,0.8801561,1.431694,0.1431693,0,0,0,0,0,0.8801561,0.8801561,0.8801561,1.459921
53.2,0.8867186,1.433128,0.1433128,0,0,0,0,0,0.8867186,0.8867186,0.8867186,1.461384
53.6,0.8929686,1.439225,0.1439225,0,0,0,0,0,0.8929686,0.8929686,0.8929686,1.467601
54,0.8996874,1.443014,0.1443014,0,0,0,0,0,0.8996874,0.8996874,0.8996874,1.471465
54.4,0.9068749,1.444124,0.1444124,0,0,0,0,0,0.9068749,0.9068749,0.9068749,1.472597
54.8,0.9131249,1.443507,0.1443507,0,0,0,0,0,0.9131249,0.9131249,0.9131249,1.471967
55.2,0.9196874,1.445504,0.1445504,0,0,0,0,0,0.9196874,0.9196874,0.9196874,1.474004
55.6,0.9262499,1.451513,0.1451513,0,0,0,0,0,0.9262499,0.9262499,0.9262499,1.480131
56,0.9332811,1.455,0.1455,0,0,0,0,0,0.9332811,0.9332811,0.9332811,1.483687
56.4,0.9399999,1.454644,0.1454644,0,0,0,0,0,0.9399999,0.9399999,0.9399999,1.483324
56.8,0.9467186,1.45604,0.145604,0,0,0,0,0,0.9467186,0.9467186,0.9467186,1.484747
57.2,0.9532811,1.461092,0.1461092,0,0,0,0,0,0.9532811,0.9532811,0.9532811,1.489899
57.6,0.9598436,1.468255,0.1468255,0,0,0,0,0,0.9598436,0.9598436,0.9598436,1.497204
58,0.9667187,1.476021,0.1476021,0,0,0,0,0,0.9667187,0.9667187,0.9667187,1.505123
58.4,0.9732812,1.486836,0.1486836,0,0,0,0,0,0.9732811,0.9732811,0.9732812,1.516151
58.8,0.9796873,1.495204,0.1495204,0,0,0,0,0,0.9796873,0.9796873,0.9796873,1.524684
59.2,0.9865623,1.507365,0.1507365,0,0,0,0,0,0.9865624,0.9865624,0.9865623,1.537084
59.6,0.9939061,1.520493,0.1520493,0,0,0,0,0,0.9939061,0.9939061,0.9939061,1.550472
60,0.9998436,1.528039,0.1528039,0,0,0,0,0,0.9998436,0.9998436,0.9998436,1.558166
60.4,1.006406,1.522223,0.1522223,0,0,0,0,0,1.006406,1.006406,1.006406,1.552235
60.8,1.013125,1.523189,0.1523189,0,0,0,0,0,1.013125,1.013125,1.013125,1.553221
61.2,1.02,1.528331,0.1528331,0,0,0,0,0,1.02,1.02,1.02,1.558464
61.6,1.026719,1.536523,0.1536523,0,0,0,0,0,1.026718,1.026718,1.026719,1.566818
62,1.033281,1.540409,0.1540409,0,0,0,0,0,1.033281,1.033281,1.033281,1.570781
62.4,1.039531,1.545121,0.1545121,0,0,0,0,0,1.039531,1.039531,1.039531,1.575585
62.8,1.046562,1.553384,0.1553384,0,0,0,0,0,1.046562,1.046562,1.046562,1.584011
63.2,1.053281,1.56235,0.156235,0,0,0,0,0,1.053281,1.053281,1.053281,1.593153
63.6,1.059844,1.572961,0.1572961,0,0,0,0,0,1.059844,1.059844,1.059844,1.603974
64,1.066406,1.584312,0.1584312,0,0,0,0,0,1.066406,1.066406,1.066406,1.615549
64.4,1.073281,1.596119,0.1596119,0,0,0,0,0,1.073281,1.073281,1.073281,1.627588
64.8,1.08,1.607598,0.1607598,0,0,0,0,0,1.08,1.08,1.08,1.639294
65.2,1.086562,1.619163,0.1619163,0,0,0,0,0,1.086562,1.086562,1.086562,1.651087
65.60001,1.092969,1.630359,0.1630359,0,0,0,0,0,1.092968,1.092968,1.092969,1.662503
66,1.099844,1.634081,0.1634081,0,0,0,0,0,1.099844,1.099844,1.099844,1.666299
66.4,1.106875,1.647914,0.1647914,0,0,0,0,0,1.106875,1.106875,1.106875,1.680404
66.8,1.113437,1.658078,0.1658078,0,0,0,0,0,1.113437,1.113437,1.113437,1.690769
67.20001,1.12,1.667917,0.1667917,0,0,0,0,0,1.12,1.12,1.12,1.700802
67.60001,1.12625,1.673139,0.1673138,0,0,0,0,0,1.12625,1.12625,1.12625,1.706126
68,1.133125,1.688142,0.1688142,0,0,0,0,0,1.133125,1.133125,1.133125,1.721426
68.4,1.14,1.704398,0.1704398,0,0,0,0,0,1.14,1.14,1.14,1.738002
68.8,1.146406,1.715262,0.1715262,0,0,0,0,0,1.146406,1.146406,1.146406,1.749081
69.20001,1.152968,1.728594,0.1728594,0,0,0,0,0,1.152969,1.152969,1.152968,1.762675
69.60001,1.160312,1.744084,0.1744084,0,0,0,0,0,1.160312,1.160312,1.160312,1.778471
70,1.166719,1.755902,0.1755902,0,0,0,0,0,1.166719,1.166719,1.166719,1.790521
70.4,1.172969,1.766031,0.1766031,0,0,0,0,0,1.172969,1.172969,1.172969,1.800851
70.8,1.179687,1.78029,0.178029,0,0,0,0,0,1.179687,1.179687,1.179687,1.81539
71.20001,1.186406,1.79428,0.179428,0,0,0,0,0,1.186406,1.186406,1.186406,1.829656
71.60001,1.193437,1.80827,0.180827,0,0,0,0,0,1.193437,1.193437,1.193437,1.843922
72,1.2,1.818953,0.1818953,0,0,0,0,0,1.2,1.2,1.2,1.854816
72.4,1.20625,1.827165,0.1827165,0,0,0,0,0,1.20625,1.20625,1.20625,1.863189
72.8,1.213125,1.844093,0.1844093,0,0,0,0,0,1.213125,1.213125,1.213125,1.880452
73.20001,1.220156,1.861579,0.1861579,0,0,0,0,0,1.220156,1.220156,1.220156,1.898282
73.60001,1.226719,1.873823,0.1873823,0,0,0,0,0,1.226719,1.226719,1.226719,1.910768
74,1.232969,1.885395,0.1885395,0,0,0,0,0,1.232969,1.232969,1.232969,1.922568
74.4,1.239687,1.895883,0.1895883,0,0,0,0,0,1.239687,1.239687,1.239687,1.933262
74.8,1.246875,1.913694,0.1913694,0,0,0,0,0,1.246875,1.246875,1.246875,1.951425
75.20001,1.253125,1.922506,0.1922506,0,0,0,0,0,1.253125,1.253125,1.253125,1.960411
75.60001,1.259687,1.936312,0.1936312,0,0,0,0,0,1.259687,1.259687,1.259687,1.974489
76,1.266406,1.950281,0.1950281,0,0,0,0,0,1.266406,1.266406,1.266406,1.988733
76.4,1.273594,1.96819,0.1968189,0,0,0,0,0,1.273594,1.273594,1.273594,2.006995
76.8,1.280312,1.982175,0.1982175,0,0,0,0,0,1.280312,1.280312,1.280312,2.021256
77.20001,1.286719,1.993353,0.1993353,0,0,0,0,0,1.286718,1.286718,1.286719,2.032655
77.60001,1.292812,2.003942,0.2003942,0,0,0,0,0,1.292812,1.292812,1.292812,2.043453
78,1.299687,2.021564,0.2021564,0,0,0,0,0,1.299687,1.299687,1.299687,2.061422
78.4,1.306719,2.037402,0.2037402,0,0,0,0,0,1.306719,1.306719,1.306719,2.077572
78.8,1.313281,2.049683,0.2049683,0,0,0,0,0,1.313281,1.313281,1.313281,2.090096
79.20001,1.319844,2.062991,0.2062991,0,0,0,0,0,1.319844,1.319844,1.319844,2.103666
79.60001,1.326562,2.075641,0.2075641,0,0,0,0,0,1.326562,1.326562,1.326562,2.116565
80,1.333437,2.091617,0.2091617,0,0,0,0,0,1.333437,1.333437,1.333437,2.132855
80.4,1.34,2.106644,0.2106644,0,0,0,0,0,1.34,1.34,1.34,2.148179
80.8,1.346562,2.120475,0.2120475,0,0,0,0,0,1.346562,1.346562,1.346562,2.162282
81.20001,1.352969,2.134855,0.2134855,0,0,0,0,0,1.352968,1.352968,1.352969,2.176947
81.60001,1.359844,2.149763,0.2149763,0,0,0,0,0,1.359843,1.359843,1.359844,2.192148
82.00001,1.367031,2.164228,0.2164228,0,0,0,0,0,1.367031,1.367031,1.367031,2.206898
82.4,1.372969,2.171191,0.2171191,0,0,0,0,0,1.372969,1.372969,1.372969,2.213999
82.8,1.379531,2.186269,0.2186269,0,0,0,0,0,1.379531,1.379531,1.379531,2.229374
83.20001,1.386562,2.202838,0.2202838,0,0,0,0,0,1.386562,1.386562,1.386562,2.246269
83.60001,1.393437,2.216846,0.2216846,0,0,0,0,0,1.393437,1.393437,1.393437,2.260554
84.00001,1.400156,2.230496,0.2230496,0,0,0,0,0,1.400156,1.400156,1.400156,2.274473
84.4,1.406719,2.241931,0.2241931,0,0,0,0,0,1.406718,1.406718,1.406719,2.286133
84.8,1.413437,2.255252,0.2255252,0,0,0,0,0,1.413437,1.413437,1.413437,2.299717
85.20001,1.420156,2.271065,0.2271065,0,0,0,0,0,1.420156,1.420156,1.420156,2.315841
85.60001,1.426406,2.282361,0.2282361,0,0,0,0,0,1.426406,1.426406,1.426406,2.327361
86.00001,1.432969,2.289717,0.2289717,0,0,0,0,0,1.432968,1.432968,1.432969,2.334862
86.4,1.439687,2.30494,0.230494,0,0,0,0,0,1.439687,1.439687,1.439687,2.350384
86.8,1.447031,2.32502,0.232502,0,0,0,0,0,1.447031,1.447031,1.447031,2.370861
87.20001,1.453437,2.335199,0.2335199,0,0,0,0,0,1.453437,1.453437,1.453437,2.38124
87.60001,1.459687,2.345175,0.2345175,0,0,0,0,0,1.459687,1.459687,1.459687,2.391413
88.00001,1.46625,2.359731,0.2359731,0,0,0,0,0,1.46625,1.46625,1.46625,2.406256
88.4,1.473125,2.374814,0.2374814,0,0,0,0,0,1.473125,1.473125,1.473125,2.421636
88.8,1.48,2.39016,0.239016,0,0,0,0,0,1.48,1.48,1.48,2.437285
89.20001,1.486406,2.402666,0.2402666,0,0,0,0,0,1.486406,1.486406,1.486406,2.450037
89.60001,1.493125,2.417664,0.2417664,0,0,0,0,0,1.493125,1.493125,1.493125,2.465332
90.00001,1.499687,2.434954,0.2434954,0,0,0,0,0,1.499687,1.499687,1.499687,2.482962
90.4,1.506719,2.453413,0.2453413,0,0,0,0,0,1.506719,1.506719,1.506719,2.501785
90.8,1.513281,2.466644,0.2466644,0,0,0,0,0,1.513281,1.513281,1.513281,2.515277
91.20001,1.519687,2.479544,0.2479544,0,0,0,0,0,1.519687,1.519687,1.519687,2.528431
91.60001,1.526406,2.494958,0.2494958,0,0,0,0,0,1.526406,1.526406,1.526406,2.544149
92.00001,1.53375,2.513281,0.2513281,0,0,0,0,0,1.53375,1.53375,1.53375,2.562833
92.4,1.539687,2.517408,0.2517408,0,0,0,0,0,1.539687,1.539687,1.539687,2.567042
92.8,1.54625,2.533471,0.2533471,0,0,0,0,0,1.54625,1.54625,1.54625,2.583421
93.20001,1.552969,2.550907,0.2550907,0,0,0,0,0,1.552969,1.552969,1.552969,2.601202
93.60001,1.560312,2.571197,0.2571197,0,0,0,0,0,1.560312,1.560312,1.560312,2.621892
94.00001,1.566719,2.582737,0.2582738,0,0,0,0,0,1.566719,1.566719,1.566719,2.633659
94.4,1.573437,2.596896,0.2596896,0,0,0,0,0,1.573437,1.573437,1.573437,2.648097
94.8,1.579844,2.610398,0.2610398,0,0,0,0,0,1.579844,1.579844,1.579844,2.661865
95.20001,1.586406,2.627695,0.2627695,0,0,0,0,0,1.586406,1.586406,1.586406,2.679503
95.60001,1.593281,2.631445,0.2631445,0,0,0,0,0,1.593281,1.593281,1.593281,2.683327
96.00001,1.599843,2.642817,0.2642817,0,0,0,0,0,1.599844,1.599844,1.599843,2.694923
96.4,1.606406,2.658934,0.2658934,0,0,0,0,0,1.606406,1.606406,1.606406,2.711358
96.8,1.613437,2.6791,0.26791,0,0,0,0,0,1.613437,1.613437,1.613437,2.731922
97.20001,1.620312,2.694951,0.2694951,0,0,0,0,0,1.620312,1.620312,1.620312,2.748085
97.60001,1.626406,2.706166,0.2706166,0,0,0,0,0,1.626406,1.626406,1.626406,2.759521
98.00001,1.632969,2.724788,0.2724788,0,0,0,0,0,1.632969,1.632969,1.632969,2.778511
98.4,1.639844,2.744059,0.2744059,0,0,0,0,0,1.639844,1.639844,1.639844,2.798162
98.8,1.646875,2.765067,0.2765068,0,0,0,0,0,1.646875,1.646875,1.646875,2.819584
99.20001,1.653437,2.780065,0.2780065,0,0,0,0,0,1.653437,1.653437,1.653437,2.834877
99.60001,1.659843,2.792436,0.2792436,0,0,0,0,0,1.659843,1.659843,1.659843,2.847492
100,1.66625,2.806593,0.2806593,0,0,0,0,0,1.66625,1.66625,1.66625,2.861928
100.4,1.673437,2.831984,0.2831984,0,0,0,0,0,1.673437,1.673437,1.673437,2.88782
100.8,1.680156,2.850302,0.2850302,0,0,0,0,0,1.680156,1.680156,1.680156,2.906499
101.2,1.686562,2.865546,0.2865546,0,0,0,0,0,1.686562,1.686562,1.686562,2.922044
101.6,1.693125,2.880797,0.2880797,0,0,0,0,0,1.693125,1.693125,1.693125,2.937595
102,1.700156,2.900801,0.2900801,0,0,0,0,0,1.700156,1.700156,1.700156,2.957994
102.4,1.706406,2.913523,0.2913523,0,0,0,0,0,1.706406,1.706406,1.706406,2.970967
102.8,1.712969,2.930899,0.2930899,0,0,0,0,0,1.712969,1.712969,1.712969,2.988685
103.2,1.719687,2.949205,0.2949205,0,0,0,0,0,1.719687,1.719687,1.719687,3.007352
103.6,1.726562,2.9712,0.29712,0,0,0,0,0,1.726562,1.726562,1.726562,3.029781
104,1.733594,2.98946,0.298946,0,0,0,0,0,1.733594,1.733594,1.733594,3.048401
104.4,1.740156,3.003229,0.3003229,0,0,0,0,0,1.740156,1.740156,1.740156,3.062442
104.8,1.746719,3.018931,0.3018931,0,0,0,0,0,1.746719,1.746719,1.746719,3.078453
105.2,1.752969,3.03339,0.303339,0,0,0,0,0,1.752969,1.752969,1.752969,3.093197
105.6,1.759844,3.056673,0.3056673,0,0,0,0,0,1.759844,1.759844,1.759844,3.116939
106,1.766562,3.074008,0.3074008,0,0,0,0,0,1.766562,1.766562,1.766562,3.134616
106.4,1.772969,3.085868,0.3085868,0,0,0,0,0,1.772969,1.772969,1.772969,3.14671
106.8,1.779844,3.104362,0.3104362,0,0,0,0,0,1.779844,1.779844,1.779844,3.165569
107.2,1.787031,3.125823,0.3125823,0,0,0,0,0,1.787031,1.787031,1.787031,3.187452
107.6,1.793281,3.136571,0.3136571,0,0,0,0,0,1.793281,1.793281,1.793281,3.198412
108,1.799531,3.152578,0.3152578,0,0,0,0,0,1.799531,1.799531,1.799531,3.214735
108.4,1.80625,3.17134,0.317134,0,0,0,0,0,1.80625,1.80625,1.80625,3.233867
108.8,1.813125,3.191507,0.3191507,0,0,0,0,0,1.813125,1.813125,1.813125,3.254431
109.2,1.82,3.206815,0.3206815,0,0,0,0,0,1.82,1.82,1.82,3.270041
109.6,1.826719,3.214926,0.3214926,0,0,0,0,0,1.826719,1.826719,1.826719,3.278312
110,1.832812,3.226154,0.3226154,0,0,0,0,0,1.832812,1.832812,1.832812,3.289762
110.4,1.839844,3.250224,0.3250224,0,0,0,0,0,1.839844,1.839844,1.839844,3.314306
110.8,1.846875,3.27229,0.327229,0,0,0,0,0,1.846875,1.846875,1.846875,3.336807
111.2,1.853281,3.288953,0.3288953,0,0,0,0,0,1.853281,1.853281,1.853281,3.353798
111.6,1.859687,3.306545,0.3306545,0,0,0,0,0,1.859687,1.859687,1.859687,3.371737
112,1.866406,3.324731,0.3324731,0,0,0,0,0,1.866406,1.866406,1.866406,3.390282
112.4,1.873437,3.347812,0.3347812,0,0,0,0,0,1.873437,1.873437,1.873437,3.413818
112.8,1.88,3.348224,0.3348224,0,0,0,0,0,1.88,1.88,1.88,3.414238
113.2,1.88625,3.36206,0.336206,0,0,0,0,0,1.88625,1.88625,1.88625,3.428347
113.6,1.892969,3.383166,0.3383166,0,0,0,0,0,1.892969,1.892969,1.892969,3.449869
114,1.900156,3.407248,0.3407249,0,0,0,0,0,1.900156,1.900156,1.900156,3.474427
114.4,1.906718,3.42323,0.342323,0,0,0,0,0,1.906718,1.906718,1.906718,3.490723
114.8,1.913437,3.440358,0.3440358,0,0,0,0,0,1.913437,1.913437,1.913437,3.508189
115.2,1.919531,3.455055,0.3455055,0,0,0,0,0,1.919531,1.919531,1.919531,3.523175
115.6,1.926406,3.480786,0.3480786,0,0,0,0,0,1.926406,1.926406,1.926406,3.549414
116,1.933437,3.504093,0.3504093,0,0,0,0,0,1.933437,1.933437,1.933437,3.57318
116.4,1.94,3.521894,0.3521894,0,0,0,0,0,1.94,1.94,1.94,3.591333
116.8,1.946562,3.536315,0.3536314,0,0,0,0,0,1.946562,1.946562,1.946562,3.606037
117.2,1.953593,3.556009,0.355601,0,0,0,0,0,1.953593,1.953593,1.953593,3.62612
117.6,1.96,3.5578,0.35578,0,0,0,0,0,1.96,1.96,1.96,3.627946
118,1.966718,3.565574,0.3565574,0,0,0,0,0,1.966718,1.966718,1.966718,3.635874
118.4,1.972968,3.580405,0.3580405,0,0,0,0,0,1.972968,1.972968,1.972968,3.650997
118.8,1.979687,3.59554,0.359554,0,0,0,0,0,1.979687,1.979687,1.979687,3.66643
119.2,1.986875,3.621794,0.3621794,0,0,0,0,0,1.986874,1.986874,1.986875,3.693202
119.6,1.993593,3.637288,0.3637288,0,0,0,0,0,1.993593,1.993593,1.993593,3.709002
120,1.999687,3.649135,0.3649135,0,0,0,0,0,1.999687,1.999687,1.999687,3.721082
120.4,2.00625,3.671412,0.3671412,0,0,0,0,0,2.006249,2.006249,2.00625,3.743798
120.8,2.013437,3.699122,0.3699122,0,0,0,0,0,2.013437,2.013437,2.013437,3.772055
121.2,2.02,3.715112,0.3715112,0,0,0,0,0,2.02,2.02,2.02,3.78836
121.6,2.026718,3.734881,0.3734881,0,0,0,0,0,2.026718,2.026718,2.026718,3.808518
122,2.033281,3.743665,0.3743665,0,0,0,0,0,2.033281,2.033281,2.033281,3.817475
122.4,2.039843,3.764932,0.3764932,0,0,0,0,0,2.039843,2.039843,2.039843,3.839162
122.8,2.046718,3.790106,0.3790106,0,0,0,0,0,2.046718,2.046718,2.046718,3.864833
123.2,2.053125,3.808196,0.3808196,0,0,0,0,0,2.053125,2.053125,2.053125,3.883279
123.6,2.059687,3.827615,0.3827615,0,0,0,0,0,2.059687,2.059687,2.059687,3.903082
124,2.066562,3.849241,0.3849241,0,0,0,0,0,2.066562,2.066562,2.066562,3.925133
124.4,2.07375,3.871741,0.3871741,0,0,0,0,0,2.07375,2.07375,2.07375,3.948077
124.8,2.08,3.869733,0.3869733,0,0,0,0,0,2.079999,2.079999,2.08,3.946029
125.2,2.08625,3.884148,0.3884148,0,0,0,0,0,2.08625,2.08625,2.08625,3.960729
125.6,2.092968,3.903723,0.3903723,0,0,0,0,0,2.092968,2.092968,2.092968,3.98069
126,2.099843,3.925008,0.3925008,0,0,0,0,0,2.099844,2.099844,2.099843,4.002395
126.4,2.106718,3.945744,0.3945744,0,0,0,0,0,2.106718,2.106718,2.106718,4.023539
126.8,2.113281,3.963252,0.3963252,0,0,0,0,0,2.113281,2.113281,2.113281,4.041392
127.2,2.12,3.980298,0.3980298,0,0,0,0,0,2.12,2.12,2.12,4.058774
127.6,2.126406,3.996203,0.3996203,0,0,0,0,0,2.126406,2.126406,2.126406,4.074993
128,2.133281,3.999844,0.3999844,0,0,0,0,0,2.133281,2.133281,2.133281,4.078706
128.4,2.139687,4.011838,0.4011838,0,0,0,0,0,2.139687,2.139687,2.139687,4.090936
128.8,2.14625,4.031826,0.4031826,0,0,0,0,0,2.14625,2.14625,2.14625,4.111318
129.2,2.153125,4.053509,0.4053509,0,0,0,0,0,2.153125,2.153125,2.153125,4.133429
129.6,2.160312,4.079426,0.4079427,0,0,0,0,0,2.160312,2.160312,2.160312,4.159857
130,2.166406,4.083672,0.4083672,0,0,0,0,0,2.166406,2.166406,2.166406,4.164186
130.4,2.172968,4.086082,0.4086082,0,0,0,0,0,2.172968,2.172968,2.172968,4.166644
130.8,2.179843,4.100635,0.4100635,0,0,0,0,0,2.179843,2.179843,2.179843,4.181484
131.2,2.186875,4.123197,0.4123197,0,0,0,0,0,2.186875,2.186875,2.186875,4.204491
131.6,2.193437,4.138716,0.4138716,0,0,0,0,0,2.193437,2.193437,2.193437,4.220316
132,2.2,4.155685,0.4155685,0,0,0,0,0,2.2,2.2,2.2,4.237619
132.4,2.20625,4.162394,0.4162394,0,0,0,0,0,2.20625,2.20625,2.20625,4.24446
132.8,2.213125,4.184237,0.4184237,0,0,0,0,0,2.213125,2.213125,2.213125,4.266735
133.2,2.22,4.208423,0.4208423,0,0,0,0,0,2.22,2.22,2.22,4.291397
133.6,2.22625,4.225966,0.4225966,0,0,0,0,0,2.226249,2.226249,2.22625,4.309286
134,2.232968,4.24576,0.424576,0,0,0,0,0,2.232968,2.232968,2.232968,4.329471
134.4,2.240312,4.274267,0.4274267,0,0,0,0,0,2.240312,2.240312,2.240312,4.35854
134.8,2.246875,4.28371,0.428371,0,0,0,0,0,2.246875,2.246875,2.246875,4.368169
135.2,2.252968,4.295972,0.4295972,0,0,0,0,0,2.252968,2.252968,2.252968,4.380672
135.6,2.259687,4.31178,0.4311779,0,0,0,0,0,2.259687,2.259687,2.259687,4.396791
136,2.266406,4.327844,0.4327844,0,0,0,0,0,2.266406,2.266406,2.266406,4.413173
136.4,2.273437,4.341754,0.4341754,0,0,0,0,0,2.273437,2.273437,2.273437,4.427357
136.8,2.28,4.354779,0.4354779,0,0,0,0,0,2.28,2.28,2.28,4.440639
137.2,2.286406,4.365892,0.4365892,0,0,0,0,0,2.286406,2.286406,2.286406,4.451971
137.6,2.292968,4.380465,0.4380465,0,0,0,0,0,2.292968,2.292968,2.292968,4.466831
138,2.300156,4.406558,0.4406558,0,0,0,0,0,2.300156,2.300156,2.300156,4.493438
138.4,2.306718,4.421519,0.4421519,0,0,0,0,0,2.306718,2.306718,2.306718,4.508694
138.8,2.313124,4.435108,0.4435108,0,0,0,0,0,2.313124,2.313124,2.313124,4.522552
139.2,2.319843,4.452856,0.4452856,0,0,0,0,0,2.319843,2.319843,2.319843,4.54065
139.6,2.326875,4.476209,0.4476209,0,0,0,0,0,2.326874,2.326874,2.326875,4.564463
140,2.333125,4.481874,0.4481874,0,0,0,0,0,2.333125,2.333125,2.333125,4.57024
140.4,2.339687,4.487518,0.4487518,0,0,0,0,0,2.339687,2.339687,2.339687,4.575995
140.8,2.34625,4.500639,0.4500639,0,0,0,0,0,2.34625,2.34625,2.34625,4.589375
141.2,2.353281,4.519588,0.4519588,0,0,0,0,0,2.353281,2.353281,2.353281,4.608697
141.6,2.360156,4.535176,0.4535176,0,0,0,0,0,2.360156,2.360156,2.360156,4.624593
142,2.366718,4.545689,0.4545689,0,0,0,0,0,2.366718,2.366718,2.366718,4.635313
142.4,2.373125,4.556274,0.4556274,0,0,0,0,0,2.373125,2.373125,2.373125,4.646107
142.8,2.379687,4.574542,0.4574542,0,0,0,0,0,2.379687,2.379687,2.379687,4.664734
143.2,2.386718,4.599302,0.4599302,0,0,0,0,0,2.386718,2.386718,2.386718,4.689983
143.6,2.393125,4.610532,0.4610532,0,0,0,0,0,2.393125,2.393125,2.393125,4.701435
144,2.399531,4.613793,0.4613793,0,0,0,0,0,2.399531,2.399531,2.399531,4.70476
144.4,2.406406,4.59705,0.459705,0,0,0,0,0,2.406406,2.406406,2.406406,4.687686
144.8,2.413593,4.617639,0.4617639,0,0,0,0,0,2.413593,2.413593,2.413593,4.708682
145.2,2.419843,4.627267,0.4627267,0,0,0,0,0,2.419843,2.419843,2.419843,4.718499
145.6,2.426406,4.647602,0.4647602,0,0,0,0,0,2.426406,2.426406,2.426406,4.739235
146,2.432968,4.669715,0.4669715,0,0,0,0,0,2.432968,2.432968,2.432968,4.761785
146.4,2.439999,4.696681,0.4696681,0,0,0,0,0,2.44,2.44,2.439999,4.789282
146.8,2.446875,4.715126,0.4715126,0,0,0,0,0,2.446875,2.446875,2.446875,4.808091
147.2,2.453281,4.729478,0.4729478,0,0,0,0,0,2.453281,2.453281,2.453281,4.822725
147.6,2.459531,4.741499,0.4741499,0,0,0,0,0,2.459531,2.459531,2.459531,4.834984
148,2.466406,4.765496,0.4765496,0,0,0,0,0,2.466406,2.466406,2.466406,4.859454
148.4,2.473437,4.784097,0.4784097,0,0,0,0,0,2.473437,2.473437,2.473437,4.878421
148.8,2.479843,4.795725,0.4795724,0,0,0,0,0,2.479843,2.479843,2.479843,4.890278
149.2,2.486406,4.781262,0.4781262,0,0,0,0,0,2.486406,2.486406,2.486406,4.875531
149.6,2.493125,4.76088,0.476088,0,0,0,0,0,2.493125,2.493125,2.493125,4.854747
150,2.499999,4.761502,0.4761502,0,0,0,0,0,2.5,2.5,2.499999,4.855381
150.4,2.506406,4.769263,0.4769263,0,0,0,0,0,2.506406,2.506406,2.506406,4.863295
150.8,2.512968,4.777196,0.4777196,0,0,0,0,0,2.512968,2.512968,2.512968,4.871385
151.2,2.519843,4.774358,0.4774358,0,0,0,0,0,2.519843,2.519843,2.519843,4.86849
151.6,2.527031,4.789838,0.4789838,0,0,0,0,0,2.527031,2.527031,2.527031,4.884275
152,2.533593,4.792688,0.4792688,0,0,0,0,0,2.533593,2.533593,2.533593,4.887182
152.4,2.539843,4.798975,0.4798975,0,0,0,0,0,2.539843,2.539843,2.539843,4.893592
152.8,2.54625,4.806875,0.4806876,0,0,0,0,0,2.54625,2.54625,2.54625,4.901649
153.2,2.553125,4.818917,0.4818917,0,0,0,0,0,2.553125,2.553125,2.553125,4.913928
153.6,2.56,4.837268,0.4837268,0,0,0,0,0,2.56,2.56,2.56,4.932641
154,2.566562,4.854736,0.4854736,0,0,0,0,0,2.566562,2.566562,2.566562,4.950453
154.4,2.573125,4.869161,0.4869161,0,0,0,0,0,2.573125,2.573125,2.573125,4.965163
154.8,2.580156,4.896214,0.4896214,0,0,0,0,0,2.580156,2.580156,2.580156,4.992749
155.2,2.586718,4.914017,0.4914017,0,0,0,0,0,2.586718,2.586718,2.586718,5.010902
155.6,2.593281,4.934623,0.4934624,0,0,0,0,0,2.593281,2.593281,2.593281,5.031916
156,2.599687,4.950637,0.4950637,0,0,0,0,0,2.599687,2.599687,2.599687,5.048245
156.4,2.606406,4.970628,0.4970628,0,0,0,0,0,2.606406,2.606406,2.606406,5.06863
156.8,2.613593,4.997189,0.4997188,0,0,0,0,0,2.613593,2.613593,2.613593,5.095714
157.2,2.620156,5.011476,0.5011476,0,0,0,0,0,2.620156,2.620156,2.620156,5.110283
157.6,2.626093,5.018785,0.5018785,0,0,0,0,0,2.626093,2.626093,2.626093,5.117736
158,2.632968,5.042516,0.5042516,0,0,0,0,0,2.632968,2.632968,2.632968,5.141935
158.4,2.640312,5.068631,0.5068631,0,0,0,0,0,2.640312,2.640312,2.640312,5.168565
158.8,2.646718,5.079594,0.5079594,0,0,0,0,0,2.646719,2.646719,2.646718,5.179744
159.2,2.653281,5.095965,0.5095965,0,0,0,0,0,2.653281,2.653281,2.653281,5.196438
159.6,2.659843,5.105781,0.5105781,0,0,0,0,0,2.659843,2.659843,2.659843,5.206448
160,2.666718,5.124699,0.5124699,0,0,0,0,0,2.666718,2.666718,2.666718,5.225738
160.4,2.673281,5.139824,0.5139824,0,0,0,0,0,2.673281,2.673281,2.673281,5.241162
160.8,2.679687,5.152902,0.5152901,0,0,0,0,0,2.679687,2.679687,2.679687,5.254498
161.2,2.686406,5.171056,0.5171056,0,0,0,0,0,2.686406,2.686406,2.686406,5.27301
161.6,2.693281,5.19348,0.519348,0,0,0,0,0,2.693281,2.693281,2.693281,5.295876
162,2.700312,5.211986,0.5211986,0,0,0,0,0,2.700312,2.700312,2.700312,5.314747
162.4,2.706562,5.220868,0.5220868,0,0,0,0,0,2.706562,2.706562,2.706562,5.323804
162.8,2.712968,5.232752,0.5232753,0,0,0,0,0,2.712968,2.712968,2.712968,5.335923
163.2,2.719687,5.243271,0.5243271,0,0,0,0,0,2.719687,2.719687,2.719687,5.346648
163.6,2.726562,5.258856,0.5258856,0,0,0,0,0,2.726562,2.726562,2.726562,5.36254
164,2.733281,5.273713,0.5273713,0,0,0,0,0,2.733281,2.733281,2.733281,5.37769
164.4,2.739843,5.282426,0.5282425,0,0,0,0,0,2.739843,2.739843,2.739843,5.386575
164.8,2.746406,5.291053,0.5291053,0,0,0,0,0,2.746406,2.746406,2.746406,5.395373
165.2,2.753281,5.310431,0.5310431,0,0,0,0,0,2.753281,2.753281,2.753281,5.415133
165.6,2.76,5.327011,0.5327011,0,0,0,0,0,2.76,2.76,2.76,5.432039
166,2.766406,5.33693,0.533693,0,0,0,0,0,2.766406,2.766406,2.766406,5.442154
166.4,2.772968,5.344455,0.5344455,0,0,0,0,0,2.772968,2.772968,2.772968,5.449827
166.8,2.78,5.357809,0.5357808,0,0,0,0,0,2.779999,2.779999,2.78,5.463444
167.2,2.786875,5.365989,0.5365989,0,0,0,0,0,2.786875,2.786875,2.786875,5.471786
167.6,2.792968,5.369832,0.5369831,0,0,0,0,0,2.792969,2.792969,2.792968,5.475704
168,2.799531,5.381351,0.5381351,0,0,0,0,0,2.799531,2.799531,2.799531,5.487451
168.4,2.806562,5.395332,0.5395331,0,0,0,0,0,2.806562,2.806562,2.806562,5.501707
168.8,2.813437,5.406448,0.5406448,0,0,0,0,0,2.813437,2.813437,2.813437,5.513042
169.2,2.820156,5.402056,0.5402056,0,0,0,0,0,2.820156,2.820156,2.820156,5.508564
169.6,2.826718,5.407227,0.5407227,0,0,0,0,0,2.826718,2.826718,2.826718,5.513837
170,2.832968,5.412813,0.5412812,0,0,0,0,0,2.832968,2.832968,2.832968,5.519533
170.4,2.84,5.431938,0.5431938,0,0,0,0,0,2.839999,2.839999,2.84,5.539035
170.8,2.846562,5.417889,0.5417889,0,0,0,0,0,2.846562,2.846562,2.846562,5.52471
171.2,2.852968,5.412689,0.5412689,0,0,0,0,0,2.852968,2.852968,2.852968,5.519407
171.6,2.859843,5.423207,0.5423207,0,0,0,0,0,2.859843,2.859843,2.859843,5.530132
172,2.867187,5.436703,0.5436703,0,0,0,0,0,2.867187,2.867187,2.867187,5.543894
172.4,2.873281,5.420343,0.5420343,0,0,0,0,0,2.873281,2.873281,2.873281,5.527212
172.8,2.879687,5.408054,0.5408054,0,0,0,0,0,2.879687,2.879687,2.879687,5.51468
173.2,2.88625,5.417963,0.5417963,0,0,0,0,0,2.88625,2.88625,2.88625,5.524785
173.6,2.893124,5.433179,0.5433179,0,0,0,0,0,2.893125,2.893125,2.893124,5.540301
174,2.899999,5.4505,0.54505,0,0,0,0,0,2.899999,2.899999,2.899999,5.557963
174.4,2.906562,5.459844,0.5459844,0,0,0,0,0,2.906562,2.906562,2.906562,5.567492
174.8,2.912968,5.469996,0.5469996,0,0,0,0,0,2.912968,2.912968,2.912968,5.577843
175.2,2.919843,5.488184,0.5488183,0,0,0,0,0,2.919843,2.919843,2.919843,5.59639
175.6,2.926875,5.51181,0.551181,0,0,0,0,0,2.926875,2.926875,2.926875,5.620482
176,2.933281,5.522367,0.5522367,0,0,0,0,0,2.933281,2.933281,2.933281,5.631247
176.4,2.939687,5.531973,0.5531973,0,0,0,0,0,2.939687,2.939687,2.939687,5.641043
176.8,2.946562,5.547978,0.5547978,0,0,0,0,0,2.946562,2.946562,2.946562,5.657363
177.2,2.953593,5.569686,0.5569686,0,0,0,0,0,2.953593,2.953593,2.953593,5.679499
177.6,2.959843,5.577138,0.5577137,0,0,0,0,0,2.959843,2.959843,2.959843,5.687098
178,2.96625,5.595148,0.5595148,0,0,0,0,0,2.96625,2.96625,2.96625,5.705463
178.4,2.973125,5.614842,0.5614842,0,0,0,0,0,2.973125,2.973125,2.973125,5.725546
178.8,2.980312,5.636947,0.5636947,0,0,0,0,0,2.980312,2.980312,2.980312,5.748086
179.2,2.986718,5.64578,0.5645781,0,0,0,0,0,2.986718,2.986718,2.986718,5.757094
179.6,2.993281,5.656483,0.5656483,0,0,0,0,0,2.993281,2.993281,2.993281,5.768007
180,2.999687,5.666314,0.5666314,0,0,0,0,0,2.999687,2.999687,2.999687,5.778032
180.4,3.006406,5.683095,0.5683095,0,0,0,0,0,3.006406,3.006406,3.006406,5.795144
180.8,3.013281,5.69925,0.5699251,0,0,0,0,0,3.013281,3.013281,3.013281,5.811618
181.2,3.019843,5.710545,0.5710545,0,0,0,0,0,3.019843,3.019843,3.019843,5.823135
181.6,3.026406,5.720803,0.5720803,0,0,0,0,0,3.026406,3.026406,3.026406,5.833595
182,3.033437,5.738062,0.5738062,0,0,0,0,0,3.033437,3.033437,3.033437,5.851195
182.4,3.04,5.750555,0.5750555,0,0,0,0,0,3.04,3.04,3.04,5.863934
182.8,3.046406,5.754995,0.5754995,0,0,0,0,0,3.046406,3.046406,3.046406,5.868462
183.2,3.052968,5.770896,0.5770896,0,0,0,0,0,3.052968,3.052968,3.052968,5.884676
183.6,3.059531,5.786931,0.5786931,0,0,0,0,0,3.059531,3.059531,3.059531,5.901027
184,3.066875,5.809678,0.5809678,0,0,0,0,0,3.066875,3.066875,3.066875,5.924222
184.4,3.073437,5.817371,0.5817371,0,0,0,0,0,3.073437,3.073437,3.073437,5.932068
184.8,3.079999,5.817945,0.5817945,0,0,0,0,0,3.079999,3.079999,3.079999,5.932653
185.2,3.08625,5.823486,0.5823486,0,0,0,0,0,3.08625,3.08625,3.08625,5.938303
185.6,3.093437,5.844576,0.5844576,0,0,0,0,0,3.093437,3.093437,3.093437,5.959809
186,3.1,5.850066,0.5850066,0,0,0,0,0,3.1,3.1,3.1,5.965407
186.4,3.106406,5.857485,0.5857485,0,0,0,0,0,3.106406,3.106406,3.106406,5.972972
186.8,3.113125,5.866744,0.5866745,0,0,0,0,0,3.113125,3.113125,3.113125,5.982414
187.2,3.120312,5.883592,0.5883592,0,0,0,0,0,3.120312,3.120312,3.120312,5.999594
187.6,3.126562,5.883704,0.5883704,0,0,0,0,0,3.126562,3.126562,3.126562,5.999708
188,3.132968,5.893447,0.5893446,0,0,0,0,0,3.132968,3.132968,3.132968,6.009643
188.4,3.139531,5.901221,0.5901221,0,0,0,0,0,3.139531,3.139531,3.139531,6.01757
188.8,3.146562,5.850832,0.5850832,0,0,0,0,0,3.146562,3.146562,3.146562,5.966188
189.2,3.15375,5.8686,0.5868599,0,0,0,0,0,3.153749,3.153749,3.15375,5.984306
189.6,3.160156,5.874487,0.5874487,0,0,0,0,0,3.160156,3.160156,3.160156,5.99031
190,3.166093,5.875173,0.5875173,0,0,0,0,0,3.166093,3.166093,3.166093,5.991009
190.4,3.172968,5.893247,0.5893247,0,0,0,0,0,3.172968,3.172968,3.172968,6.00944
190.8,3.18,5.916184,0.5916184,0,0,0,0,0,3.18,3.18,3.18,6.032828
191.2,3.186718,5.927309,0.5927309,0,0,0,0,0,3.186718,3.186718,3.186718,6.044173
191.6,3.193125,5.933346,0.5933346,0,0,0,0,0,3.193125,3.193125,3.193125,6.050329
192,3.199843,5.940112,0.5940112,0,0,0,0,0,3.199843,3.199843,3.199843,6.057229
192.4,3.206562,5.95131,0.595131,0,0,0,0,0,3.206562,3.206562,3.206562,6.068647
192.8,3.213281,5.963208,0.5963207,0,0,0,0,0,3.213281,3.213281,3.213281,6.08078
193.2,3.219843,5.971428,0.5971428,0,0,0,0,0,3.219843,3.219843,3.219843,6.089162
193.6,3.226249,5.980807,0.5980807,0,0,0,0,0,3.226249,3.226249,3.226249,6.098726
194,3.233125,5.993676,0.5993676,0,0,0,0,0,3.233124,3.233124,3.233125,6.111848
194.4,3.240312,6.011187,0.6011187,0,0,0,0,0,3.240312,3.240312,3.240312,6.129705
194.8,3.246562,6.014553,0.6014553,0,0,0,0,0,3.246562,3.246562,3.246562,6.133137
195.2,3.252812,6.023894,0.6023895,0,0,0,0,0,3.252812,3.252812,3.252812,6.142663
195.6,3.259843,6.041507,0.6041508,0,0,0,0,0,3.259843,3.259843,3.259843,6.160623
196,3.266874,6.060367,0.6060367,0,0,0,0,0,3.266875,3.266875,3.266874,6.179855
196.4,3.273437,6.060791,0.6060792,0,0,0,0,0,3.273437,3.273437,3.273437,6.180287
196.8,3.279843,6.064689,0.6064689,0,0,0,0,0,3.279843,3.279843,3.279843,6.184262
197.2,3.286718,6.070934,0.6070934,0,0,0,0,0,3.286718,3.286718,3.286718,6.190629
197.6,3.293281,6.08445,0.6084449,0,0,0,0,0,3.293281,3.293281,3.293281,6.204412
198,3.299843,6.096569,0.6096569,0,0,0,0,0,3.299843,3.299843,3.299843,6.216771
198.4,3.30625,6.105767,0.6105767,0,0,0,0,0,3.30625,3.30625,3.30625,6.22615
198.8,3.312968,6.116849,0.6116849,0,0,0,0,0,3.312968,3.312968,3.312968,6.23745
199.2,3.32,6.128921,0.612892,0,0,0,0,0,3.32,3.32,3.32,6.24976
199.6,3.326874,6.140117,0.6140116,0,0,0,0,0,3.326874,3.326874,3.326874,6.261177
200,3.333125,6.145515,0.6145514,0,0,0,0,0,3.333125,3.333125,3.333125,6.266681
200.4,3.339531,6.157401,0.6157401,0,0,0,0,0,3.339531,3.339531,3.339531,6.278801
200.8,3.346406,6.172496,0.6172496,0,0,0,0,0,3.346406,3.346406,3.346406,6.294194
201.2,3.353437,6.194018,0.6194018,0,0,0,0,0,3.353437,3.353437,3.353437,6.316141
201.6,3.36,6.203804,0.6203804,0,0,0,0,0,3.359999,3.359999,3.36,6.326119
202,3.366562,6.207935,0.6207935,0,0,0,0,0,3.366562,3.366562,3.366562,6.330332
202.4,3.372968,6.206421,0.6206421,0,0,0,0,0,3.372968,3.372968,3.372968,6.328788
202.8,3.380156,6.227461,0.6227461,0,0,0,0,0,3.380156,3.380156,3.380156,6.350243
203.2,3.386718,6.233383,0.6233383,0,0,0,0,0,3.386718,3.386718,3.386718,6.356281
203.6,3.392968,6.240004,0.6240004,0,0,0,0,0,3.392968,3.392968,3.392968,6.363033
204,3.399687,6.250662,0.6250662,0,0,0,0,0,3.399687,3.399687,3.399687,6.373901
204.4,3.407031,6.261545,0.6261545,0,0,0,0,0,3.407031,3.407031,3.407031,6.384999
204.8,3.413124,6.259797,0.6259797,0,0,0,0,0,3.413125,3.413125,3.413124,6.383216
205.2,3.419687,6.271087,0.6271088,0,0,0,0,0,3.419687,3.419687,3.419687,6.39473
205.6,3.426406,6.286243,0.6286243,0,0,0,0,0,3.426406,3.426406,3.426406,6.410183
206,3.433437,6.308072,0.6308072,0,0,0,0,0,3.433437,3.433437,3.433437,6.432443
206.4,3.44,6.313997,0.6313997,0,0,0,0,0,3.44,3.44,3.44,6.438485
206.8,3.446718,6.321692,0.6321692,0,0,0,0,0,3.446718,3.446718,3.446718,6.446332
207.2,3.453281,6.330009,0.6330009,0,0,0,0,0,3.453281,3.453281,3.453281,6.454813
207.6,3.459843,6.331426,0.6331426,0,0,0,0,0,3.459843,3.459843,3.459843,6.456258
208,3.466718,6.35023,0.6350231,0,0,0,0,0,3.466718,3.466718,3.466718,6.475433
208.4,3.473281,6.353923,0.6353923,0,0,0,0,0,3.473281,3.473281,3.473281,6.479198
208.8,3.479687,6.361704,0.6361704,0,0,0,0,0,3.479687,3.479687,3.479687,6.487133
208.966,3.4825,6.368271,0.6368271,0,0,0,0,0,3.4825,3.4825,3.4825,6.493829